Workbook

Sheet v3使用说明
A1: 全行业景气度量化跟踪体系 v3｜核心驱动、事件与风险闭环
A2: 流程：更新指标台账 → 检查行业核心标准 → 验证事件 → 执行风险否决 → 在行业监控面板排序。行业景气不等于交易信号。
A4: 更新 | B4: 台账维护最新值、发布日期、状态和评分，行业页自动使用台账评分。
A5: 事件 | B5: 事件须至少两项证据、明确验证指标、且未过期，才进入最终行业分。
A6: 风险 | B6: 库存、应收、现金流、价格战和政策降价等否决项可直接扣减分数。
A7: 边界 | B7: 最终行业分用于基本面排序与研究优先级；估值、资金面、买卖时点另建交易层。

Sheet 跨行业因子库
A1: 跨行业因子 | B1: 核心标准 | C1: 主要影响行业 | D1: 评分限制 | E1: 建议口径
A2: 需求/订单 | B2: 需求、订单、客户预算同向改善 | C2: 消费、制造、医药、TMT、服务 | D2: 预期不能替代订单或销量 | E2: 季调同比+3个月环比+订单覆盖率
A3: 供给/库存 | B3: 去库、产能出清、竞争格局改善 | C3: 资源品、化工、光伏锂电、半导体 | D3: 供给缩减不等于需求恢复 | E3: 库存分位+产能增速+开工率
A4: 价格/价差 | B4: 价差扩张并由库存/利润确认 | C4: 资源品、化工、制造、运输 | D4: 价格单项不可给满分 | E4: 5年分位+动量+价差/库存
A5: 资本开支 | B5: 计划→招标→订单→交付逐级确认 | C5: 设备、通信、电网、AI、建筑 | D5: 规划本身不创造收入 | E5: 滚动4季同比+合同负债
A6: 现金流/信用 | B6: 回款、现金流、应收质量改善 | C6: 地产、建筑、环保、设备、医疗 | D6: 收入不能替代回款 | E6: TTM现金流/收入+应收周转
A7: 政策/支付 | B7: 改变支付、准入、供给规则且有细则 | C7: 医药、新能源、公用、军工、金融 | D7: 政策/热度不直接计分 | E7: 确认项，单项权重≤8%
A8: 技术/替代 | B8: 技术转化为订单、利用率、毛利 | C8: 半导体、AI、机器人、创新药 | D8: 技术热度不替代兑现 | E8: 里程碑+订单+利用率/毛利
A9: 外需/贸易 | B9: 出口量价、海外CAPEX、贸易限制 | C9: 电子、家电、机械、光伏、汽车、CXO | D9: 汇率或出口额不可单看 | E9: 量价拆分+订单+汇率敏感性
A10: 运营效率 | B10: 利用率、周转、人效、费用率持续改善 | C10: 制造、CXO、服务、零售 | D10: 一次性改善不计 | E10: TTM分位+连续两期验证
A11: 估值/资金面 | B11: 仅用于交易层的预期回报与拥挤度 | C11: 全部行业 | D11: 不计基本面景气 | E11: 单独建模

Sheet 指标更新台账_v3
A1: 指标键 | B1: 行业 | C1: 层级 | D1: 指标名称 | E1: 数据来源 | F1: 当前值（原始） | G1: 单位 | H1: 建议权重 | I1: 当前评分(1-10) | J1: 数据发布日期 | K1: 数据状态 | L1: 角色 | M1: 评分口径 | N1: 更新备注
A2: 农林牧渔|1-能繁母猪存栏量变化 | B2: 农林牧渔 | C2: 先行 | D2: 1-能繁母猪存栏量变化 | E2: 农业农村部 | F2: +1.2 | G2: %YoY | H2: 0.125 | I2: 6 | K2: 待更新 | L2: 核心先行 | M2: 采用5年滚动分位+同比/环比双阈值；数据滞后超过一个频率周期时自动降权。 | N2: 请按评分口径复核最新值、日期和评分。
A3: 农林牧渔|2-仔猪价格变化 | B3: 农林牧渔 | C3: 先行 | D3: 2-仔猪价格变化 | E3: 农业农村部/博亚和讯 | F3: +35 | G3: %YoY | H3: 0.125 | I3: 9 | K3: 待更新 | L3: 核心先行 | M3: 改为5年滚动分位(P20/P40/P60/P80)+3个月动量；须与库存、价差或利润交叉确认。 | N3: 请按评分口径复核最新值、日期和评分。
A4: 农林牧渔|3-饲料价格变化 | B4: 农林牧渔 | C4: 先行 | D4: 3-饲料价格变化 | E4: 中国饲料工业协会 | F4: -3.5 | G4: %YoY | H4: 0.1 | I4: 8 | K4: 待更新 | L4: 核心先行 | M4: 改为5年滚动分位(P20/P40/P60/P80)+3个月动量；须与库存、价差或利润交叉确认。 | N4: 请按评分口径复核最新值、日期和评分。
A5: 农林牧渔|4-农产品进口量增速 | B5: 农林牧渔 | C5: 先行 | D5: 4-农产品进口量增速 | E5: 海关总署 | F5: +2.1 | G5: %YoY | H5: 0.0833 | I5: 6 | K5: 待更新 | L5: 核心先行 | M5: 采用5年滚动分位+同比/环比双阈值；数据滞后超过一个频率周期时自动降权。 | N5: 请按评分口径复核最新值、日期和评分。
A6: 农林牧渔|5-种植面积变化 | B6: 农林牧渔 | C6: 先行 | D6: 5-种植面积变化 | E6: 国家统计局 | F6: +0.8 | G6: %YoY | H6: 0.0667 | I6: 6 | K6: 待更新 | L6: 核心先行 | M6: 采用5年滚动分位+同比/环比双阈值；数据滞后超过一个频率周期时自动降权。 | N6: 请按评分口径复核最新值、日期和评分。
A7: 农林牧渔|6-生猪出栏均价 | B7: 农林牧渔 | C7: 同步 | D7: 6-生猪出栏均价 | E7: 农业农村部 | F7: 15.8 | G7: 元/公斤 | H7: 0.1312 | I7: 6 | K7: 待更新 | L7: 同步确认 | M7: 改为5年滚动分位(P20/P40/P60/P80)+3个月动量；须与库存、价差或利润交叉确认。 | N7: 请按评分口径复核最新值、日期和评分。
A8: 农林牧渔|7-白羽肉鸡价格 | B8: 农林牧渔 | C8: 同步 | D8: 7-白羽肉鸡价格 | E8: 博亚和讯 | F8: 8.2 | G8: 元/公斤 | H8: 0.0875 | I8: 8 | K8: 待更新 | L8: 同步确认 | M8: 改为5年滚动分位(P20/P40/P60/P80)+3个月动量；须与库存、价差或利润交叉确认。 | N8: 请按评分口径复核最新值、日期和评分。
A9: 农林牧渔|8-水产批发价格指数 | B9: 农林牧渔 | C9: 同步 | D9: 8-水产批发价格指数 | E9: 农业农村部 | F9: 112 | G9: 点 | H9: 0.07 | I9: 6 | K9: 待更新 | L9: 同步确认 | M9: 改为5年滚动分位(P20/P40/P60/P80)+3个月动量；须与库存、价差或利润交叉确认。 | N9: 请按评分口径复核最新值、日期和评分。
A10: 农林牧渔|9-农产品批发价格200指数 | B10: 农林牧渔 | C10: 同步 | D10: 9-农产品批发价格200指数 | E10: 农业农村部 | F10: 118 | G10: 点 | H10: 0.0612 | I10: 6 | K10: 待更新 | L10: 同步确认 | M10: 改为5年滚动分位(P20/P40/P60/P80)+3个月动量；须与库存、价差或利润交叉确认。 | N10: 请按评分口径复核最新值、日期和评分。
A11: 农林牧渔|10-养殖企业季度净利润率 | B11: 农林牧渔 | C11: 滞后 | D11: 10-养殖企业季度净利润率 | E11: 上市公司财报 | F11: 6.5 | G11: % | H11: 0.06 | I11: 6 | K11: 待更新 | L11: 质量验证 | M11: 采用TTM/滚动4季同比+历史分位；剔除一次性损益，IRR按项目现金流复核。 | N11: 请按评分口径复核最新值、日期和评分。
A12: 农林牧渔|11-农林牧渔固定资产投资增速 | B12: 农林牧渔 | C12: 滞后 | D12: 11-农林牧渔固定资产投资增速 | E12: 国家统计局 | F12: +8.2 | G12: %YoY | H12: 0.048 | I12: 8 | K12: 待更新 | L12: 质量验证 | M12: 采用5年滚动分位+同比/环比双阈值；数据滞后超过一个频率周期时自动降权。 | N12: 请按评分口径复核最新值、日期和评分。
A13: 农林牧渔|12-CPI食品项同比 | B13: 农林牧渔 | C13: 滞后 | D13: 12-CPI食品项同比 | E13: 国家统计局 | F13: +1.2 | G13: % | H13: 0.042 | I13: 6 | K13: 待更新 | L13: 质量验证 | M13: 采用5年滚动分位+同比/环比双阈值；数据滞后超过一个频率周期时自动降权。 | N13: 请按评分口径复核最新值、日期和评分。
... A83: 纺织服饰|3-美国服装零售库存 | B83: 纺织服饰 | C83: 先行 | D83: 3-美国服装零售库存 | E83: 美国商务部 | F83: -3.5 | G83: %YoY | H83: 0.0889 | I83: 8 | K83: 待更新 | L83: 核心先行 | M83: 采用同比、环比、历史分位三维评分；按去库/改善方向计分。 | N83: 请按评分口径复核最新值、日期和评分。
A84: 纺织服饰|4-人民币汇率 | B84: 纺织服饰 | C84: 先行 | D84: 4-人民币汇率 | E84: 中国外汇交易中心 | F84: 7.18 | H84: 0.0711 | I84: 6 | K84: 待更新 | L84: 核心先行 | M84: 采用5年滚动分位+同比/环比双阈值；数据滞后超过一个频率周期时自动降权。 | N84: 请按评分口径复核最新值、日期和评分。
A85: 纺织服饰|5-纺织品出口金额增速 | B85: 纺织服饰 | C85: 同步 | D85: 5-纺织品出口金额增速 | E85: 海关总署 | F85: +8.5 | G85: %YoY | H85: 0.1333 | I85: 8 | K85: 待更新 | L85: 同步确认 | M85: 采用5年滚动分位+同比/环比双阈值；数据滞后超过一个频率周期时自动降权。 | N85: 请按评分口径复核最新值、日期和评分。
A86: 纺织服饰|6-服装出口金额增速 | B86: 纺织服饰 | C86: 同步 | D86: 6-服装出口金额增速 | E86: 海关总署 | F86: +6.2 | G86: %YoY | H86: 0.1067 | I86: 6 | K86: 待更新 | L86: 同步确认 | M86: 采用5年滚动分位+同比/环比双阈值；数据滞后超过一个频率周期时自动降权。 | N86: 请按评分口径复核最新值、日期和评分。
A87: 纺织服饰|7-柯桥纺织价格指数 | B87: 纺织服饰 | C87: 同步 | D87: 7-柯桥纺织价格指数 | E87: 柯桥指数 | F87: 104 | G87: 点 | H87: 0.0889 | I87: 6 | K87: 待更新 | L87: 同步确认 | M87: 改为5年滚动分位(P20/P40/P60/P80)+3个月动量；须与库存、价差或利润交叉确认。 | N87: 请按评分口径复核最新值、日期和评分。
A88: 纺织服饰|8-纺服企业开工率 | B88: 纺织服饰 | C88: 同步 | D88: 8-纺服企业开工率 | E88: 中国纺织工业联合会 | F88: 78 | G88: % | H88: 0.0711 | I88: 6 | K88: 待更新 | L88: 同步确认 | M88: 采用5年滚动分位+同比/环比双阈值；数据滞后超过一个频率周期时自动降权。 | N88: 请按评分口径复核最新值、日期和评分。
A89: 纺织服饰|9-纺服企业季度净利润率 | B89: 纺织服饰 | C89: 滞后 | D89: 9-纺服企业季度净利润率 | E89: 上市公司财报 | F89: 5.5 | G89: % | H89: 0.08 | I89: 6 | K89: 待更新 | L89: 质量验证 | M89: 采用TTM/滚动4季同比+历史分位；剔除一次性损益，IRR按项目现金流复核。 | N89: 请按评分口径复核最新值、日期和评分。
A90: 纺织服饰|10-纺服行业库存周转天数 | B90: 纺织服饰 | C90: 滞后 | D90: 10-纺服行业库存周转天数 | E90: 上市公司财报 | F90: 68 | G90: 天 | H90: 0.064 | I90: 6 | K90: 待更新 | L90: 质量验证 | M90: 采用同比、环比、历史分位三维评分；按去库/改善方向计分。 | N90: 请按评分口径复核最新值、日期和评分。
A91: 纺织服饰|11-社会消费品零售-服装类 | B91: 纺织服饰 | C91: 滞后 | D91: 11-社会消费品零售-服装类 | E91: 国家统计局 | F91: +3.8 | G91: %YoY | H91: 0.056 | I91: 6 | K91: 待更新 | L91: 质量验证 | M91: 采用季调同比+3个月环比；单月值用3个月移动均值过滤。 | N91: 请按评分口径复核最新值、日期和评分。
A92: 轻工制造|1-纸浆价格变化 | B92: 轻工制造 | C92: 先行 | D92: 1-纸浆价格变化 | E92: 针叶浆/阔叶浆 | F92: -8.5 | G92: %YoY | H92: 0.1333 | I92: 8 | K92: 待更新 | L92: 核心先行 | M92: 改为5年滚动分位(P20/P40/P60/P80)+3个月动量；须与库存、价差或利润交叉确认。 | N92: 请按评分口径复核最新值、日期和评分。
A93: 轻工制造|2-木材价格变化 | B93: 轻工制造 | C93: 先行 | D93: 2-木材价格变化 | E93: 木材指数 | F93: -2.5 | G93: %YoY | H93: 0.0889 | I93: 8 | K93: 待更新 | L93: 核心先行 | M93: 改为5年滚动分位(P20/P40/P60/P80)+3个月动量；须与库存、价差或利润交叉确认。 | N93: 请按评分口径复核最新值、日期和评分。
A94: 轻工制造|3-房地产竣工面积增速 | B94: 轻工制造 | C94: 先行 | D94: 3-房地产竣工面积增速 | E94: 国家统计局 | F94: -8.5 | G94: %YoY | H94: 0.1067 | I94: 4 | K94: 待更新 | L94: 核心先行 | M94: 采用5年滚动分位+同比/环比双阈值；数据滞后超过一个频率周期时自动降权。 | N94: 请按评分口径复核最新值、日期和评分。
A95: 轻工制造|4-美国新房销售 | B95: 轻工制造 | C95: 先行 | D95: 4-美国新房销售 | E95: 美国商务部 | F95: +2.5 | G95: %YoY | H95: 0.0711 | I95: 6 | K95: 待更新 | L95: 核心先行 | M95: 采用5年滚动分位+同比/环比双阈值；数据滞后超过一个频率周期时自动降权。 | N95: 请按评分口径复核最新值、日期和评分。
A96: 轻工制造|5-瓦楞纸价格 | B96: 轻工制造 | C96: 同步 | D96: 5-瓦楞纸价格 | E96: 卓创资讯 | F96: 2800 | G96: 元/吨 | H96: 0.1143 | I96: 4 | K96: 待更新 | L96: 同步确认 | M96: 改为5年滚动分位(P20/P40/P60/P80)+3个月动量；须与库存、价差或利润交叉确认。 | N96: 请按评分口径复核最新值、日期和评分。
... A276: 非银金融|11-保险综合偿付能力充足率 | B276: 非银金融 | C276: 滞后 | D276: 11-保险综合偿付能力充足率 | E276: 银保监会 | F276: 225 | G276: % | H276: 0.056 | I276: 8 | K276: 待更新 | L276: 质量验证 | M276: 采用5年滚动分位+同比/环比双阈值；数据滞后超过一个频率周期时自动降权。 | N276: 请按评分口径复核最新值、日期和评分。
A277: 汽车|1-汽车经销商库存系数 | B277: 汽车 | C277: 先行 | D277: 1-汽车经销商库存系数 | E277: 中国汽车流通协会 | F277: 1.55 | H277: 0.1333 | I277: 6 | K277: 待更新 | L277: 核心先行 | M277: 采用同比、环比、历史分位三维评分；按去库/改善方向计分。 | N277: 请按评分口径复核最新值、日期和评分。
A278: 汽车|2-新能源汽车渗透率 | B278: 汽车 | C278: 先行 | D278: 2-新能源汽车渗透率 | E278: 中汽协 | F278: 42.5 | G278: % | H278: 0.1067 | I278: 8 | K278: 待更新 | L278: 核心先行 | M278: 采用5年滚动分位+同比/环比双阈值；数据滞后超过一个频率周期时自动降权。 | N278: 请按评分口径复核最新值、日期和评分。
A279: 汽车|3-动力电池装车量增速 | B279: 汽车 | C279: 先行 | D279: 3-动力电池装车量增速 | E279: 中国汽车动力电池产业创新联盟 | F279: +38 | G279: %YoY | H279: 0.0889 | I279: 8 | K279: 待更新 | L279: 核心先行 | M279: 采用5年滚动分位+同比/环比双阈值；数据滞后超过一个频率周期时自动降权。 | N279: 请按评分口径复核最新值、日期和评分。
A280: 汽车|4-汽车出口量增速 | B280: 汽车 | C280: 先行 | D280: 4-汽车出口量增速 | E280: 海关总署 | F280: +28 | G280: %YoY | H280: 0.0711 | I280: 8 | K280: 待更新 | L280: 核心先行 | M280: 采用5年滚动分位+同比/环比双阈值；数据滞后超过一个频率周期时自动降权。 | N280: 请按评分口径复核最新值、日期和评分。
A281: 汽车|5-汽车销量增速 | B281: 汽车 | C281: 同步 | D281: 5-汽车销量增速 | E281: 中汽协 | F281: +9.5 | G281: %YoY | H281: 0.1333 | I281: 8 | K281: 待更新 | L281: 同步确认 | M281: 采用季调同比+3个月环比；单月值用3个月移动均值过滤。 | N281: 请按评分口径复核最新值、日期和评分。
A282: 汽车|6-新能源汽车销量 | B282: 汽车 | C282: 同步 | D282: 6-新能源汽车销量 | E282: 中汽协 | F282: 88 | G282: 万辆/月 | H282: 0.1067 | I282: 8 | K282: 待更新 | L282: 同步确认 | M282: 采用季调同比+3个月环比；单月值用3个月移动均值过滤。 | N282: 请按评分口径复核最新值、日期和评分。
A283: 汽车|7-乘用车批发量 | B283: 汽车 | C283: 同步 | D283: 7-乘用车批发量 | E283: 乘联会 | F283: 198 | G283: 万辆/月 | H283: 0.0889 | I283: 8 | K283: 待更新 | L283: 同步确认 | M283: 采用5年滚动分位+同比/环比双阈值；数据滞后超过一个频率周期时自动降权。 | N283: 请按评分口径复核最新值、日期和评分。
A284: 汽车|8-汽车制造业PMI | B284: 汽车 | C284: 同步 | D284: 8-汽车制造业PMI | E284: 国家统计局 | F284: 52.5 | G284: 点 | H284: 0.0711 | I284: 8 | K284: 待更新 | L284: 同步确认 | M284: 采用5年滚动分位+同比/环比双阈值；数据滞后超过一个频率周期时自动降权。 | N284: 请按评分口径复核最新值、日期和评分。
A285: 汽车|9-汽车企业季度净利润 | B285: 汽车 | C285: 滞后 | D285: 9-汽车企业季度净利润 | E285: 上市公司财报 | F285: 185 | G285: 亿元 | H285: 0.08 | I285: 8 | K285: 待更新 | L285: 质量验证 | M285: 采用TTM/滚动4季同比+历史分位；剔除一次性损益，IRR按项目现金流复核。 | N285: 请按评分口径复核最新值、日期和评分。
A286: 汽车|10-汽车行业产能利用率 | B286: 汽车 | C286: 滞后 | D286: 10-汽车行业产能利用率 | E286: 国家统计局 | F286: 78 | G286: % | H286: 0.064 | I286: 6 | K286: 待更新 | L286: 质量验证 | M286: 采用TTM/滚动4季同比+历史分位；剔除一次性损益，IRR按项目现金流复核。 | N286: 请按评分口径复核最新值、日期和评分。
A287: 汽车|11-汽车制造业固定资产投资 | B287: 汽车 | C287: 滞后 | D287: 11-汽车制造业固定资产投资 | E287: 国家统计局 | F287: +12.5 | G287: %YoY | H287: 0.056 | I287: 8 | K287: 待更新 | L287: 质量验证 | M287: 采用5年滚动分位+同比/环比双阈值；数据滞后超过一个频率周期时自动降权。 | N287: 请按评分口径复核最新值、日期和评分。
A288: 机械设备|1-制造业固定资产投资增速 | B288: 机械设备 | C288: 先行 | D288: 1-制造业固定资产投资增速 | E288: 国家统计局 | F288: +9.5 | G288: %YoY | H288: 0.1667 | I288: 8 | K288: 待更新 | L288: 核心先行 | M288: 采用5年滚动分位+同比/环比双阈值；数据滞后超过一个频率周期时自动降权。 | N288: 请按评分口径复核最新值、日期和评分。
...

Sheet 行业监控面板_v3
A1: 行业 | B1: 基础景气分 | C1: 核心增长内核 | D1: 必选先行标准 | E1: 风险否决重点 | F1: 事件证据数(0-3) | G1: 事件影响(-1.5~1.5) | H1: 风险扣分(0~-1.5) | I1: 事件有效影响 | J1: 最终行业分 | K1: 使用状态
A2: 农林牧渔 | B2: =VLOOKUP(A2,全行业景气度总览!$A$4:$E$50,5,FALSE()) -> 6.8 | C2: 供给周期与养殖价差 | D2: 母猪存栏/淘汰率、仔猪价、饲料成本 | E2: 单纯CPI、年度种植面积 | F2: 0 | G2: 0 | H2: 0 | I2: =IF(AND(F2>=2,G2<>0),G2,0) -> 0 | J2: =MIN(10,MAX(1,B2+I2+H2)) -> 6.8 | K2: =IF(H2<=-1,"风险否决",IF(F2<2,"基础分有效，事件未验证",IF(I2>0,"事件上调已验证",IF(I2<0,"事件下调已验证","中性观察")))) -> 基础分有效，事件未验证
A3: 基础化工 | B3: =VLOOKUP(A3,全行业景气度总览!$A$4:$E$50,5,FALSE()) -> 7.4 | C3: 库存周期与价差修复 | D3: 下游订单、库存、计划新增产能 | E3: 原油绝对价格 | F3: 0 | G3: 0 | H3: 0 | I3: =IF(AND(F3>=2,G3<>0),G3,0) -> 0 | J3: =MIN(10,MAX(1,B3+I3+H3)) -> 7.4 | K3: =IF(H3<=-1,"风险否决",IF(F3<2,"基础分有效，事件未验证",IF(I3>0,"事件上调已验证",IF(I3<0,"事件下调已验证","中性观察")))) -> 基础分有效，事件未验证
A4: 钢铁 | B4: =VLOOKUP(A4,全行业景气度总览!$A$4:$E$50,5,FALSE()) -> 7 | C4: 需求/去库与利润修复 | D4: 地产施工、基建实物量、库存变化 | E4: 钢价绝对水平 | F4: 0 | G4: 0 | H4: 0 | I4: =IF(AND(F4>=2,G4<>0),G4,0) -> 0 | J4: =MIN(10,MAX(1,B4+I4+H4)) -> 7 | K4: =IF(H4<=-1,"风险否决",IF(F4<2,"基础分有效，事件未验证",IF(I4>0,"事件上调已验证",IF(I4<0,"事件下调已验证","中性观察")))) -> 基础分有效，事件未验证
A5: 有色金属 | B5: =VLOOKUP(A5,全行业景气度总览!$A$4:$E$50,5,FALSE()) -> 7.9 | C5: 库存、供给约束与需求弹性 | D5: 库存、TC/RC、美元、矿端扰动 | E5: 金属绝对价格 | F5: 0 | G5: 0 | H5: 0 | I5: =IF(AND(F5>=2,G5<>0),G5,0) -> 0 | J5: =MIN(10,MAX(1,B5+I5+H5)) -> 7.9 | K5: =IF(H5<=-1,"风险否决",IF(F5<2,"基础分有效，事件未验证",IF(I5>0,"事件上调已验证",IF(I5<0,"事件下调已验证","中性观察")))) -> 基础分有效，事件未验证
A6: 电子 | B6: =VLOOKUP(A6,全行业景气度总览!$A$4:$E$50,5,FALSE()) -> 7.8 | C6: 库存去化与需求/产能利用率 | D6: 订单、库存周转、存储价格、终端出货 | E6: 行业总销售单指标 | F6: 0 | G6: 0 | H6: 0 | I6: =IF(AND(F6>=2,G6<>0),G6,0) -> 0 | J6: =MIN(10,MAX(1,B6+I6+H6)) -> 7.8 | K6: =IF(H6<=-1,"风险否决",IF(F6<2,"基础分有效，事件未验证",IF(I6>0,"事件上调已验证",IF(I6<0,"事件下调已验证","中性观察")))) -> 基础分有效，事件未验证
A7: 家用电器 | B7: =VLOOKUP(A7,全行业景气度总览!$A$4:$E$50,5,FALSE()) -> 6.5 | C7: 更新需求、出口和产品结构 | D7: 地产竣工、海外订单、排产 | E7: 商品房销售 | F7: 0 | G7: 0 | H7: 0 | I7: =IF(AND(F7>=2,G7<>0),G7,0) -> 0 | J7: =MIN(10,MAX(1,B7+I7+H7)) -> 6.5 | K7: =IF(H7<=-1,"风险否决",IF(F7<2,"基础分有效，事件未验证",IF(I7>0,"事件上调已验证",IF(I7<0,"事件下调已验证","中性观察")))) -> 基础分有效，事件未验证
A8: 食品饮料 | B8: =VLOOKUP(A8,全行业景气度总览!$A$4:$E$50,5,FALSE()) -> 6.7 | C8: 动销、渠道与价格带 | D8: 经销商库存、终端动销、批价 | E8: CPI单项 | F8: 0 | G8: 0 | H8: 0 | I8: =IF(AND(F8>=2,G8<>0),G8,0) -> 0 | J8: =MIN(10,MAX(1,B8+I8+H8)) -> 6.7 | K8: =IF(H8<=-1,"风险否决",IF(F8<2,"基础分有效，事件未验证",IF(I8>0,"事件上调已验证",IF(I8<0,"事件下调已验证","中性观察")))) -> 基础分有效，事件未验证
A9: 纺织服饰 | B9: =VLOOKUP(A9,全行业景气度总览!$A$4:$E$50,5,FALSE()) -> 6.9 | C9: 海外库存、订单与汇率 | D9: 海外零售库存、订单、汇率 | E9: 棉价单项 | F9: 0 | G9: 0 | H9: 0 | I9: =IF(AND(F9>=2,G9<>0),G9,0) -> 0 | J9: =MIN(10,MAX(1,B9+I9+H9)) -> 6.9 | K9: =IF(H9<=-1,"风险否决",IF(F9<2,"基础分有效，事件未验证",IF(I9>0,"事件上调已验证",IF(I9<0,"事件下调已验证","中性观察")))) -> 基础分有效，事件未验证
A10: 轻工制造 | B10: =VLOOKUP(A10,全行业景气度总览!$A$4:$E$50,5,FALSE()) -> 5.8 | C10: 地产后周期/出口与价差 | D10: 竣工、海外地产、原料与产品价差 | E10: 纸浆绝对价格 | F10: 0 | G10: 0 | H10: 0 | I10: =IF(AND(F10>=2,G10<>0),G10,0) -> 0 | J10: =MIN(10,MAX(1,B10+I10+H10)) -> 5.8 | K10: =IF(H10<=-1,"风险否决",IF(F10<2,"基础分有效，事件未验证",IF(I10>0,"事件上调已验证",IF(I10<0,"事件下调已验证","中性观察")))) -> 基础分有效，事件未验证
A11: 医药生物 | B11: =VLOOKUP(A11,全行业景气度总览!$A$4:$E$50,5,FALSE()) -> 7.7 | C11: 创新、诊疗与政策支付 | D11: IND/注册、医保政策、研发融资 | E11: 单一原料药价格 | F11: 0 | G11: 0 | H11: 0 | I11: =IF(AND(F11>=2,G11<>0),G11,0) -> 0 | J11: =MIN(10,MAX(1,B11+I11+H11)) -> 7.7 | K11: =IF(H11<=-1,"风险否决",IF(F11<2,"基础分有效，事件未验证",IF(I11>0,"事件上调已验证",IF(I11<0,"事件下调已验证","中性观察")))) -> 基础分有效，事件未验证
A12: 公用事业 | B12: =VLOOKUP(A12,全行业景气度总览!$A$4:$E$50,5,FALSE()) -> 7.9 | C12: 利用小时、燃料传导与资本回报 | D12: 来水、燃料、电价机制、装机进度 | E12: 装机规划 | F12: 0 | G12: 0 | H12: 0 | I12: =IF(AND(F12>=2,G12<>0),G12,0) -> 0 | J12: =MIN(10,MAX(1,B12+I12+H12)) -> 7.9 | K12: =IF(H12<=-1,"风险否决",IF(F12<2,"基础分有效，事件未验证",IF(I12>0,"事件上调已验证",IF(I12<0,"事件下调已验证","中性观察")))) -> 基础分有效，事件未验证
A13: 交通运输 | B13: =VLOOKUP(A13,全行业景气度总览!$A$4:$E$50,5,FALSE()) -> 8 | C13: 运价、运量与供给 | D13: 运力投放、运价、油价 | E13: 投资增速 | F13: 0 | G13: 0 | H13: 0 | I13: =IF(AND(F13>=2,G13<>0),G13,0) -> 0 | J13: =MIN(10,MAX(1,B13+I13+H13)) -> 8 | K13: =IF(H13<=-1,"风险否决",IF(F13<2,"基础分有效，事件未验证",IF(I13>0,"事件上调已验证",IF(I13<0,"事件下调已验证","中性观察")))) -> 基础分有效，事件未验证
... A44: 创新药 | B44: =VLOOKUP(A44,全行业景气度总览!$A$4:$E$50,5,FALSE()) -> 8 | C44: 研发兑现、商业化与支付 | D44: BD、临床、获批、医保/准入 | E44: 获批数量单项 | F44: 0 | G44: 0 | H44: 0 | I44: =IF(AND(F44>=2,G44<>0),G44,0) -> 0 | J44: =MIN(10,MAX(1,B44+I44+H44)) -> 8 | K44: =IF(H44<=-1,"风险否决",IF(F44<2,"基础分有效，事件未验证",IF(I44>0,"事件上调已验证",IF(I44<0,"事件下调已验证","中性观察")))) -> 基础分有效，事件未验证

Sheet 事件覆盖层
A1: 事件ID | B1: 日期 | C1: 受影响行业 | D1: 事件类别 | E1: 方向 | F1: 影响期限 | G1: 证据数(0-3) | H1: 事件影响(-1.5~1.5) | I1: 验证指标 | J1: 证伪条件 | K1: 到期复核日 | L1: 状态 | M1: 备注
A2: EVT-001 | L2: 待验证
A3: EVT-002 | L3: 待验证
A4: EVT-003 | L4: 待验证
A5: EVT-004 | L5: 待验证
A6: EVT-005 | L6: 待验证
A7: EVT-006 | L7: 待验证
A8: EVT-007 | L8: 待验证
A9: EVT-008 | L9: 待验证
A10: EVT-009 | L10: 待验证
A11: EVT-010 | L11: 待验证
A12: EVT-011 | L12: 待验证
A13: EVT-012 | L13: 待验证
... A101: EVT-100 | L101: 待验证

Sheet 参数优化说明
A1: 全行业景气度量化跟踪体系｜参数优化说明
A2: 数据口径：保留原工作簿“截至2026年5月”的数值。本版优化权重、公式和阈值口径；不把旧数值视为实时投资数据。
A4: 审计结论 | B4: 原表无公式；43个行业页权重和均大于1；细分行业原加权分可超过10；总览与行业页未链接。
A5: 本版修复 | B5: 各行业归一化为先行/同步/滞后合计100%；行业综合分、分项分数和总览均改为公式联动。
A6: 阶段模板 | B6: 复苏55/30/15；扩张45/40/15；过热35/45/20；下行50/30/20；防御30/45/25（顺序为先行/同步/滞后）。
A7: 阈值原则 | B7: 价格、库存、量、利润、政策分别采用分位、变化率、季调、TTM、确认项上限；估值与交易信号单列。
A8: 使用纪律 | B8: 景气度只用于基本面筛选与排序，不能直接生成交易仓位；每次更新数据后须在Excel中重算。

Sheet 行业核心标准库
A1: 行业 | B1: 核心增长内核 | C1: 必选先行标准（未满足不得上调） | D1: 同步确认标准 | E1: 质量/盈利验证 | F1: 不作为主评分的指标 | G1: 新标理由
A2: 农林牧渔 | B2: 供给周期与养殖价差 | C2: 母猪存栏/淘汰率、仔猪价、饲料成本 | D2: 出栏量、猪鸡价、库存 | E2: 养殖现金成本、单头利润、经营现金流 | F2: 单纯CPI、年度种植面积 | G2: 供给约束决定价格，利润需在出栏兑现后确认。
A3: 基础化工 | B3: 库存周期与价差修复 | C3: 下游订单、库存、计划新增产能 | D3: 开工率、产品价差、出口 | E3: 现金成本、ROE、自由现金流 | F3: 原油绝对价格 | G3: 化工盈利取决于供需和价差，不是单一原料价格。
A4: 钢铁 | B4: 需求/去库与利润修复 | C4: 地产施工、基建实物量、库存变化 | D4: 表观消费、开工率、钢价/原料价差 | E4: 吨钢利润、现金流、应收 | F4: 钢价绝对水平 | G4: 钢价上升若库存不去化或利润不扩张，不能确认景气。
A5: 有色金属 | B5: 库存、供给约束与需求弹性 | C5: 库存、TC/RC、美元、矿端扰动 | D5: 金属价、加工费、消费量 | E5: 单位成本、资本开支、现金流 | F5: 金属绝对价格 | G5: 资源品价格需用供需紧张与加工利润验证。
A6: 电子 | B6: 库存去化与需求/产能利用率 | C6: 订单、库存周转、存储价格、终端出货 | D6: 稼动率、出货、ASP | E6: 毛利率、资本开支回报、现金流 | F6: 行业总销售单指标 | G6: AI、存储、消费电子周期不同，需拆分确认。
A7: 家用电器 | B7: 更新需求、出口和产品结构 | C7: 地产竣工、海外订单、排产 | D7: 零售/出货、出口、ASP | E7: 毛利率、渠道库存、现金流 | F7: 商品房销售 | G7: 竣工对家电更直接，销售只作前瞻背景。
A8: 食品饮料 | B8: 动销、渠道与价格带 | C8: 经销商库存、终端动销、批价 | D8: 销量、同店、收入 | E8: 毛利率、费用率、经营现金流 | F8: CPI单项 | G8: 品牌消费的核心是量价与渠道健康，不是宏观通胀。
A9: 纺织服饰 | B9: 海外库存、订单与汇率 | C9: 海外零售库存、订单、汇率 | D9: 出口、开工、零售 | E9: 库存周转、毛利率、现金流 | F9: 棉价单项 | G9: 成本变化只有传导到订单和毛利才有意义。
A10: 轻工制造 | B10: 地产后周期/出口与价差 | C10: 竣工、海外地产、原料与产品价差 | D10: 出货、开工、出口 | E10: 库存、ROE、现金流 | F10: 纸浆绝对价格 | G10: 需求与产品价差共同决定轻工盈利。
A11: 医药生物 | B11: 创新、诊疗与政策支付 | C11: IND/注册、医保政策、研发融资 | D11: 诊疗量、收入、器械出口 | E11: 毛利率、研发效率、经营现金流 | F11: 单一原料药价格 | G11: 子行业差异大，政策和商业化必须分层。
A12: 公用事业 | B12: 利用小时、燃料传导与资本回报 | C12: 来水、燃料、电价机制、装机进度 | D12: 发电量、利用小时 | E12: ROE、负债率、经营现金流 | F12: 装机规划 | G12: 规划不产生收益，利用率和现金流才决定回报。
... A44: 创新药 | B44: 研发兑现、商业化与支付 | C44: BD、临床、获批、医保/准入 | D44: 销售、处方、出海 | E44: 现金流、销售效率、研发回报 | F44: 获批数量单项 | G44: 获批不等于商业化，需用准入、处方和现金流确认。

Sheet 打分机制标准
A1: 行业景气度新打分机制（统一底层方法，行业核心标准库决定指标选择）
A3: 环节 | B3: 新标准 | C3: 理由
A4: 1. 指标可用性 | B4: 数据发布日期不滞后于其频率周期；异常值、口径变化、单月季节性先处理 | C4: 避免旧数据或异常点直接影响行业排序。
A5: 2. 单项标准化 | B5: 方向调整后使用5年滚动历史分位：P20/P40/P60/P80对应2/4/6/8分；价格和利润率另加3个月动量确认 | C5: 消除不同行业量纲差异，避免绝对阈值随通胀、技术降本而失效。
A6: 3. 因果层级 | B6: 先行仅回答“是否会变”；同步回答“是否已发生”；滞后仅验证“盈利/现金流是否兑现” | C6: 防止政策、规划、价格等相关但非因果指标主导分数。
A7: 4. 上调门槛 | B7: 行业分数上调一档，须至少2项必选先行标准+1项同步确认同向；仅先行改善时，综合分最高上调至6.5 | C7: 降低假复苏和主题驱动的误判。
A8: 5. 过热/风险扣分 | B8: 价格或估值急升但库存、需求、利润未确认时，价格指标封顶8分；现金流/应收恶化时，行业综合分扣0.5–1.5分 | C8: 价格上涨不必然转化为盈利，回款恶化会先破坏基本面。
A9: 6. 权重限制 | B9: 单项权重≤15%；政策/规划/热度单项≤8%；任一高度相关指标组（如多种价格）合计≤25% | C9: 降低重复计分和政策/情绪放大。
A10: 7. 阶段权重 | B10: 复苏55/30/15；扩张45/40/15；过热35/45/20；下行50/30/20；防御30/45/25（先行/同步/滞后） | C10: 不同阶段的信息含量不同，固定权重会滞后或误判。
A11: 8. 输出边界 | B11: 景气度只输出：行业排序、阶段、证据缺口和风险；估值、资金面、交易时点单独建模 | C11: 避免把基本面景气直接等同为买卖信号。

Sheet 全行业景气度总览
A1: 全行业景气度量化跟踪总览表（参数优化版）
A2: 本页公式连接各行业归一化评分；需按各页N列口径更新数据并打开Excel重算后，再用于横向排序。
A3: 行业名称 | B3: 先行指标 得分 | C3: 同步指标 得分 | D3: 滞后指标 得分 | E3: 综合景气度 评分 | F3: 景气度 判断 | G3: 阶段框架 | H3: 建议使用方式 | I3: 行业分类 | J3: 核心跟踪要点
A4: 农林牧渔 | B4: =农林牧渔!$P$4 -> 7.2 | C4: =农林牧渔!$P$5 -> 6.5 | D4: =农林牧渔!$P$6 -> 6.6 | E4: =农林牧渔!$G$19 -> 6.8 | F4: =IF(E4>=8.5,"强/防过热",IF(E4>=7.5,"偏强",IF(E4>=6.5,"中性偏强",IF(E4>=5,"中性",IF(E4>=3,"偏弱","低迷"))))) -> 中性偏强 | G4: 强周期/供给出清 | H4: 基本面筛选与排序；非交易仓位指令 | I4: 一级行业 | J4: 先用库存、供给、订单确认反转；价格本身不能直接等同高景气。
A5: 基础化工 | B5: =基础化工!$P$4 -> 8 | C5: =基础化工!$P$5 -> 6.8 | D5: =基础化工!$P$6 -> 6.6 | E5: =基础化工!$G$18 -> 7.4 | F5: =IF(E5>=8.5,"强/防过热",IF(E5>=7.5,"偏强",IF(E5>=6.5,"中性偏强",IF(E5>=5,"中性",IF(E5>=3,"偏弱","低迷"))))) -> 中性偏强 | G5: 强周期/供给出清 | H5: 基本面筛选与排序；非交易仓位指令 | I5: 一级行业 | J5: 先用库存、供给、订单确认反转；价格本身不能直接等同高景气。
A6: 钢铁 | B6: =钢铁!$P$4 -> 8 | C6: =钢铁!$P$5 -> 6 | D6: =钢铁!$P$6 -> 6 | E6: =钢铁!$G$18 -> 7 | F6: =IF(E6>=8.5,"强/防过热",IF(E6>=7.5,"偏强",IF(E6>=6.5,"中性偏强",IF(E6>=5,"中性",IF(E6>=3,"偏弱","低迷"))))) -> 中性偏强 | G6: 强周期/供给出清 | H6: 基本面筛选与排序；非交易仓位指令 | I6: 一级行业 | J6: 先用库存、供给、订单确认反转；价格本身不能直接等同高景气。
A7: 有色金属 | B7: =有色金属!$P$4 -> 6.9 | C7: =有色金属!$P$5 -> 8.7 | D7: =有色金属!$P$6 -> 8.6 | E7: =有色金属!$G$18 -> 7.9 | F7: =IF(E7>=8.5,"强/防过热",IF(E7>=7.5,"偏强",IF(E7>=6.5,"中性偏强",IF(E7>=5,"中性",IF(E7>=3,"偏弱","低迷"))))) -> 偏强 | G7: 资源品/宏观供需 | H7: 基本面筛选与排序；非交易仓位指令 | I7: 一级行业 | J7: 库存、加工费、美元和价格共同确认。
A8: 电子 | B8: =电子!$P$4 -> 8.2 | C8: =电子!$P$5 -> 7.2 | D8: =电子!$P$6 -> 8 | E8: =电子!$G$19 -> 7.8 | F8: =IF(E8>=8.5,"强/防过热",IF(E8>=7.5,"偏强",IF(E8>=6.5,"中性偏强",IF(E8>=5,"中性",IF(E8>=3,"偏弱","低迷"))))) -> 偏强 | G8: 科技制造/订单库存周期 | H8: 基本面筛选与排序；非交易仓位指令 | I8: 一级行业 | J8: 订单、库存和利用率优先；不同子行业拆分后再汇总。
A9: 家用电器 | B9: =家用电器!$P$4 -> 5.3 | C9: =家用电器!$P$5 -> 7.2 | D9: =家用电器!$P$6 -> 7.4 | E9: =家用电器!$G$18 -> 6.5 | F9: =IF(E9>=8.5,"强/防过热",IF(E9>=7.5,"偏强",IF(E9>=6.5,"中性偏强",IF(E9>=5,"中性",IF(E9>=3,"偏弱","低迷"))))) -> 中性偏强 | G9: 消费/需求恢复 | H9: 基本面筛选与排序；非交易仓位指令 | I9: 一级行业 | J9: 高频需求、渠道库存和价格/利润交叉确认，使用季调数据。
A10: 食品饮料 | B10: =食品饮料!$P$4 -> 5.9 | C10: =食品饮料!$P$5 -> 6.8 | D10: =食品饮料!$P$6 -> 7.4 | E10: =食品饮料!$G$18 -> 6.7 | F10: =IF(E10>=8.5,"强/防过热",IF(E10>=7.5,"偏强",IF(E10>=6.5,"中性偏强",IF(E10>=5,"中性",IF(E10>=3,"偏弱","低迷"))))) -> 中性偏强 | G10: 防御/成熟 | H10: 基本面筛选与排序；非交易仓位指令 | I10: 一级行业 | J10: 同步经营和现金流优先；先行指标只作边际变化确认。
A11: 纺织服饰 | B11: =纺织服饰!$P$4 -> 7.6 | C11: =纺织服饰!$P$5 -> 6.7 | D11: =纺织服饰!$P$6 -> 6 | E11: =纺织服饰!$G$18 -> 6.9 | F11: =IF(E11>=8.5,"强/防过热",IF(E11>=7.5,"偏强",IF(E11>=6.5,"中性偏强",IF(E11>=5,"中性",IF(E11>=3,"偏弱","低迷"))))) -> 中性偏强 | G11: 消费/需求恢复 | H11: 基本面筛选与排序；非交易仓位指令 | I11: 一级行业 | J11: 高频需求、渠道库存和价格/利润交叉确认，使用季调数据。
A12: 轻工制造 | B12: =轻工制造!$P$4 -> 6.6 | C12: =轻工制造!$P$5 -> 5 | D12: =轻工制造!$P$6 -> 6 | E12: =轻工制造!$G$18 -> 5.8 | F12: =IF(E12>=8.5,"强/防过热",IF(E12>=7.5,"偏强",IF(E12>=6.5,"中性偏强",IF(E12>=5,"中性",IF(E12>=3,"偏弱","低迷"))))) -> 中性 | G12: 消费/需求恢复 | H12: 基本面筛选与排序；非交易仓位指令 | I12: 一级行业 | J12: 高频需求、渠道库存和价格/利润交叉确认，使用季调数据。
A13: 医药生物 | B13: =医药生物!$P$4 -> 8 | C13: =医药生物!$P$5 -> 7.2 | D13: =医药生物!$P$6 -> 8 | E13: =医药生物!$G$18 -> 7.7 | F13: =IF(E13>=8.5,"强/防过热",IF(E13>=7.5,"偏强",IF(E13>=6.5,"中性偏强",IF(E13>=5,"中性",IF(E13>=3,"偏弱","低迷"))))) -> 偏强 | G13: 科技制造/订单库存周期 | H13: 基本面筛选与排序；非交易仓位指令 | I13: 一级行业 | J13: 订单、库存和利用率优先；不同子行业拆分后再汇总。
A14: 公用事业 | B14: =公用事业!$P$4 -> 9 | C14: =公用事业!$P$5 -> 7.1 | D14: =公用事业!$P$6 -> 8 | E14: =公用事业!$G$18 -> 7.9 | F14: =IF(E14>=8.5,"强/防过热",IF(E14>=7.5,"偏强",IF(E14>=6.5,"中性偏强",IF(E14>=5,"中性",IF(E14>=3,"偏弱","低迷"))))) -> 偏强 | G14: 防御/成熟 | H14: 基本面筛选与排序；非交易仓位指令 | I14: 一级行业 | J14: 同步经营和现金流优先；先行指标只作边际变化确认。
A15: 交通运输 | B15: =交通运输!$P$4 -> 8 | C15: =交通运输!$P$5 -> 8 | D15: =交通运输!$P$6 -> 8 | E15: =交通运输!$G$18 -> 8 | F15: =IF(E15>=8.5,"强/防过热",IF(E15>=7.5,"偏强",IF(E15>=6.5,"中性偏强",IF(E15>=5,"中性",IF(E15>=3,"偏弱","低迷"))))) -> 偏强 | G15: 消费/需求恢复 | H15: 基本面筛选与排序；非交易仓位指令 | I15: 一级行业 | J15: 高频需求、渠道库存和价格/利润交叉确认，使用季调数据。
A16: 房地产 | B16: =房地产!$P$4 -> 4.9 | C16: =房地产!$P$5 -> 4 | D16: =房地产!$P$6 -> 3.4 | E16: =房地产!$G$18 -> 4.3 | F16: =IF(E16>=8.5,"强/防过热",IF(E16>=7.5,"偏强",IF(E16>=6.5,"中性偏强",IF(E16>=5,"中性",IF(E16>=3,"偏弱","低迷"))))) -> 偏弱 | G16: 强周期/供给出清 | H16: 基本面筛选与排序；非交易仓位指令 | I16: 一级行业 | J16: 先用库存、供给、订单确认反转；价格本身不能直接等同高景气。
A17: 商贸零售 | B17: =商贸零售!$P$4 -> 5.5 | C17: =商贸零售!$P$5 -> 7.4 | D17: =商贸零售!$P$6 -> 6.6 | E17: =商贸零售!$G$18 -> 6.5 | F17: =IF(E17>=8.5,"强/防过热",IF(E17>=7.5,"偏强",IF(E17>=6.5,"中性偏强",IF(E17>=5,"中性",IF(E17>=3,"偏弱","低迷"))))) -> 中性偏强 | G17: 消费/需求恢复 | H17: 基本面筛选与排序；非交易仓位指令 | I17: 一级行业 | J17: 高频需求、渠道库存和价格/利润交叉确认，使用季调数据。
A18: 社会服务 | B18: =社会服务!$P$4 -> 7.2 | C18: =社会服务!$P$5 -> 7.6 | D18: =社会服务!$P$6 -> 5.4 | E18: =社会服务!$G$18 -> 7 | F18: =IF(E18>=8.5,"强/防过热",IF(E18>=7.5,"偏强",IF(E18>=6.5,"中性偏强",IF(E18>=5,"中性",IF(E18>=3,"偏弱","低迷"))))) -> 中性偏强 | G18: 消费/需求恢复 | H18: 基本面筛选与排序；非交易仓位指令 | I18: 一级行业 | J18: 高频需求、渠道库存和价格/利润交叉确认，使用季调数据。
A19: 综合 | B19: =综合!$P$4 -> 6.4 | C19: =综合!$P$5 -> 6.7 | D19: =综合!$P$6 -> 7.2 | E19: =综合!$G$15 -> 6.6 | F19: =IF(E19>=8.5,"强/防过热",IF(E19>=7.5,"偏强",IF(E19>=6.5,"中性偏强",IF(E19>=5,"中性",IF(E19>=3,"偏弱","低迷"))))) -> 中性偏强 | G19: 扩张/订单周期 | H19: 基本面筛选与排序；非交易仓位指令 | I19: 一级行业 | J19: 订单、需求和利润三段式确认，避免单一宏观指标主导。
A20: 建筑材料 | B20: =建筑材料!$P$4 -> 4.8 | C20: =建筑材料!$P$5 -> 4.9 | D20: =建筑材料!$P$6 -> 4 | E20: =建筑材料!$G$18 -> 4.7 | F20: =IF(E20>=8.5,"强/防过热",IF(E20>=7.5,"偏强",IF(E20>=6.5,"中性偏强",IF(E20>=5,"中性",IF(E20>=3,"偏弱","低迷"))))) -> 偏弱 | G20: 强周期/供给出清 | H20: 基本面筛选与排序；非交易仓位指令 | I20: 一级行业 | J20: 先用库存、供给、订单确认反转；价格本身不能直接等同高景气。
A21: 建筑装饰 | B21: =建筑装饰!$P$4 -> 7.1 | C21: =建筑装饰!$P$5 -> 5.3 | D21: =建筑装饰!$P$6 -> 6 | E21: =建筑装饰!$G$18 -> 6.3 | F21: =IF(E21>=8.5,"强/防过热",IF(E21>=7.5,"偏强",IF(E21>=6.5,"中性偏强",IF(E21>=5,"中性",IF(E21>=3,"偏弱","低迷"))))) -> 中性 | G21: 政策资本开支/交付 | H21: 基本面筛选与排序；非交易仓位指令 | I21: 一级行业 | J21: 政策与规划只作确认项，必须由招标、交付、回款和利润验证。
A22: 电力设备 | B22: =电力设备!$P$4 -> 8.8 | C22: =电力设备!$P$5 -> 6.4 | D22: =电力设备!$P$6 -> 5.9 | E22: =电力设备!$G$19 -> 7.4 | F22: =IF(E22>=8.5,"强/防过热",IF(E22>=7.5,"偏强",IF(E22>=6.5,"中性偏强",IF(E22>=5,"中性",IF(E22>=3,"偏弱","低迷"))))) -> 中性偏强 | G22: 政策资本开支/交付 | H22: 基本面筛选与排序；非交易仓位指令 | I22: 一级行业 | J22: 政策与规划只作确认项，必须由招标、交付、回款和利润验证。
A23: 国防军工 | B23: =国防军工!$P$4 -> 7.2 | C23: =国防军工!$P$5 -> 7.7 | D23: =国防军工!$P$6 -> 7.2 | E23: =国防军工!$G$18 -> 7.4 | F23: =IF(E23>=8.5,"强/防过热",IF(E23>=7.5,"偏强",IF(E23>=6.5,"中性偏强",IF(E23>=5,"中性",IF(E23>=3,"偏弱","低迷"))))) -> 中性偏强 | G23: 政策资本开支/交付 | H23: 基本面筛选与排序；非交易仓位指令 | I23: 一级行业 | J23: 政策与规划只作确认项，必须由招标、交付、回款和利润验证。
A24: 计算机 | B24: =计算机!$P$4 -> 8.5 | C24: =计算机!$P$5 -> 7.6 | D24: =计算机!$P$6 -> 6.6 | E24: =计算机!$G$18 -> 7.9 | F24: =IF(E24>=8.5,"强/防过热",IF(E24>=7.5,"偏强",IF(E24>=6.5,"中性偏强",IF(E24>=5,"中性",IF(E24>=3,"偏弱","低迷"))))) -> 偏强 | G24: 科技制造/订单库存周期 | H24: 基本面筛选与排序；非交易仓位指令 | I24: 一级行业 | J24: 订单、库存和利用率优先；不同子行业拆分后再汇总。
A25: 传媒 | B25: =传媒!$P$4 -> 7.2 | C25: =传媒!$P$5 -> 7 | D25: =传媒!$P$6 -> 6.6 | E25: =传媒!$G$18 -> 7 | F25: =IF(E25>=8.5,"强/防过热",IF(E25>=7.5,"偏强",IF(E25>=6.5,"中性偏强",IF(E25>=5,"中性",IF(E25>=3,"偏弱","低迷"))))) -> 中性偏强 | G25: 消费/需求恢复 | H25: 基本面筛选与排序；非交易仓位指令 | I25: 一级行业 | J25: 高频需求、渠道库存和价格/利润交叉确认，使用季调数据。
A26: 通信 | B26: =通信!$P$4 -> 9.5 | C26: =通信!$P$5 -> 8.5 | D26: =通信!$P$6 -> 8 | E26: =通信!$G$18 -> 8.9 | F26: =IF(E26>=8.5,"强/防过热",IF(E26>=7.5,"偏强",IF(E26>=6.5,"中性偏强",IF(E26>=5,"中性",IF(E26>=3,"偏弱","低迷"))))) -> 强/防过热 | G26: 科技制造/订单库存周期 | H26: 基本面筛选与排序；非交易仓位指令 | I26: 一级行业 | J26: 订单、库存和利用率优先；不同子行业拆分后再汇总。
A27: 银行 | B27: =银行!$P$4 -> 8 | C27: =银行!$P$5 -> 6.5 | D27: =银行!$P$6 -> 6.6 | E27: =银行!$G$18 -> 7 | F27: =IF(E27>=8.5,"强/防过热",IF(E27>=7.5,"偏强",IF(E27>=6.5,"中性偏强",IF(E27>=5,"中性",IF(E27>=3,"偏弱","低迷"))))) -> 中性偏强 | G27: 防御/成熟 | H27: 基本面筛选与排序；非交易仓位指令 | I27: 一级行业 | J27: 同步经营和现金流优先；先行指标只作边际变化确认。
A28: 非银金融 | B28: =非银金融!$P$4 -> 7.1 | C28: =非银金融!$P$5 -> 7.1 | D28: =非银金融!$P$6 -> 7.4 | E28: =非银金融!$G$18 -> 7.2 | F28: =IF(E28>=8.5,"强/防过热",IF(E28>=7.5,"偏强",IF(E28>=6.5,"中性偏强",IF(E28>=5,"中性",IF(E28>=3,"偏弱","低迷"))))) -> 中性偏强 | G28: 信用/风险偏好周期 | H28: 基本面筛选与排序；非交易仓位指令 | I28: 一级行业 | J28: 信用与资产质量优先；券商、保险、银行不宜混算。
A29: 汽车 | B29: =汽车!$P$4 -> 7.3 | C29: =汽车!$P$5 -> 8 | D29: =汽车!$P$6 -> 7.4 | E29: =汽车!$G$18 -> 7.6 | F29: =IF(E29>=8.5,"强/防过热",IF(E29>=7.5,"偏强",IF(E29>=6.5,"中性偏强",IF(E29>=5,"中性",IF(E29>=3,"偏弱","低迷"))))) -> 偏强 | G29: 消费/需求恢复 | H29: 基本面筛选与排序；非交易仓位指令 | I29: 一级行业 | J29: 高频需求、渠道库存和价格/利润交叉确认，使用季调数据。
A30: 机械设备 | B30: =机械设备!$P$4 -> 7.5 | C30: =机械设备!$P$5 -> 7.5 | D30: =机械设备!$P$6 -> 6 | E30: =机械设备!$G$18 -> 7.2 | F30: =IF(E30>=8.5,"强/防过热",IF(E30>=7.5,"偏强",IF(E30>=6.5,"中性偏强",IF(E30>=5,"中性",IF(E30>=3,"偏弱","低迷"))))) -> 中性偏强 | G30: 科技制造/订单库存周期 | H30: 基本面筛选与排序；非交易仓位指令 | I30: 一级行业 | J30: 订单、库存和利用率优先；不同子行业拆分后再汇总。
A31: 煤炭 | B31: =煤炭!$P$4 -> 7.6 | C31: =煤炭!$P$5 -> 7.6 | D31: =煤炭!$P$6 -> 6.6 | E31: =煤炭!$G$18 -> 7.5 | F31: =IF(E31>=8.5,"强/防过热",IF(E31>=7.5,"偏强",IF(E31>=6.5,"中性偏强",IF(E31>=5,"中性",IF(E31>=3,"偏弱","低迷"))))) -> 偏强 | G31: 强周期/供给出清 | H31: 基本面筛选与排序；非交易仓位指令 | I31: 一级行业 | J31: 先用库存、供给、订单确认反转；价格本身不能直接等同高景气。
A32: 石油石化 | B32: =石油石化!$P$4 -> 7.6 | C32: =石油石化!$P$5 -> 6 | D32: =石油石化!$P$6 -> 6.6 | E32: =石油石化!$G$18 -> 6.9 | F32: =IF(E32>=8.5,"强/防过热",IF(E32>=7.5,"偏强",IF(E32>=6.5,"中性偏强",IF(E32>=5,"中性",IF(E32>=3,"偏弱","低迷"))))) -> 中性偏强 | G32: 强周期/供给出清 | H32: 基本面筛选与排序；非交易仓位指令 | I32: 一级行业 | J32: 先用库存、供给、订单确认反转；价格本身不能直接等同高景气。
A33: 环保 | B33: =环保!$P$4 -> 8 | C33: =环保!$P$5 -> 6.5 | D33: =环保!$P$6 -> 6 | E33: =环保!$G$18 -> 7.1 | F33: =IF(E33>=8.5,"强/防过热",IF(E33>=7.5,"偏强",IF(E33>=6.5,"中性偏强",IF(E33>=5,"中性",IF(E33>=3,"偏弱","低迷"))))) -> 中性偏强 | G33: 政策资本开支/交付 | H33: 基本面筛选与排序；非交易仓位指令 | I33: 一级行业 | J33: 政策与规划只作确认项，必须由招标、交付、回款和利润验证。
A34: 美容护理 | B34: =美容护理!$P$4 -> 5.8 | C34: =美容护理!$P$5 -> 7.6 | D34: =美容护理!$P$6 -> 7.2 | E34: =美容护理!$G$18 -> 6.8 | F34: =IF(E34>=8.5,"强/防过热",IF(E34>=7.5,"偏强",IF(E34>=6.5,"中性偏强",IF(E34>=5,"中性",IF(E34>=3,"偏弱","低迷"))))) -> 中性偏强 | G34: 消费/需求恢复 | H34: 基本面筛选与排序；非交易仓位指令 | I34: 一级行业 | J34: 高频需求、渠道库存和价格/利润交叉确认，使用季调数据。
A35: 半导体 | B35: =半导体!$P$4 -> 8 | C35: =半导体!$P$5 -> 7.6 | D35: =半导体!$P$6 -> 8.6 | E35: =半导体!$G$22 -> 8 | F35: =IF(E35>=8.5,"强/防过热",IF(E35>=7.5,"偏强",IF(E35>=6.5,"中性偏强",IF(E35>=5,"中性",IF(E35>=3,"偏弱","低迷"))))) -> 偏强 | G35: 科技制造/订单库存周期 | H35: 基本面筛选与排序；非交易仓位指令 | I35: 重点细分行业 | J35: 订单、库存和利用率优先；不同子行业拆分后再汇总。
A36: 新能源 | B36: =新能源!$P$4 -> 8.6 | C36: =新能源!$P$5 -> 6.5 | D36: =新能源!$P$6 -> 5.4 | E36: =新能源!$G$22 -> 7.3 | F36: =IF(E36>=8.5,"强/防过热",IF(E36>=7.5,"偏强",IF(E36>=6.5,"中性偏强",IF(E36>=5,"中性",IF(E36>=3,"偏弱","低迷"))))) -> 中性偏强 | G36: 强周期/供给出清 | H36: 基本面筛选与排序；非交易仓位指令 | I36: 重点细分行业 | J36: 先用库存、供给、订单确认反转；价格本身不能直接等同高景气。
A37: 医药医疗 | B37: =医药医疗!$P$4 -> 8 | C37: =医药医疗!$P$5 -> 7.2 | D37: =医药医疗!$P$6 -> 8 | E37: =医药医疗!$G$22 -> 7.7 | F37: =IF(E37>=8.5,"强/防过热",IF(E37>=7.5,"偏强",IF(E37>=6.5,"中性偏强",IF(E37>=5,"中性",IF(E37>=3,"偏弱","低迷"))))) -> 偏强 | G37: 科技制造/订单库存周期 | H37: 基本面筛选与排序；非交易仓位指令 | I37: 重点细分行业 | J37: 订单、库存和利用率优先；不同子行业拆分后再汇总。
A38: 高端制造 | B38: =高端制造!$P$4 -> 7.6 | C38: =高端制造!$P$5 -> 7 | D38: =高端制造!$P$6 -> 6 | E38: =高端制造!$G$19 -> 7.2 | F38: =IF(E38>=8.5,"强/防过热",IF(E38>=7.5,"偏强",IF(E38>=6.5,"中性偏强",IF(E38>=5,"中性",IF(E38>=3,"偏弱","低迷"))))) -> 中性偏强 | G38: 科技制造/订单库存周期 | H38: 基本面筛选与排序；非交易仓位指令 | I38: 重点细分行业 | J38: 订单、库存和利用率优先；不同子行业拆分后再汇总。
A39: 人形机器人 | B39: =人形机器人!$P$4 -> 8.4 | C39: =人形机器人!$P$5 -> 7.6 | D39: =人形机器人!$P$6 -> 5.8 | E39: =人形机器人!$G$19 -> 7.8 | F39: =IF(E39>=8.5,"强/防过热",IF(E39>=7.5,"偏强",IF(E39>=6.5,"中性偏强",IF(E39>=5,"中性",IF(E39>=3,"偏弱","低迷"))))) -> 偏强 | G39: 早期产业化/兑现 | H39: 基本面筛选与排序；非交易仓位指令 | I39: 重点细分行业 | J39: 量产、订单、交付优先；热度与规划指标不得主导评分。
A40: AI算力 | B40: =AI算力!$P$4 -> 9.4 | C40: =AI算力!$P$5 -> 8.5 | D40: =AI算力!$P$6 -> 8 | E40: =AI算力!$G$19 -> 8.9 | F40: =IF(E40>=8.5,"强/防过热",IF(E40>=7.5,"偏强",IF(E40>=6.5,"中性偏强",IF(E40>=5,"中性",IF(E40>=3,"偏弱","低迷"))))) -> 强/防过热 | G40: 早期产业化/兑现 | H40: 基本面筛选与排序；非交易仓位指令 | I40: 重点细分行业 | J40: 量产、订单、交付优先；热度与规划指标不得主导评分。
...

Sheet 农林牧渔
A1: 行业景气度量化跟踪体系（参数优化版）— 农林牧渔
A2: 默认阶段框架：强周期/供给出清｜先行/同步/滞后=50%/35%/15%。先用库存、供给、订单确认反转；价格本身不能直接等同高景气。｜核心验证：供给周期与养殖价差；必选：母猪存栏/淘汰率、仔猪价、饲料成本
A3: 指标名称 | B3: 数据来源 | C3: 最新数值 | D3: 单位 | E3: 趋势 | F3: 权重 | G3: 评分 (1-10) | H3: 评分阈值说明 | I3: 历史分位 | J3: 对景气度影响 | K3: 跟踪频率 | L3: 原权重 | M3: 参数优化建议 | N3: 评分口径（更新时采用） | O3: 阶段分项 | P3: 公式分数
A4: 【第一部分：先行指标（Leading Indicators）——提前1-2个季度预示景气变化】 | O4: 先行 | P4: =ROUND(SUMPRODUCT(F5:F9,G5:G9)/SUM(F5:F9),1) -> 7.2
A5: 1-能繁母猪存栏量变化 | B5: 农业农村部 | C5: +1.2 | D5: %YoY | E5: 企稳 | F5: 0.125 | G5: =IFERROR(VLOOKUP("农林牧渔|1-能繁母猪存栏量变化",指标更新台账_v3!$A$2:$I$600,9,FALSE()),0) -> 6 | H5: >5%=10分,2-5%=8分,0-2%=6分,-2-0%=4分,<-2%=2分 | I5: 45% | J5: 产能温和回升，供给端压力可控 | K5: 月度 | L5: 0.15 | M5: 目标组权重 50%；按同组相对重要性归一化。 | N5: 采用5年滚动分位+同比/环比双阈值；数据滞后超过一个频率周期时自动降权。 | O5: 同步 | P5: =ROUND(SUMPRODUCT(F11:F14,G11:G14)/SUM(F11:F14),1) -> 6.5
A6: 2-仔猪价格变化 | B6: 农业农村部/博亚和讯 | C6: +35 | D6: %YoY | E6: 大涨 | F6: 0.125 | G6: =IFERROR(VLOOKUP("农林牧渔|2-仔猪价格变化",指标更新台账_v3!$A$2:$I$600,9,FALSE()),0) -> 9 | H6: >30%=10分,10-30%=8分,0-10%=6分,-10-0%=4分,<-10%=2分 | I6: 78% | J6: 补栏积极性高，预示6个月后出栏增加 | K6: 周度 | L6: 0.15 | M6: 目标组权重 50%；按同组相对重要性归一化。 | N6: 改为5年滚动分位(P20/P40/P60/P80)+3个月动量；须与库存、价差或利润交叉确认。 | O6: 滞后 | P6: =ROUND(SUMPRODUCT(F16:F18,G16:G18)/SUM(F16:F18),1) -> 6.6
A7: 3-饲料价格变化 | B7: 中国饲料工业协会 | C7: -3.5 | D7: %YoY | E7: 下行 | F7: 0.1 | G7: =IFERROR(VLOOKUP("农林牧渔|3-饲料价格变化",指标更新台账_v3!$A$2:$I$600,9,FALSE()),0) -> 8 | H7: <-10%=10分,-10-0%=8分,0-5%=6分,5-10%=4分,>10%=2分 | I7: 35% | J7: 成本端改善，养殖利润修复 | K7: 月度 | L7: 0.12 | M7: 目标组权重 50%；按同组相对重要性归一化。 | N7: 改为5年滚动分位(P20/P40/P60/P80)+3个月动量；须与库存、价差或利润交叉确认。
A8: 4-农产品进口量增速 | B8: 海关总署 | C8: +2.1 | D8: %YoY | E8: 上行 | F8: 0.0833 | G8: =IFERROR(VLOOKUP("农林牧渔|4-农产品进口量增速",指标更新台账_v3!$A$2:$I$600,9,FALSE()),0) -> 6 | H8: <-5%=10分,-5-0%=8分,0-5%=6分,5-10%=4分,>10%=2分 | I8: 52% | J8: 进口平稳，国内供给基本自足 | K8: 月度 | L8: 0.1 | M8: 目标组权重 50%；按同组相对重要性归一化。 | N8: 采用5年滚动分位+同比/环比双阈值；数据滞后超过一个频率周期时自动降权。
A9: 5-种植面积变化 | B9: 国家统计局 | C9: +0.8 | D9: %YoY | E9: 企稳 | F9: 0.0667 | G9: =IFERROR(VLOOKUP("农林牧渔|5-种植面积变化",指标更新台账_v3!$A$2:$I$600,9,FALSE()),0) -> 6 | H9: >2%=10分,0-2%=8分,-2-0%=6分,-5--2%=4分,<-5%=2分 | I9: 48% | J9: 种植面积稳定，产量预期平稳 | K9: 年度 | L9: 0.08 | M9: 目标组权重 50%；按同组相对重要性归一化。 | N9: 采用5年滚动分位+同比/环比双阈值；数据滞后超过一个频率周期时自动降权。
A10: 【第二部分：同步指标（Coincident Indicators）——与当前景气同步变动】
A11: 6-生猪出栏均价 | B11: 农业农村部 | C11: 15.8 | D11: 元/公斤 | E11: 上行 | F11: 0.1312 | G11: =IFERROR(VLOOKUP("农林牧渔|6-生猪出栏均价",指标更新台账_v3!$A$2:$I$600,9,FALSE()),0) -> 6 | H11: >20=10分,16-20=8分,14-16=6分,12-14=4分,<12=2分 | I11: 55% | J11: 猪价温和回升，养殖盈利改善 | K11: 周度 | L11: 0.15 | M11: 目标组权重 35%；按同组相对重要性归一化。 | N11: 改为5年滚动分位(P20/P40/P60/P80)+3个月动量；须与库存、价差或利润交叉确认。
A12: 7-白羽肉鸡价格 | B12: 博亚和讯 | C12: 8.2 | D12: 元/公斤 | E12: 上行 | F12: 0.0875 | G12: =IFERROR(VLOOKUP("农林牧渔|7-白羽肉鸡价格",指标更新台账_v3!$A$2:$I$600,9,FALSE()),0) -> 8 | H12: >10=10分,8-10=8分,7-8=6分,6-7=4分,<6=2分 | I12: 62% | J12: 禽价处于较好水平，养殖利润可观 | K12: 周度 | L12: 0.1 | M12: 目标组权重 35%；按同组相对重要性归一化。 | N12: 改为5年滚动分位(P20/P40/P60/P80)+3个月动量；须与库存、价差或利润交叉确认。
A13: 8-水产批发价格指数 | B13: 农业农村部 | C13: 112 | D13: 点 | E13: 上行 | F13: 0.07 | G13: =IFERROR(VLOOKUP("农林牧渔|8-水产批发价格指数",指标更新台账_v3!$A$2:$I$600,9,FALSE()),0) -> 6 | H13: >120=10分,110-120=8分,100-110=6分,90-100=4分,<90=2分 | I13: 58% | J13: 水产价格温和上涨，消费旺季来临 | K13: 周度 | L13: 0.08 | M13: 目标组权重 35%；按同组相对重要性归一化。 | N13: 改为5年滚动分位(P20/P40/P60/P80)+3个月动量；须与库存、价差或利润交叉确认。
A14: 9-农产品批发价格200指数 | B14: 农业农村部 | C14: 118 | D14: 点 | E14: 上行 | F14: 0.0612 | G14: =IFERROR(VLOOKUP("农林牧渔|9-农产品批发价格200指数",指标更新台账_v3!$A$2:$I$600,9,FALSE()),0) -> 6 | H14: >130=10分,120-130=8分,110-120=6分,100-110=4分,<100=2分 | I14: 54% | J14: 农产品价格整体平稳略升 | K14: 日度 | L14: 0.07 | M14: 目标组权重 35%；按同组相对重要性归一化。 | N14: 改为5年滚动分位(P20/P40/P60/P80)+3个月动量；须与库存、价差或利润交叉确认。
A15: 【第三部分：滞后指标（Lagging Indicators）——滞后1-2个季度反映景气变化】
A16: 10-养殖企业季度净利润率 | B16: 上市公司财报 | C16: 6.5 | D16: % | E16: 上行 | F16: 0.06 | G16: =IFERROR(VLOOKUP("农林牧渔|10-养殖企业季度净利润率",指标更新台账_v3!$A$2:$I$600,9,FALSE()),0) -> 6 | H16: >15%=10分,5-15%=8分,0-5%=6分,-5-0%=4分,<-5%=2分 | I16: 48% | J16: Q1养殖利润转正，景气度回升 | K16: 季度 | L16: 0.1 | M16: 目标组权重 15%；按同组相对重要性归一化。 | N16: 采用TTM/滚动4季同比+历史分位；剔除一次性损益，IRR按项目现金流复核。
A17: 11-农林牧渔固定资产投资增速 | B17: 国家统计局 | C17: +8.2 | D17: %YoY | E17: 上行 | F17: 0.048 | G17: =IFERROR(VLOOKUP("农林牧渔|11-农林牧渔固定资产投资增速",指标更新台账_v3!$A$2:$I$600,9,FALSE()),0) -> 8 | H17: >15%=10分,5-15%=8分,0-5%=6分,-5-0%=4分,<-5%=2分 | I17: 60% | J17: 投资回暖，产能扩张意愿增强 | K17: 季度 | L17: 0.08 | M17: 目标组权重 15%；按同组相对重要性归一化。 | N17: 采用5年滚动分位+同比/环比双阈值；数据滞后超过一个频率周期时自动降权。
A18: 12-CPI食品项同比 | B18: 国家统计局 | C18: +1.2 | D18: % | E18: 上行 | F18: 0.042 | G18: =IFERROR(VLOOKUP("农林牧渔|12-CPI食品项同比",指标更新台账_v3!$A$2:$I$600,9,FALSE()),0) -> 6 | H18: >5%=10分,2-5%=8分,0-2%=6分,-2-0%=4分,<-2%=2分 | I18: 42% | J18: 食品通胀温和，终端需求平稳 | K18: 月度 | L18: 0.07 | M18: 目标组权重 15%；按同组相对重要性归一化。 | N18: 采用5年滚动分位+同比/环比双阈值；数据滞后超过一个频率周期时自动降权。
A19: 行业综合景气度加权得分 | G19: =ROUND(SUMPRODUCT(F5:F18,G5:G18),1) -> 6.8 | H19: 综合分=Σ(建议权重×单项评分)，建议权重和=100%。

Sheet 基础化工
A1: 行业景气度量化跟踪体系（参数优化版）— 基础化工
A2: 默认阶段框架：强周期/供给出清｜先行/同步/滞后=50%/35%/15%。先用库存、供给、订单确认反转；价格本身不能直接等同高景气。｜核心验证：库存周期与价差修复；必选：下游订单、库存、计划新增产能
A3: 指标名称 | B3: 数据来源 | C3: 最新数值 | D3: 单位 | E3: 趋势 | F3: 权重 | G3: 评分 (1-10) | H3: 评分阈值说明 | I3: 历史分位 | J3: 对景气度影响 | K3: 跟踪频率 | L3: 原权重 | M3: 参数优化建议 | N3: 评分口径（更新时采用） | O3: 阶段分项 | P3: 公式分数
A4: 【第一部分：先行指标（Leading Indicators）——提前1-2个季度预示景气变化】 | O4: 先行 | P4: =ROUND(SUMPRODUCT(F5:F8,G5:G8)/SUM(F5:F8),1) -> 8
A5: 1-原油价格变化 | B5: WTI/布伦特 | C5: 72 | D5: 美元/桶 | E5: 下行 | F5: 0.15 | G5: =IFERROR(VLOOKUP("基础化工|1-原油价格变化",指标更新台账_v3!$A$2:$I$600,9,FALSE()),0) -> 8 | H5: 60-80=10分,50-60或80-90=8分,40-50或90-100=6分,<40或>100=4分 | I5: 55% | J5: 油价中枢回落，成本压力缓解 | K5: 日度 | L5: 0.15 | M5: 目标组权重 50%；按同组相对重要性归一化。 | N5: 改为5年滚动分位(P20/P40/P60/P80)+3个月动量；须与库存、价差或利润交叉确认。 | O5: 同步 | P5: =ROUND(SUMPRODUCT(F10:F13,G10:G13)/SUM(F10:F13),1) -> 6.8
A6: 2-煤化工原料煤价格 | B6: 秦皇岛动力煤 | C6: 680 | D6: 元/吨 | E6: 下行 | F6: 0.12 | G6: =IFERROR(VLOOKUP("基础化工|2-煤化工原料煤价格",指标更新台账_v3!$A$2:$I$600,9,FALSE()),0) -> 10 | H6: <700=10分,700-800=8分,800-900=6分,900-1000=4分,>1000=2分 | I6: 30% | J6: 煤价处于低位，煤化工成本优势明显 | K6: 周度 | L6: 0.12 | M6: 目标组权重 50%；按同组相对重要性归一化。 | N6: 改为5年滚动分位(P20/P40/P60/P80)+3个月动量；须与库存、价差或利润交叉确认。 | O6: 滞后 | P6: =ROUND(SUMPRODUCT(F15:F17,G15:G17)/SUM(F15:F17),1) -> 6.6
A7: 3-化工品产能利用率 | B7: 卓创资讯 | C7: 74 | D7: % | E7: 上行 | F7: 0.13 | G7: =IFERROR(VLOOKUP("基础化工|3-化工品产能利用率",指标更新台账_v3!$A$2:$I$600,9,FALSE()),0) -> 6 | H7: >80%=10分,75-80%=8分,70-75%=6分,65-70%=4分,<65%=2分 | I7: 52% | J7: 产能利用率回升，供需格局改善 | K7: 月度 | L7: 0.13 | M7: 目标组权重 50%；按同组相对重要性归一化。 | N7: 采用TTM/滚动4季同比+历史分位；剔除一次性损益，IRR按项目现金流复核。
A8: 4-新增产能投放计划 | B8: 公司公告/行业协会 | C8: +3.5 | D8: % | E8: 放缓 | F8: 0.1 | G8: =IFERROR(VLOOKUP("基础化工|4-新增产能投放计划",指标更新台账_v3!$A$2:$I$600,9,FALSE()),0) -> 8 | H8: <2%=10分,2-5%=8分,5-8%=6分,8-12%=4分,>12%=2分 | I8: 45% | J8: 产能投放放缓，供给压力减轻 | K8: 季度 | L8: 0.1 | M8: 目标组权重 50%；按同组相对重要性归一化。 | N8: 采用5年滚动分位+同比/环比双阈值；数据滞后超过一个频率周期时自动降权。
A9: 【第二部分：同步指标（Coincident Indicators）——与当前景气同步变动】
A10: 5-中国化工产品价格指数(CCPI) | B10: 卓创资讯 | C10: 4850 | D10: 点 | E10: 上行 | F10: 0.1167 | G10: =IFERROR(VLOOKUP("基础化工|5-中国化工产品价格指数(CCPI)",指标更新台账_v3!$A$2:$I$600,9,FALSE()),0) -> 6 | H10: >5500=10分,5000-5500=8分,4500-5000=6分,4000-4500=4分,<4000=2分 | I10: 48% | J10: 化工品价格温和上涨，价差修复 | K10: 周度 | L10: 0.15 | M10: 目标组权重 35%；按同组相对重要性归一化。 | N10: 改为5年滚动分位(P20/P40/P60/P80)+3个月动量；须与库存、价差或利润交叉确认。
A11: 6-主要化工品价差 | B11: 百川盈孚 | C11: +5 | D11: %vs均值 | E11: 上行 | F11: 0.0933 | G11: =IFERROR(VLOOKUP("基础化工|6-主要化工品价差",指标更新台账_v3!$A$2:$I$600,9,FALSE()),0) -> 6 | H11: >历史均值20%=10分,0-20%=8分,-10-0%=6分,-20--10%=4分,<-20%=2分 | I11: 55% | J11: 价差改善，企业盈利空间扩大 | K11: 周度 | L11: 0.12 | M11: 目标组权重 35%；按同组相对重要性归一化。 | N11: 改为5年滚动分位(P20/P40/P60/P80)+3个月动量；须与库存、价差或利润交叉确认。
A12: 7-化工品库存天数 | B12: 卓创资讯 | C12: 18 | D12: 天 | E12: 下行 | F12: 0.0778 | G12: =IFERROR(VLOOKUP("基础化工|7-化工品库存天数",指标更新台账_v3!$A$2:$I$600,9,FALSE()),0) -> 8 | H12: <15天=10分,15-20天=8分,20-25天=6分,25-30天=4分,>30天=2分 | I12: 40% | J12: 库存健康，去库接近尾声 | K12: 月度 | L12: 0.1 | M12: 目标组权重 35%；按同组相对重要性归一化。 | N12: 采用同比、环比、历史分位三维评分；按去库/改善方向计分。
A13: 8-化工品出口增速 | B13: 海关总署 | C13: +12.5 | D13: %YoY | E13: 上行 | F13: 0.0622 | G13: =IFERROR(VLOOKUP("基础化工|8-化工品出口增速",指标更新台账_v3!$A$2:$I$600,9,FALSE()),0) -> 8 | H13: >15%=10分,5-15%=8分,0-5%=6分,-5-0%=4分,<-5%=2分 | I13: 65% | J13: 出口强劲，外需支撑景气度 | K13: 月度 | L13: 0.08 | M13: 目标组权重 35%；按同组相对重要性归一化。 | N13: 采用5年滚动分位+同比/环比双阈值；数据滞后超过一个频率周期时自动降权。
A14: 【第三部分：滞后指标（Lagging Indicators）——滞后1-2个季度反映景气变化】
A15: 9-化工企业季度ROE | B15: 上市公司财报 | C15: 7.5 | D15: % | E15: 上行 | F15: 0.06 | G15: =IFERROR(VLOOKUP("基础化工|9-化工企业季度ROE",指标更新台账_v3!$A$2:$I$600,9,FALSE()),0) -> 6 | H15: >12%=10分,8-12%=8分,4-8%=6分,0-4%=4分,<0%=2分 | I15: 50% | J15: Q1盈利修复，ROE回升 | K15: 季度 | L15: 0.1 | M15: 目标组权重 15%；按同组相对重要性归一化。 | N15: 采用TTM/滚动4季同比+历史分位；剔除一次性损益，IRR按项目现金流复核。
A16: 10-化工行业固定资产投资增速 | B16: 国家统计局 | C16: +8.5 | D16: %YoY | E16: 上行 | F16: 0.048 | G16: =IFERROR(VLOOKUP("基础化工|10-化工行业固定资产投资增速",指标更新台账_v3!$A$2:$I$600,9,FALSE()),0) -> 8 | H16: >10%=10分,5-10%=8分,0-5%=6分,-5-0%=4分,<-5%=2分 | I16: 58% | J16: 投资回暖，扩产意愿增强 | K16: 季度 | L16: 0.08 | M16: 目标组权重 15%；按同组相对重要性归一化。 | N16: 采用5年滚动分位+同比/环比双阈值；数据滞后超过一个频率周期时自动降权。
A17: 11-PPI化工原料同比 | B17: 国家统计局 | C17: +2.5 | D17: % | E17: 上行 | F17: 0.042 | G17: =IFERROR(VLOOKUP("基础化工|11-PPI化工原料同比",指标更新台账_v3!$A$2:$I$600,9,FALSE()),0) -> 6 | H17: >5%=10分,0-5%=8分,-3-0%=6分,-6--3%=4分,<-6%=2分 | I17: 55% | J17: 价格同比转正，通缩压力缓解 | K17: 月度 | L17: 0.07 | M17: 目标组权重 15%；按同组相对重要性归一化。 | N17: 采用5年滚动分位+同比/环比双阈值；数据滞后超过一个频率周期时自动降权。
A18: 行业综合景气度加权得分 | G18: =ROUND(SUMPRODUCT(F5:F17,G5:G17),1) -> 7.4 | H18: 综合分=Σ(建议权重×单项评分)，建议权重和=100%。

Sheet 钢铁
A1: 行业景气度量化跟踪体系（参数优化版）— 钢铁
A2: 默认阶段框架：强周期/供给出清｜先行/同步/滞后=50%/35%/15%。先用库存、供给、订单确认反转；价格本身不能直接等同高景气。｜核心验证：需求/去库与利润修复；必选：地产施工、基建实物量、库存变化
A3: 指标名称 | B3: 数据来源 | C3: 最新数值 | D3: 单位 | E3: 趋势 | F3: 权重 | G3: 评分 (1-10) | H3: 评分阈值说明 | I3: 历史分位 | J3: 对景气度影响 | K3: 跟踪频率 | L3: 原权重 | M3: 参数优化建议 | N3: 评分口径（更新时采用） | O3: 阶段分项 | P3: 公式分数
A4: 【第一部分：先行指标（Leading Indicators）——提前1-2个季度预示景气变化】 | O4: 先行 | P4: =ROUND(SUMPRODUCT(F5:F8,G5:G8)/SUM(F5:F8),1) -> 8
A5: 1-铁矿石价格变化 | B5: 普氏62%指数 | C5: 105 | D5: 美元/吨 | E5: 下行 | F5: 0.15 | G5: =IFERROR(VLOOKUP("钢铁|1-铁矿石价格变化",指标更新台账_v3!$A$2:$I$600,9,FALSE()),0) -> 8 | H5: 80-100=10分,70-80或100-120=8分,60-70或120-140=6分,<60或>140=4分 | I5: 62% | J5: 矿价回落，成本压力减轻 | K5: 日度 | L5: 0.15 | M5: 目标组权重 50%；按同组相对重要性归一化。 | N5: 改为5年滚动分位(P20/P40/P60/P80)+3个月动量；须与库存、价差或利润交叉确认。 | O5: 同步 | P5: =ROUND(SUMPRODUCT(F10:F13,G10:G13)/SUM(F10:F13),1) -> 6
A6: 2-焦煤价格变化 | B6: CCI指数 | C6: 1650 | D6: 元/吨 | E6: 下行 | F6: 0.12 | G6: =IFERROR(VLOOKUP("钢铁|2-焦煤价格变化",指标更新台账_v3!$A$2:$I$600,9,FALSE()),0) -> 8 | H6: <1500=10分,1500-1800=8分,1800-2200=6分,2200-2600=4分,>2600=2分 | I6: 45% | J6: 焦煤价格回落，焦炭成本下降 | K6: 周度 | L6: 0.12 | M6: 目标组权重 50%；按同组相对重要性归一化。 | N6: 改为5年滚动分位(P20/P40/P60/P80)+3个月动量；须与库存、价差或利润交叉确认。 | O6: 滞后 | P6: =ROUND(SUMPRODUCT(F15:F17,G15:G17)/SUM(F15:F17),1) -> 6
A7: 3-高炉开工率 | B7: Mysteel | C7: 82 | D7: % | E7: 上行 | F7: 0.13 | G7: =IFERROR(VLOOKUP("钢铁|3-高炉开工率",指标更新台账_v3!$A$2:$I$600,9,FALSE()),0) -> 8 | H7: >85%=10分,80-85%=8分,75-80%=6分,70-75%=4分,<70%=2分 | I7: 58% | J7: 开工率回升，生产积极性改善 | K7: 周度 | L7: 0.13 | M7: 目标组权重 50%；按同组相对重要性归一化。 | N7: 采用5年滚动分位+同比/环比双阈值；数据滞后超过一个频率周期时自动降权。
A8: 4-钢材社会库存变化 | B8: Mysteel | C8: -4.2 | D8: %MoM | E8: 去库 | F8: 0.1 | G8: =IFERROR(VLOOKUP("钢铁|4-钢材社会库存变化",指标更新台账_v3!$A$2:$I$600,9,FALSE()),0) -> 8 | H8: <-5%=10分,-5-0%=8分,0-5%=6分,5-10%=4分,>10%=2分 | I8: 38% | J8: 库存去化顺利，供需格局改善 | K8: 周度 | L8: 0.1 | M8: 目标组权重 50%；按同组相对重要性归一化。 | N8: 采用同比、环比、历史分位三维评分；按去库/改善方向计分。
A9: 【第二部分：同步指标（Coincident Indicators）——与当前景气同步变动】
A10: 5-螺纹钢现货价格 | B10: 上海钢联 | C10: 3450 | D10: 元/吨 | E10: 上行 | F10: 0.1167 | G10: =IFERROR(VLOOKUP("钢铁|5-螺纹钢现货价格",指标更新台账_v3!$A$2:$I$600,9,FALSE()),0) -> 6 | H10: >4000=10分,3500-4000=8分,3000-3500=6分,2500-3000=4分,<2500=2分 | I10: 48% | J10: 钢价温和回升，盈利边际改善 | K10: 日度 | L10: 0.15 | M10: 目标组权重 35%；按同组相对重要性归一化。 | N10: 改为5年滚动分位(P20/P40/P60/P80)+3个月动量；须与库存、价差或利润交叉确认。
A11: 6-热轧板卷价格 | B11: 上海钢联 | C11: 3650 | D11: 元/吨 | E11: 上行 | F11: 0.0778 | G11: =IFERROR(VLOOKUP("钢铁|6-热轧板卷价格",指标更新台账_v3!$A$2:$I$600,9,FALSE()),0) -> 6 | H11: >4200=10分,3800-4200=8分,3400-3800=6分,3000-3400=4分,<3000=2分 | I11: 45% | J11: 板材价格回升，制造业需求支撑 | K11: 日度 | L11: 0.1 | M11: 目标组权重 35%；按同组相对重要性归一化。 | N11: 改为5年滚动分位(P20/P40/P60/P80)+3个月动量；须与库存、价差或利润交叉确认。
A12: 7-钢厂盈利面 | B12: Mysteel | C12: 55 | D12: % | E12: 上行 | F12: 0.0933 | G12: =IFERROR(VLOOKUP("钢铁|7-钢厂盈利面",指标更新台账_v3!$A$2:$I$600,9,FALSE()),0) -> 6 | H12: >70%=10分,50-70%=8分,30-50%=6分,10-30%=4分,<10%=2分 | I12: 48% | J12: 盈利面扩大，过半钢厂实现盈利 | K12: 周度 | L12: 0.12 | M12: 目标组权重 35%；按同组相对重要性归一化。 | N12: 采用5年滚动分位+同比/环比双阈值；数据滞后超过一个频率周期时自动降权。
A13: 8-钢材表观消费量 | B13: 国家统计局 | C13: 1.05 | D13: 亿吨/年化 | E13: 上行 | F13: 0.0622 | G13: =IFERROR(VLOOKUP("钢铁|8-钢材表观消费量",指标更新台账_v3!$A$2:$I$600,9,FALSE()),0) -> 6 | H13: >1.1亿年化=10分,1.0-1.1亿=8分,0.9-1.0亿=6分,0.8-0.9亿=4分,<0.8亿=2分 | I13: 52% | J13: 表观消费回升，需求端改善 | K13: 月度 | L13: 0.08 | M13: 目标组权重 35%；按同组相对重要性归一化。 | N13: 采用季调同比+3个月环比；单月值用3个月移动均值过滤。
A14: 【第三部分：滞后指标（Lagging Indicators）——滞后1-2个季度反映景气变化】
A15: 9-钢铁企业季度净利润 | B15: 上市公司财报 | C15: 35 | D15: 亿元 | E15: 上行 | F15: 0.06 | G15: =IFERROR(VLOOKUP("钢铁|9-钢铁企业季度净利润",指标更新台账_v3!$A$2:$I$600,9,FALSE()),0) -> 6 | H15: >50亿=10分,20-50亿=8分,0-20亿=6分,-20-0亿=4分,<-20亿=2分 | I15: 45% | J15: Q1扭亏为盈，利润端改善 | K15: 季度 | L15: 0.1 | M15: 目标组权重 15%；按同组相对重要性归一化。 | N15: 采用TTM/滚动4季同比+历史分位；剔除一次性损益，IRR按项目现金流复核。
A16: 10-钢铁行业产能利用率 | B16: 国家统计局 | C16: 77 | D16: % | E16: 上行 | F16: 0.048 | G16: =IFERROR(VLOOKUP("钢铁|10-钢铁行业产能利用率",指标更新台账_v3!$A$2:$I$600,9,FALSE()),0) -> 6 | H16: >80%=10分,75-80%=8分,70-75%=6分,65-70%=4分,<65%=2分 | I16: 52% | J16: 产能利用率回升，供需趋于平衡 | K16: 季度 | L16: 0.08 | M16: 目标组权重 15%；按同组相对重要性归一化。 | N16: 采用TTM/滚动4季同比+历史分位；剔除一次性损益，IRR按项目现金流复核。
A17: 11-PPI黑色金属冶炼同比 | B17: 国家统计局 | C17: +1.8 | D17: % | E17: 上行 | F17: 0.042 | G17: =IFERROR(VLOOKUP("钢铁|11-PPI黑色金属冶炼同比",指标更新台账_v3!$A$2:$I$600,9,FALSE()),0) -> 6 | H17: >5%=10分,0-5%=8分,-5-0%=6分,-10--5%=4分,<-10%=2分 | I17: 48% | J17: 价格同比转正，通缩压力缓解 | K17: 月度 | L17: 0.07 | M17: 目标组权重 15%；按同组相对重要性归一化。 | N17: 采用5年滚动分位+同比/环比双阈值；数据滞后超过一个频率周期时自动降权。
A18: 行业综合景气度加权得分 | G18: =ROUND(SUMPRODUCT(F5:F17,G5:G17),1) -> 7 | H18: 综合分=Σ(建议权重×单项评分)，建议权重和=100%。

Sheet 有色金属
A1: 行业景气度量化跟踪体系（参数优化版）— 有色金属
A2: 默认阶段框架：资源品/宏观供需｜先行/同步/滞后=45%/40%/15%。库存、加工费、美元和价格共同确认。｜核心验证：库存、供给约束与需求弹性；必选：库存、TC/RC、美元、矿端扰动
A3: 指标名称 | B3: 数据来源 | C3: 最新数值 | D3: 单位 | E3: 趋势 | F3: 权重 | G3: 评分 (1-10) | H3: 评分阈值说明 | I3: 历史分位 | J3: 对景气度影响 | K3: 跟踪频率 | L3: 原权重 | M3: 参数优化建议 | N3: 评分口径（更新时采用） | O3: 阶段分项 | P3: 公式分数
A4: 【第一部分：先行指标（Leading Indicators）——提前1-2个季度预示景气变化】 | O4: 先行 | P4: =ROUND(SUMPRODUCT(F5:F8,G5:G8)/SUM(F5:F8),1) -> 6.9
A5: 1-LME铜库存变化 | B5: LME | C5: -12 | D5: %YoY | E5: 去库 | F5: 0.15 | G5: =IFERROR(VLOOKUP("有色金属|1-LME铜库存变化",指标更新台账_v3!$A$2:$I$600,9,FALSE()),0) -> 8 | H5: <-10%=10分,-10-0%=8分,0-10%=6分,10-20%=4分,>20%=2分 | I5: 35% | J5: 全球库存去化，供给偏紧 | K5: 周度 | L5: 0.15 | M5: 目标组权重 45%；按同组相对重要性归一化。 | N5: 采用同比、环比、历史分位三维评分；按去库/改善方向计分。 | O5: 同步 | P5: =ROUND(SUMPRODUCT(F10:F13,G10:G13)/SUM(F10:F13),1) -> 8.7
A6: 2-铜精矿TC/RC | B6: SMM | C6: 25 | D6: 美元/吨 | E6: 下行 | F6: 0.12 | G6: =IFERROR(VLOOKUP("有色金属|2-铜精矿TC/RC",指标更新台账_v3!$A$2:$I$600,9,FALSE()),0) -> 4 | H6: >80=10分,60-80=8分,40-60=6分,20-40=4分,<20=2分 | I6: 15% | J6: 加工费极低，铜矿供给紧张 | K6: 月度 | L6: 0.12 | M6: 目标组权重 45%；按同组相对重要性归一化。 | N6: 改为5年滚动分位(P20/P40/P60/P80)+3个月动量；须与库存、价差或利润交叉确认。 | O6: 滞后 | P6: =ROUND(SUMPRODUCT(F15:F17,G15:G17)/SUM(F15:F17),1) -> 8.6
A7: 3-美元指数 | B7: 美联储 | C7: 99.5 | D7: 点 | E7: 下行 | F7: 0.1 | G7: =IFERROR(VLOOKUP("有色金属|3-美元指数",指标更新台账_v3!$A$2:$I$600,9,FALSE()),0) -> 8 | H7: <100=10分,100-103=8分,103-106=6分,106-110=4分,>110=2分 | I7: 35% | J7: 美元走弱，利好大宗商品定价 | K7: 日度 | L7: 0.1 | M7: 目标组权重 45%；按同组相对重要性归一化。 | N7: 采用5年滚动分位+同比/环比双阈值；数据滞后超过一个频率周期时自动降权。
A8: 4-全球矿山资本开支增速 | B8: Wood Mackenzie | C8: +18 | D8: %YoY | E8: 上行 | F8: 0.08 | G8: =IFERROR(VLOOKUP("有色金属|4-全球矿山资本开支增速",指标更新台账_v3!$A$2:$I$600,9,FALSE()),0) -> 8 | H8: >15%=10分,5-15%=8分,0-5%=6分,-5-0%=4分,<-5%=2分 | I8: 65% | J8: 资本开支增加，远期供给有望改善 | K8: 年度 | L8: 0.08 | M8: 目标组权重 45%；按同组相对重要性归一化。 | N8: 采用5年滚动分位+同比/环比双阈值；数据滞后超过一个频率周期时自动降权。
A9: 【第二部分：同步指标（Coincident Indicators）——与当前景气同步变动】
A10: 5-LME铜现货价格 | B10: LME | C10: 9800 | D10: 美元/吨 | E10: 上行 | F10: 0.1395 | G10: =IFERROR(VLOOKUP("有色金属|5-LME铜现货价格",指标更新台账_v3!$A$2:$I$600,9,FALSE()),0) -> 10 | H10: >9500=10分,8500-9500=8分,7500-8500=6分,6500-7500=4分,<6500=2分 | I10: 85% | J10: 铜价处于历史高位，新能源+AI需求强劲 | K10: 日度 | L10: 0.15 | M10: 目标组权重 40%；按同组相对重要性归一化。 | N10: 改为5年滚动分位(P20/P40/P60/P80)+3个月动量；须与库存、价差或利润交叉确认。
A11: 6-铝现货价格 | B11: SMM | C11: 20500 | D11: 元/吨 | E11: 上行 | F11: 0.093 | G11: =IFERROR(VLOOKUP("有色金属|6-铝现货价格",指标更新台账_v3!$A$2:$I$600,9,FALSE()),0) -> 10 | H11: >20000=10分,18000-20000=8分,16000-18000=6分,14000-16000=4分,<14000=2分 | I11: 78% | J11: 铝价高位运行，氧化铝成本支撑 | K11: 日度 | L11: 0.1 | M11: 目标组权重 40%；按同组相对重要性归一化。 | N11: 改为5年滚动分位(P20/P40/P60/P80)+3个月动量；须与库存、价差或利润交叉确认。
A12: 7-有色金属冶炼加工费 | B12: SMM | C12: +8 | D12: %vs均值 | E12: 上行 | F12: 0.093 | G12: =IFERROR(VLOOKUP("有色金属|7-有色金属冶炼加工费",指标更新台账_v3!$A$2:$I$600,9,FALSE()),0) -> 6 | H12: >均值20%=10分,0-20%=8分,-10-0%=6分,-20--10%=4分,<-20%=2分 | I12: 55% | J12: 加工费改善，冶炼端利润修复 | K12: 月度 | L12: 0.1 | M12: 目标组权重 40%；按同组相对重要性归一化。 | N12: 采用5年滚动分位+同比/环比双阈值；数据滞后超过一个频率周期时自动降权。
A13: 8-中国有色金属消费量 | B13: 中国有色金属工业协会 | C13: +7.5 | D13: %YoY | E13: 上行 | F13: 0.0744 | G13: =IFERROR(VLOOKUP("有色金属|8-中国有色金属消费量",指标更新台账_v3!$A$2:$I$600,9,FALSE()),0) -> 8 | H13: >8%=10分,5-8%=8分,2-5%=6分,0-2%=4分,<0%=2分 | I13: 62% | J13: 消费量稳健增长，新能源需求拉动 | K13: 月度 | L13: 0.08 | M13: 目标组权重 40%；按同组相对重要性归一化。 | N13: 采用季调同比+3个月环比；单月值用3个月移动均值过滤。
A14: 【第三部分：滞后指标（Lagging Indicators）——滞后1-2个季度反映景气变化】
A15: 9-有色企业季度净利润 | B15: 上市公司财报 | C15: 180 | D15: 亿元 | E15: 上行 | F15: 0.06 | G15: =IFERROR(VLOOKUP("有色金属|9-有色企业季度净利润",指标更新台账_v3!$A$2:$I$600,9,FALSE()),0) -> 8 | H15: >100亿=10分,50-100亿=8分,10-50亿=6分,0-10亿=4分,<0亿=2分 | I15: 72% | J15: Q1业绩爆发，小金属板块净利增93% | K15: 季度 | L15: 0.1 | M15: 目标组权重 15%；按同组相对重要性归一化。 | N15: 采用TTM/滚动4季同比+历史分位；剔除一次性损益，IRR按项目现金流复核。
A16: 10-有色金属库存周转天数 | B16: 上市公司财报 | C16: 38 | D16: 天 | E16: 下行 | F16: 0.048 | G16: =IFERROR(VLOOKUP("有色金属|10-有色金属库存周转天数",指标更新台账_v3!$A$2:$I$600,9,FALSE()),0) -> 8 | H16: <30天=10分,30-45天=8分,45-60天=6分,60-75天=4分,>75天=2分 | I16: 42% | J16: 库存周转加快，运营效率提升 | K16: 季度 | L16: 0.08 | M16: 目标组权重 15%；按同组相对重要性归一化。 | N16: 采用同比、环比、历史分位三维评分；按去库/改善方向计分。
A17: 11-PPI有色金属冶炼同比 | B17: 国家统计局 | C17: +12.5 | D17: % | E17: 上行 | F17: 0.042 | G17: =IFERROR(VLOOKUP("有色金属|11-PPI有色金属冶炼同比",指标更新台账_v3!$A$2:$I$600,9,FALSE()),0) -> 10 | H17: >10%=10分,5-10%=8分,0-5%=6分,-5-0%=4分,<-5%=2分 | I17: 75% | J17: 价格同比大涨，行业景气度高企 | K17: 月度 | L17: 0.07 | M17: 目标组权重 15%；按同组相对重要性归一化。 | N17: 采用5年滚动分位+同比/环比双阈值；数据滞后超过一个频率周期时自动降权。
A18: 行业综合景气度加权得分 | G18: =ROUND(SUMPRODUCT(F5:F17,G5:G17),1) -> 7.9 | H18: 综合分=Σ(建议权重×单项评分)，建议权重和=100%。

Sheet 电子
A1: 行业景气度量化跟踪体系（参数优化版）— 电子
A2: 默认阶段框架：科技制造/订单库存周期｜先行/同步/滞后=50%/35%/15%。订单、库存和利用率优先；不同子行业拆分后再汇总。｜核心验证：库存去化与需求/产能利用率；必选：订单、库存周转、存储价格、终端出货
A3: 指标名称 | B3: 数据来源 | C3: 最新数值 | D3: 单位 | E3: 趋势 | F3: 权重 | G3: 评分 (1-10) | H3: 评分阈值说明 | I3: 历史分位 | J3: 对景气度影响 | K3: 跟踪频率 | L3: 原权重 | M3: 参数优化建议 | N3: 评分口径（更新时采用） | O3: 阶段分项 | P3: 公式分数
A4: 【第一部分：先行指标（Leading Indicators）——提前1-2个季度预示景气变化】 | O4: 先行 | P4: =ROUND(SUMPRODUCT(F5:F9,G5:G9)/SUM(F5:F9),1) -> 8.2
A5: 1-全球半导体销售额增速 | B5: SIA/WSTS | C5: +18.5 | D5: %YoY | E5: 上行 | F5: 0.1364 | G5: =IFERROR(VLOOKUP("电子|1-全球半导体销售额增速",指标更新台账_v3!$A$2:$I$600,9,FALSE()),0) -> 8 | H5: >20%=10分,10-20%=8分,5-10%=6分,0-5%=4分,<0%=2分 | I5: 75% | J5: 半导体周期强劲复苏，AI需求驱动 | K5: 月度 | L5: 0.15 | M5: 目标组权重 50%；按同组相对重要性归一化。 | N5: 采用5年滚动分位+同比/环比双阈值；数据滞后超过一个频率周期时自动降权。 | O5: 同步 | P5: =ROUND(SUMPRODUCT(F11:F14,G11:G14)/SUM(F11:F14),1) -> 7.2
A6: 2-存储芯片价格变化 | B6: DRAMeXchange | C6: +22 | D6: %MoM | E6: 大涨 | F6: 0.1091 | G6: =IFERROR(VLOOKUP("电子|2-存储芯片价格变化",指标更新台账_v3!$A$2:$I$600,9,FALSE()),0) -> 9 | H6: 涨价>10%=10分,涨价5-10%=8分,持平=5分,跌价5-10%=3分,跌价>10%=1分 | I6: 82% | J6: 存储超级周期，HBM需求爆发 | K6: 周度 | L6: 0.12 | M6: 目标组权重 50%；按同组相对重要性归一化。 | N6: 改为5年滚动分位(P20/P40/P60/P80)+3个月动量；须与库存、价差或利润交叉确认。 | O6: 滞后 | P6: =ROUND(SUMPRODUCT(F16:F18,G16:G18)/SUM(F16:F18),1) -> 8
A7: 3-硅片出货量增速 | B7: SEMI | C7: +15.2 | D7: %YoY | E7: 上行 | F7: 0.0909 | G7: =IFERROR(VLOOKUP("电子|3-硅片出货量增速",指标更新台账_v3!$A$2:$I$600,9,FALSE()),0) -> 7 | H7: >30%=10分,20-30%=8分,10-20%=6分,0-10%=4分,<0%=2分 | I7: 68% | J7: 硅片需求回暖，晶圆厂扩产 | K7: 季度 | L7: 0.1 | M7: 目标组权重 50%；按同组相对重要性归一化。 | N7: 采用季调同比+3个月环比；单月值用3个月移动均值过滤。
A8: 4-设备商订单增速 | B8: 应用材料/ASML财报 | C8: +28 | D8: %YoY | E8: 上行 | F8: 0.0909 | G8: =IFERROR(VLOOKUP("电子|4-设备商订单增速",指标更新台账_v3!$A$2:$I$600,9,FALSE()),0) -> 8 | H8: >40%=10分,20-40%=8分,10-20%=6分,0-10%=4分,<0%=2分 | I8: 72% | J8: 设备订单高增，扩产周期确认 | K8: 季度 | L8: 0.1 | M8: 目标组权重 50%；按同组相对重要性归一化。 | N8: 滚动3M/4Q同比；以交付、收入或现金流确认，政策/规划单项权重≤8%。
A9: 5-下游客户库存周转天数 | B9: 下游公司财报 | C9: 58 | D9: 天 | E9: 去库完成 | F9: 0.0727 | G9: =IFERROR(VLOOKUP("电子|5-下游客户库存周转天数",指标更新台账_v3!$A$2:$I$600,9,FALSE()),0) -> 9 | H9: 去库完成<60天=10分,去库中60-80天=7分,高位80-100天=4分,补库初期100-120天=6分,补库后期>120天=3分 | I9: 35% | J9: 库存去化完成，补库周期即将启动 | K9: 季度 | L9: 0.08 | M9: 目标组权重 50%；按同组相对重要性归一化。 | N9: 采用同比、环比、历史分位三维评分；按去库/改善方向计分。
A10: 【第二部分：同步指标（Coincident Indicators）——与当前景气同步变动】
A11: 6-晶圆厂产能利用率 | B11: 台积电/中芯国际 | C11: 88 | D11: % | E11: 上行 | F11: 0.1105 | G11: =IFERROR(VLOOKUP("电子|6-晶圆厂产能利用率",指标更新台账_v3!$A$2:$I$600,9,FALSE()),0) -> 8 | H11: >90%=10分,80-90%=8分,70-80%=6分,60-70%=4分,<60%=2分 | I11: 72% | J11: 产能利用率高位，供需偏紧 | K11: 月度 | L11: 0.12 | M11: 目标组权重 35%；按同组相对重要性归一化。 | N11: 采用TTM/滚动4季同比+历史分位；剔除一次性损益，IRR按项目现金流复核。
A12: 7-智能手机出货量增速 | B12: IDC/Counterpoint | C12: +8.5 | D12: %YoY | E12: 上行 | F12: 0.0921 | G12: =IFERROR(VLOOKUP("电子|7-智能手机出货量增速",指标更新台账_v3!$A$2:$I$600,9,FALSE()),0) -> 8 | H12: >10%=10分,5-10%=8分,0-5%=6分,-5-0%=4分,<-5%=2分 | I12: 60% | J12: 手机出货回暖，AI手机换机潮 | K12: 季度 | L12: 0.1 | M12: 目标组权重 35%；按同组相对重要性归一化。 | N12: 采用季调同比+3个月环比；单月值用3个月移动均值过滤。
A13: 8-PC出货量增速 | B13: IDC/Gartner | C13: +3.2 | D13: %YoY | E13: 上行 | F13: 0.0737 | G13: =IFERROR(VLOOKUP("电子|8-PC出货量增速",指标更新台账_v3!$A$2:$I$600,9,FALSE()),0) -> 6 | H13: >5%=10分,0-5%=8分,-5-0%=6分,-10--5%=4分,<-10%=2分 | I13: 55% | J13: PC出货温和复苏，AI PC渗透 | K13: 季度 | L13: 0.08 | M13: 目标组权重 35%；按同组相对重要性归一化。 | N13: 采用季调同比+3个月环比；单月值用3个月移动均值过滤。
A14: 9-MLCC出货量 | B14: 村田/TDK | C14: 480 | D14: 亿颗/月 | E14: 上行 | F14: 0.0737 | G14: =IFERROR(VLOOKUP("电子|9-MLCC出货量",指标更新台账_v3!$A$2:$I$600,9,FALSE()),0) -> 6 | H14: >500=10分,450-500=8分,400-450=6分,350-400=4分,<350=2分 | I14: 58% | J14: 被动元件出货回升，消费电子复苏 | K14: 月度 | L14: 0.08 | M14: 目标组权重 35%；按同组相对重要性归一化。 | N14: 采用季调同比+3个月环比；单月值用3个月移动均值过滤。
A15: 【第三部分：滞后指标（Lagging Indicators）——滞后1-2个季度反映景气变化】
A16: 10-电子企业季度毛利率 | B16: 上市公司财报 | C16: 28 | D16: % | E16: 上行 | F16: 0.0625 | G16: =IFERROR(VLOOKUP("电子|10-电子企业季度毛利率",指标更新台账_v3!$A$2:$I$600,9,FALSE()),0) -> 8 | H16: >30%=10分,25-30%=8分,20-25%=6分,15-20%=4分,<15%=2分 | I16: 62% | J16: Q1毛利率改善，产品结构优化 | K16: 季度 | L16: 0.1 | M16: 目标组权重 15%；按同组相对重要性归一化。 | N16: 改为5年滚动分位(P20/P40/P60/P80)+3个月动量；须与库存、价差或利润交叉确认。
A17: 11-电子行业固定资产投资增速 | B17: 国家统计局 | C17: +12 | D17: %YoY | E17: 上行 | F17: 0.0437 | G17: =IFERROR(VLOOKUP("电子|11-电子行业固定资产投资增速",指标更新台账_v3!$A$2:$I$600,9,FALSE()),0) -> 8 | H17: >15%=10分,5-15%=8分,0-5%=6分,-5-0%=4分,<-5%=2分 | I17: 65% | J17: 投资高增，产能扩张积极 | K17: 季度 | L17: 0.07 | M17: 目标组权重 15%；按同组相对重要性归一化。 | N17: 采用5年滚动分位+同比/环比双阈值；数据滞后超过一个频率周期时自动降权。
A18: 12-电子元器件进口金额增速 | B18: 海关总署 | C18: +15 | D18: %YoY | E18: 上行 | F18: 0.0437 | G18: =IFERROR(VLOOKUP("电子|12-电子元器件进口金额增速",指标更新台账_v3!$A$2:$I$600,9,FALSE()),0) -> 8 | H18: >10%=10分,5-10%=8分,0-5%=6分,-5-0%=4分,<-5%=2分 | I18: 68% | J18: 进口高增，国内需求旺盛 | K18: 月度 | L18: 0.07 | M18: 目标组权重 15%；按同组相对重要性归一化。 | N18: 采用5年滚动分位+同比/环比双阈值；数据滞后超过一个频率周期时自动降权。
A19: 行业综合景气度加权得分 | G19: =ROUND(SUMPRODUCT(F5:F18,G5:G18),1) -> 7.8 | H19: 综合分=Σ(建议权重×单项评分)，建议权重和=100%。

Sheet 家用电器
A1: 行业景气度量化跟踪体系（参数优化版）— 家用电器
A2: 默认阶段框架：消费/需求恢复｜先行/同步/滞后=40%/40%/20%。高频需求、渠道库存和价格/利润交叉确认，使用季调数据。｜核心验证：更新需求、出口和产品结构；必选：地产竣工、海外订单、排产
A3: 指标名称 | B3: 数据来源 | C3: 最新数值 | D3: 单位 | E3: 趋势 | F3: 权重 | G3: 评分 (1-10) | H3: 评分阈值说明 | I3: 历史分位 | J3: 对景气度影响 | K3: 跟踪频率 | L3: 原权重 | M3: 参数优化建议 | N3: 评分口径（更新时采用） | O3: 阶段分项 | P3: 公式分数
A4: 【第一部分：先行指标（Leading Indicators）——提前1-2个季度预示景气变化】 | O4: 先行 | P4: =ROUND(SUMPRODUCT(F5:F8,G5:G8)/SUM(F5:F8),1) -> 5.3
A5: 1-房地产竣工面积增速 | B5: 国家统计局 | C5: -8.5 | D5: %YoY | E5: 下行 | F5: 0.1277 | G5: =IFERROR(VLOOKUP("家用电器|1-房地产竣工面积增速",指标更新台账_v3!$A$2:$I$600,9,FALSE()),0) -> 4 | H5: >10%=10分,5-10%=8分,0-5%=6分,-5-0%=4分,<-5%=2分 | I5: 25% | J5: 竣工下滑，后周期需求承压 | K5: 月度 | L5: 0.15 | M5: 目标组权重 40%；按同组相对重要性归一化。 | N5: 采用5年滚动分位+同比/环比双阈值；数据滞后超过一个频率周期时自动降权。 | O5: 同步 | P5: =ROUND(SUMPRODUCT(F10:F13,G10:G13)/SUM(F10:F13),1) -> 7.2
A6: 2-商品房销售面积增速 | B6: 国家统计局 | C6: -5.2 | D6: %YoY | E6: 下行 | F6: 0.1021 | G6: =IFERROR(VLOOKUP("家用电器|2-商品房销售面积增速",指标更新台账_v3!$A$2:$I$600,9,FALSE()),0) -> 4 | H6: >5%=10分,0-5%=8分,-5-0%=6分,-10--5%=4分,<-10%=2分 | I6: 30% | J6: 销售低迷，新增需求不足 | K6: 月度 | L6: 0.12 | M6: 目标组权重 40%；按同组相对重要性归一化。 | N6: 采用5年滚动分位+同比/环比双阈值；数据滞后超过一个频率周期时自动降权。 | O6: 滞后 | P6: =ROUND(SUMPRODUCT(F15:F17,G15:G17)/SUM(F15:F17),1) -> 7.4
A7: 3-铜/钢等原材料价格 | B7: LME/上海期货 | C7: -2.5 | D7: %YoY | E7: 下行 | F7: 0.0851 | G7: =IFERROR(VLOOKUP("家用电器|3-铜/钢等原材料价格",指标更新台账_v3!$A$2:$I$600,9,FALSE()),0) -> 8 | H7: <-5%=10分,-5-0%=8分,0-5%=6分,5-10%=4分,>10%=2分 | I7: 45% | J7: 原材料成本下降，利润端改善 | K7: 日度 | L7: 0.1 | M7: 目标组权重 40%；按同组相对重要性归一化。 | N7: 改为5年滚动分位(P20/P40/P60/P80)+3个月动量；须与库存、价差或利润交叉确认。
A8: 4-家电企业排产计划 | B8: 产业在线 | C8: +8 | D8: %YoY | E8: 上行 | F8: 0.0851 | G8: =IFERROR(VLOOKUP("家用电器|4-家电企业排产计划",指标更新台账_v3!$A$2:$I$600,9,FALSE()),0) -> 6 | H8: >15%=10分,5-15%=8分,0-5%=6分,-5-0%=4分,<-5%=2分 | I8: 55% | J8: 排产温和增长，出口订单支撑 | K8: 月度 | L8: 0.1 | M8: 目标组权重 40%；按同组相对重要性归一化。 | N8: 采用5年滚动分位+同比/环比双阈值；数据滞后超过一个频率周期时自动降权。
A9: 【第二部分：同步指标（Coincident Indicators）——与当前景气同步变动】
A10: 5-空调销量增速 | B10: 产业在线 | C10: +12 | D10: %YoY | E10: 上行 | F10: 0.1395 | G10: =IFERROR(VLOOKUP("家用电器|5-空调销量增速",指标更新台账_v3!$A$2:$I$600,9,FALSE()),0) -> 8 | H10: >15%=10分,5-15%=8分,0-5%=6分,-5-0%=4分,<-5%=2分 | I10: 62% | J10: 空调销售旺季，出口强劲 | K10: 月度 | L10: 0.15 | M10: 目标组权重 40%；按同组相对重要性归一化。 | N10: 采用季调同比+3个月环比；单月值用3个月移动均值过滤。
A11: 6-冰箱销量增速 | B11: 产业在线 | C11: +6.5 | D11: %YoY | E11: 上行 | F11: 0.093 | G11: =IFERROR(VLOOKUP("家用电器|6-冰箱销量增速",指标更新台账_v3!$A$2:$I$600,9,FALSE()),0) -> 6 | H11: >10%=10分,5-10%=8分,0-5%=6分,-5-0%=4分,<-5%=2分 | I11: 55% | J11: 冰箱销售平稳，更新需求为主 | K11: 月度 | L11: 0.1 | M11: 目标组权重 40%；按同组相对重要性归一化。 | N11: 采用季调同比+3个月环比；单月值用3个月移动均值过滤。
A12: 7-洗衣机销量增速 | B12: 产业在线 | C12: +4.2 | D12: %YoY | E12: 上行 | F12: 0.0744 | G12: =IFERROR(VLOOKUP("家用电器|7-洗衣机销量增速",指标更新台账_v3!$A$2:$I$600,9,FALSE()),0) -> 6 | H12: >10%=10分,5-10%=8分,0-5%=6分,-5-0%=4分,<-5%=2分 | I12: 52% | J12: 洗衣机销售温和增长 | K12: 月度 | L12: 0.08 | M12: 目标组权重 40%；按同组相对重要性归一化。 | N12: 采用季调同比+3个月环比；单月值用3个月移动均值过滤。
A13: 8-家电出口金额增速 | B13: 海关总署 | C13: +18.5 | D13: %YoY | E13: 上行 | F13: 0.093 | G13: =IFERROR(VLOOKUP("家用电器|8-家电出口金额增速",指标更新台账_v3!$A$2:$I$600,9,FALSE()),0) -> 8 | H13: >15%=10分,5-15%=8分,0-5%=6分,-5-0%=4分,<-5%=2分 | I13: 70% | J13: 出口高增，海外需求旺盛 | K13: 月度 | L13: 0.1 | M13: 目标组权重 40%；按同组相对重要性归一化。 | N13: 采用5年滚动分位+同比/环比双阈值；数据滞后超过一个频率周期时自动降权。
A14: 【第三部分：滞后指标（Lagging Indicators）——滞后1-2个季度反映景气变化】
A15: 9-家电企业季度净利润率 | B15: 上市公司财报 | C15: 8.5 | D15: % | E15: 上行 | F15: 0.08 | G15: =IFERROR(VLOOKUP("家用电器|9-家电企业季度净利润率",指标更新台账_v3!$A$2:$I$600,9,FALSE()),0) -> 8 | H15: >10%=10分,7-10%=8分,4-7%=6分,1-4%=4分,<1%=2分 | I15: 60% | J15: Q1净利率改善，成本红利释放 | K15: 季度 | L15: 0.1 | M15: 目标组权重 20%；按同组相对重要性归一化。 | N15: 采用TTM/滚动4季同比+历史分位；剔除一次性损益，IRR按项目现金流复核。
A16: 10-家电行业库存周转天数 | B16: 上市公司财报 | C16: 42 | D16: 天 | E16: 下行 | F16: 0.064 | G16: =IFERROR(VLOOKUP("家用电器|10-家电行业库存周转天数",指标更新台账_v3!$A$2:$I$600,9,FALSE()),0) -> 8 | H16: <40天=10分,40-50天=8分,50-60天=6分,60-70天=4分,>70天=2分 | I16: 45% | J16: 库存周转加快，运营效率提升 | K16: 季度 | L16: 0.08 | M16: 目标组权重 20%；按同组相对重要性归一化。 | N16: 采用同比、环比、历史分位三维评分；按去库/改善方向计分。
A17: 11-家电零售均价变化 | B17: 奥维云网 | C17: +2.5 | D17: %YoY | E17: 上行 | F17: 0.056 | G17: =IFERROR(VLOOKUP("家用电器|11-家电零售均价变化",指标更新台账_v3!$A$2:$I$600,9,FALSE()),0) -> 6 | H17: >5%=10分,0-5%=8分,-3-0%=6分,-6--3%=4分,<-6%=2分 | I17: 55% | J17: 均价温和上涨，产品结构升级 | K17: 月度 | L17: 0.07 | M17: 目标组权重 20%；按同组相对重要性归一化。 | N17: 改为5年滚动分位(P20/P40/P60/P80)+3个月动量；须与库存、价差或利润交叉确认。
A18: 行业综合景气度加权得分 | G18: =ROUND(SUMPRODUCT(F5:F17,G5:G17),1) -> 6.5 | H18: 综合分=Σ(建议权重×单项评分)，建议权重和=100%。

Sheet 食品饮料
A1: 行业景气度量化跟踪体系（参数优化版）— 食品饮料
A2: 默认阶段框架：防御/成熟｜先行/同步/滞后=30%/45%/25%。同步经营和现金流优先；先行指标只作边际变化确认。｜核心验证：动销、渠道与价格带；必选：经销商库存、终端动销、批价
A3: 指标名称 | B3: 数据来源 | C3: 最新数值 | D3: 单位 | E3: 趋势 | F3: 权重 | G3: 评分 (1-10) | H3: 评分阈值说明 | I3: 历史分位 | J3: 对景气度影响 | K3: 跟踪频率 | L3: 原权重 | M3: 参数优化建议 | N3: 评分口径（更新时采用） | O3: 阶段分项 | P3: 公式分数
A4: 【第一部分：先行指标（Leading Indicators）——提前1-2个季度预示景气变化】 | O4: 先行 | P4: =ROUND(SUMPRODUCT(F5:F8,G5:G8)/SUM(F5:F8),1) -> 5.9
A5: 1-粮食价格变化 | B5: 农业农村部 | C5: +2.8 | D5: %YoY | E5: 上行 | F5: 0.08 | G5: =IFERROR(VLOOKUP("食品饮料|1-粮食价格变化",指标更新台账_v3!$A$2:$I$600,9,FALSE()),0) -> 6 | H5: <3%=10分,3-5%=8分,5-8%=6分,8-10%=4分,>10%=2分 | I5: 55% | J5: 粮价温和上涨，成本端可控 | K5: 月度 | L5: 0.12 | M5: 目标组权重 30%；按同组相对重要性归一化。 | N5: 改为5年滚动分位(P20/P40/P60/P80)+3个月动量；须与库存、价差或利润交叉确认。 | O5: 同步 | P5: =ROUND(SUMPRODUCT(F10:F13,G10:G13)/SUM(F10:F13),1) -> 6.8
A6: 2-包材价格变化 | B6: 生意社 | C6: -4.5 | D6: %YoY | E6: 下行 | F6: 0.0667 | G6: =IFERROR(VLOOKUP("食品饮料|2-包材价格变化",指标更新台账_v3!$A$2:$I$600,9,FALSE()),0) -> 8 | H6: <-5%=10分,-5-0%=8分,0-5%=6分,5-10%=4分,>10%=2分 | I6: 38% | J6: 包材成本下降，利润端改善 | K6: 月度 | L6: 0.1 | M6: 目标组权重 30%；按同组相对重要性归一化。 | N6: 改为5年滚动分位(P20/P40/P60/P80)+3个月动量；须与库存、价差或利润交叉确认。 | O6: 滞后 | P6: =ROUND(SUMPRODUCT(F15:F17,G15:G17)/SUM(F15:F17),1) -> 7.4
A7: 3-消费者信心指数 | B7: 国家统计局 | C7: 88 | D7: 点 | E7: 下行 | F7: 0.0867 | G7: =IFERROR(VLOOKUP("食品饮料|3-消费者信心指数",指标更新台账_v3!$A$2:$I$600,9,FALSE()),0) -> 4 | H7: >120=10分,110-120=8分,100-110=6分,90-100=4分,<90=2分 | I7: 25% | J7: 信心指数低迷，消费意愿偏弱 | K7: 月度 | L7: 0.13 | M7: 目标组权重 30%；按同组相对重要性归一化。 | N7: 采用5年滚动分位+同比/环比双阈值；数据滞后超过一个频率周期时自动降权。
A8: 4-社会消费品零售总额增速 | B8: 国家统计局 | C8: +5.2 | D8: %YoY | E8: 上行 | F8: 0.0667 | G8: =IFERROR(VLOOKUP("食品饮料|4-社会消费品零售总额增速",指标更新台账_v3!$A$2:$I$600,9,FALSE()),0) -> 6 | H8: >8%=10分,5-8%=8分,3-5%=6分,0-3%=4分,<0%=2分 | I8: 48% | J8: 社零温和增长，消费复苏缓慢 | K8: 月度 | L8: 0.1 | M8: 目标组权重 30%；按同组相对重要性归一化。 | N8: 采用季调同比+3个月环比；单月值用3个月移动均值过滤。
A9: 【第二部分：同步指标（Coincident Indicators）——与当前景气同步变动】
A10: 5-白酒批价 | B10: 今日酒价 | C10: 2650 | D10: 元/瓶 | E10: 下行 | F10: 0.1776 | G10: =IFERROR(VLOOKUP("食品饮料|5-白酒批价",指标更新台账_v3!$A$2:$I$600,9,FALSE()),0) -> 8 | H10: >2800=10分,2500-2800=8分,2200-2500=6分,2000-2200=4分,<2000=2分 | I10: 65% | J10: 茅台批价坚挺，高端酒需求稳定 | K10: 周度 | L10: 0.15 | M10: 目标组权重 45%；按同组相对重要性归一化。 | N10: 改为5年滚动分位(P20/P40/P60/P80)+3个月动量；须与库存、价差或利润交叉确认。
A11: 6-乳制品产量增速 | B11: 国家统计局 | C11: +3.5 | D11: %YoY | E11: 上行 | F11: 0.0947 | G11: =IFERROR(VLOOKUP("食品饮料|6-乳制品产量增速",指标更新台账_v3!$A$2:$I$600,9,FALSE()),0) -> 6 | H11: >5%=10分,2-5%=8分,0-2%=6分,-3-0%=4分,<-3%=2分 | I11: 52% | J11: 乳制品产量温和增长 | K11: 月度 | L11: 0.08 | M11: 目标组权重 45%；按同组相对重要性归一化。 | N11: 采用季调同比+3个月环比；单月值用3个月移动均值过滤。
A12: 7-啤酒产量增速 | B12: 国家统计局 | C12: +1.8 | D12: %YoY | E12: 上行 | F12: 0.0947 | G12: =IFERROR(VLOOKUP("食品饮料|7-啤酒产量增速",指标更新台账_v3!$A$2:$I$600,9,FALSE()),0) -> 6 | H12: >5%=10分,2-5%=8分,0-2%=6分,-3-0%=4分,<-3%=2分 | I12: 48% | J12: 啤酒产量平稳，旺季来临 | K12: 月度 | L12: 0.08 | M12: 目标组权重 45%；按同组相对重要性归一化。 | N12: 采用季调同比+3个月环比；单月值用3个月移动均值过滤。
