Workbook

Sheet 参数优化说明
A1: 全行业景气度量化跟踪体系｜参数优化说明
A2: 数据口径：保留原工作簿“截至2026年5月”的数值。本版优化权重、公式和阈值口径；不把旧数值视为实时投资数据。
A4: 审计结论 | B4: 原表无公式；43个行业页权重和均大于1；细分行业原加权分可超过10；总览与行业页未链接。
A5: 本版修复 | B5: 各行业归一化为先行/同步/滞后合计100%；行业综合分、分项分数和总览均改为公式联动。
A6: 阶段模板 | B6: 复苏55/30/15；扩张45/40/15；过热35/45/20；下行50/30/20；防御30/45/25（顺序为先行/同步/滞后）。
A7: 阈值原则 | B7: 价格、库存、量、利润、政策分别采用分位、变化率、季调、TTM、确认项上限；估值与交易信号单列。
A8: 使用纪律 | B8: 景气度只用于基本面筛选与排序，不能直接生成交易仓位；每次更新数据后须在Excel中重算。

Sheet 行业核心标准库
A1: 行业 | B1: 核心增长内核 | C1: 必选先行标准（未满足不得上调） | D1: 同步确认标准 | E1: 质量/盈利验证 | F1: 不作为主评分的指标 | G1: 新标理由
A2: 农林牧渔 | B2: 供给周期与养殖价差 | C2: 母猪存栏/淘汰率、仔猪价、饲料成本 | D2: 出栏量、猪鸡价、库存 | E2: 养殖现金成本、单头利润、经营现金流 | F2: 单纯CPI、年度种植面积 | G2: 供给约束决定价格，利润需在出栏兑现后确认。
A3: 基础化工 | B3: 库存周期与价差修复 | C3: 下游订单、库存、计划新增产能 | D3: 开工率、产品价差、出口 | E3: 现金成本、ROE、自由现金流 | F3: 原油绝对价格 | G3: 化工盈利取决于供需和价差，不是单一原料价格。
A4: 钢铁 | B4: 需求/去库与利润修复 | C4: 地产施工、基建实物量、库存变化 | D4: 表观消费、开工率、钢价/原料价差 | E4: 吨钢利润、现金流、应收 | F4: 钢价绝对水平 | G4: 钢价上升若库存不去化或利润不扩张，不能确认景气。
A5: 有色金属 | B5: 库存、供给约束与需求弹性 | C5: 库存、TC/RC、美元、矿端扰动 | D5: 金属价、加工费、消费量 | E5: 单位成本、资本开支、现金流 | F5: 金属绝对价格 | G5: 资源品价格需用供需紧张与加工利润验证。
A6: 电子 | B6: 库存去化与需求/产能利用率 | C6: 订单、库存周转、存储价格、终端出货 | D6: 稼动率、出货、ASP | E6: 毛利率、资本开支回报、现金流 | F6: 行业总销售单指标 | G6: AI、存储、消费电子周期不同，需拆分确认。
A7: 家用电器 | B7: 更新需求、出口和产品结构 | C7: 地产竣工、海外订单、排产 | D7: 零售/出货、出口、ASP | E7: 毛利率、渠道库存、现金流 | F7: 商品房销售 | G7: 竣工对家电更直接，销售只作前瞻背景。
A8: 食品饮料 | B8: 动销、渠道与价格带 | C8: 经销商库存、终端动销、批价 | D8: 销量、同店、收入 | E8: 毛利率、费用率、经营现金流 | F8: CPI单项 | G8: 品牌消费的核心是量价与渠道健康，不是宏观通胀。
A9: 纺织服饰 | B9: 海外库存、订单与汇率 | C9: 海外零售库存、订单、汇率 | D9: 出口、开工、零售 | E9: 库存周转、毛利率、现金流 | F9: 棉价单项 | G9: 成本变化只有传导到订单和毛利才有意义。
A10: 轻工制造 | B10: 地产后周期/出口与价差 | C10: 竣工、海外地产、原料与产品价差 | D10: 出货、开工、出口 | E10: 库存、ROE、现金流 | F10: 纸浆绝对价格 | G10: 需求与产品价差共同决定轻工盈利。
A11: 医药生物 | B11: 创新、诊疗与政策支付 | C11: IND/注册、医保政策、研发融资 | D11: 诊疗量、收入、器械出口 | E11: 毛利率、研发效率、经营现金流 | F11: 单一原料药价格 | G11: 子行业差异大，政策和商业化必须分层。
A12: 公用事业 | B12: 利用小时、燃料传导与资本回报 | C12: 来水、燃料、电价机制、装机进度 | D12: 发电量、利用小时 | E12: ROE、负债率、经营现金流 | F12: 装机规划 | G12: 规划不产生收益，利用率和现金流才决定回报。
... A44: 创新药 | B44: 研发兑现、商业化与支付 | C44: BD、临床、获批、医保/准入 | D44: 销售、处方、出海 | E44: 现金流、销售效率、研发回报 | F44: 获批数量单项 | G44: 获批不等于商业化，需用准入、处方和现金流确认。

Sheet 打分机制标准
A1: 行业景气度新打分机制（统一底层方法，行业核心标准库决定指标选择）
A3: 环节 | B3: 新标准 | C3: 理由
A4: 1. 指标可用性 | B4: 数据发布日期不滞后于其频率周期；异常值、口径变化、单月季节性先处理 | C4: 避免旧数据或异常点直接影响行业排序。
A5: 2. 单项标准化 | B5: 方向调整后使用5年滚动历史分位：P20/P40/P60/P80对应2/4/6/8分；价格和利润率另加3个月动量确认 | C5: 消除不同行业量纲差异，避免绝对阈值随通胀、技术降本而失效。
A6: 3. 因果层级 | B6: 先行仅回答“是否会变”；同步回答“是否已发生”；滞后仅验证“盈利/现金流是否兑现” | C6: 防止政策、规划、价格等相关但非因果指标主导分数。
A7: 4. 上调门槛 | B7: 行业分数上调一档，须至少2项必选先行标准+1项同步确认同向；仅先行改善时，综合分最高上调至6.5 | C7: 降低假复苏和主题驱动的误判。
A8: 5. 过热/风险扣分 | B8: 价格或估值急升但库存、需求、利润未确认时，价格指标封顶8分；现金流/应收恶化时，行业综合分扣0.5–1.5分 | C8: 价格上涨不必然转化为盈利，回款恶化会先破坏基本面。
A9: 6. 权重限制 | B9: 单项权重≤15%；政策/规划/热度单项≤8%；任一高度相关指标组（如多种价格）合计≤25% | C9: 降低重复计分和政策/情绪放大。
A10: 7. 阶段权重 | B10: 复苏55/30/15；扩张45/40/15；过热35/45/20；下行50/30/20；防御30/45/25（先行/同步/滞后） | C10: 不同阶段的信息含量不同，固定权重会滞后或误判。
A11: 8. 输出边界 | B11: 景气度只输出：行业排序、阶段、证据缺口和风险；估值、资金面、交易时点单独建模 | C11: 避免把基本面景气直接等同为买卖信号。

Sheet 全行业景气度总览
A1: 全行业景气度量化跟踪总览表（参数优化版）
A2: 本页公式连接各行业归一化评分；需按各页N列口径更新数据并打开Excel重算后，再用于横向排序。
A3: 行业名称 | B3: 先行指标 得分 | C3: 同步指标 得分 | D3: 滞后指标 得分 | E3: 综合景气度 评分 | F3: 景气度 判断 | G3: 阶段框架 | H3: 建议使用方式 | I3: 行业分类 | J3: 核心跟踪要点
A4: 农林牧渔 | B4: =农林牧渔!$P$4 -> 7.2 | C4: =农林牧渔!$P$5 -> 6.5 | D4: =农林牧渔!$P$6 -> 6.6 | E4: =农林牧渔!$G$19 -> 6.8 | F4: =IF(E4>=8.5,"强/防过热",IF(E4>=7.5,"偏强",IF(E4>=6.5,"中性偏强",IF(E4>=5,"中性",IF(E4>=3,"偏弱","低迷"))))) -> 中性偏强 | G4: 强周期/供给出清 | H4: 基本面筛选与排序；非交易仓位指令 | I4: 一级行业 | J4: 先用库存、供给、订单确认反转；价格本身不能直接等同高景气。
A5: 基础化工 | B5: =基础化工!$P$4 -> 8 | C5: =基础化工!$P$5 -> 6.8 | D5: =基础化工!$P$6 -> 6.6 | E5: =基础化工!$G$18 -> 7.4 | F5: =IF(E5>=8.5,"强/防过热",IF(E5>=7.5,"偏强",IF(E5>=6.5,"中性偏强",IF(E5>=5,"中性",IF(E5>=3,"偏弱","低迷"))))) -> 中性偏强 | G5: 强周期/供给出清 | H5: 基本面筛选与排序；非交易仓位指令 | I5: 一级行业 | J5: 先用库存、供给、订单确认反转；价格本身不能直接等同高景气。
A6: 钢铁 | B6: =钢铁!$P$4 -> 8 | C6: =钢铁!$P$5 -> 6 | D6: =钢铁!$P$6 -> 6 | E6: =钢铁!$G$18 -> 7 | F6: =IF(E6>=8.5,"强/防过热",IF(E6>=7.5,"偏强",IF(E6>=6.5,"中性偏强",IF(E6>=5,"中性",IF(E6>=3,"偏弱","低迷"))))) -> 中性偏强 | G6: 强周期/供给出清 | H6: 基本面筛选与排序；非交易仓位指令 | I6: 一级行业 | J6: 先用库存、供给、订单确认反转；价格本身不能直接等同高景气。
A7: 有色金属 | B7: =有色金属!$P$4 -> 6.9 | C7: =有色金属!$P$5 -> 8.7 | D7: =有色金属!$P$6 -> 8.6 | E7: =有色金属!$G$18 -> 7.9 | F7: =IF(E7>=8.5,"强/防过热",IF(E7>=7.5,"偏强",IF(E7>=6.5,"中性偏强",IF(E7>=5,"中性",IF(E7>=3,"偏弱","低迷"))))) -> 偏强 | G7: 资源品/宏观供需 | H7: 基本面筛选与排序；非交易仓位指令 | I7: 一级行业 | J7: 库存、加工费、美元和价格共同确认。
A8: 电子 | B8: =电子!$P$4 -> 8.2 | C8: =电子!$P$5 -> 7.2 | D8: =电子!$P$6 -> 8 | E8: =电子!$G$19 -> 7.8 | F8: =IF(E8>=8.5,"强/防过热",IF(E8>=7.5,"偏强",IF(E8>=6.5,"中性偏强",IF(E8>=5,"中性",IF(E8>=3,"偏弱","低迷"))))) -> 偏强 | G8: 科技制造/订单库存周期 | H8: 基本面筛选与排序；非交易仓位指令 | I8: 一级行业 | J8: 订单、库存和利用率优先；不同子行业拆分后再汇总。
A9: 家用电器 | B9: =家用电器!$P$4 -> 5.3 | C9: =家用电器!$P$5 -> 7.2 | D9: =家用电器!$P$6 -> 7.4 | E9: =家用电器!$G$18 -> 6.5 | F9: =IF(E9>=8.5,"强/防过热",IF(E9>=7.5,"偏强",IF(E9>=6.5,"中性偏强",IF(E9>=5,"中性",IF(E9>=3,"偏弱","低迷"))))) -> 中性偏强 | G9: 消费/需求恢复 | H9: 基本面筛选与排序；非交易仓位指令 | I9: 一级行业 | J9: 高频需求、渠道库存和价格/利润交叉确认，使用季调数据。
A10: 食品饮料 | B10: =食品饮料!$P$4 -> 5.9 | C10: =食品饮料!$P$5 -> 6.8 | D10: =食品饮料!$P$6 -> 7.4 | E10: =食品饮料!$G$18 -> 6.7 | F10: =IF(E10>=8.5,"强/防过热",IF(E10>=7.5,"偏强",IF(E10>=6.5,"中性偏强",IF(E10>=5,"中性",IF(E10>=3,"偏弱","低迷"))))) -> 中性偏强 | G10: 防御/成熟 | H10: 基本面筛选与排序；非交易仓位指令 | I10: 一级行业 | J10: 同步经营和现金流优先；先行指标只作边际变化确认。
A11: 纺织服饰 | B11: =纺织服饰!$P$4 -> 7.6 | C11: =纺织服饰!$P$5 -> 6.7 | D11: =纺织服饰!$P$6 -> 6 | E11: =纺织服饰!$G$18 -> 6.9 | F11: =IF(E11>=8.5,"强/防过热",IF(E11>=7.5,"偏强",IF(E11>=6.5,"中性偏强",IF(E11>=5,"中性",IF(E11>=3,"偏弱","低迷"))))) -> 中性偏强 | G11: 消费/需求恢复 | H11: 基本面筛选与排序；非交易仓位指令 | I11: 一级行业 | J11: 高频需求、渠道库存和价格/利润交叉确认，使用季调数据。
A12: 轻工制造 | B12: =轻工制造!$P$4 -> 6.6 | C12: =轻工制造!$P$5 -> 5 | D12: =轻工制造!$P$6 -> 6 | E12: =轻工制造!$G$18 -> 5.8 | F12: =IF(E12>=8.5,"强/防过热",IF(E12>=7.5,"偏强",IF(E12>=6.5,"中性偏强",IF(E12>=5,"中性",IF(E12>=3,"偏弱","低迷"))))) -> 中性 | G12: 消费/需求恢复 | H12: 基本面筛选与排序；非交易仓位指令 | I12: 一级行业 | J12: 高频需求、渠道库存和价格/利润交叉确认，使用季调数据。
A13: 医药生物 | B13: =医药生物!$P$4 -> 8 | C13: =医药生物!$P$5 -> 7.2 | D13: =医药生物!$P$6 -> 8 | E13: =医药生物!$G$18 -> 7.7 | F13: =IF(E13>=8.5,"强/防过热",IF(E13>=7.5,"偏强",IF(E13>=6.5,"中性偏强",IF(E13>=5,"中性",IF(E13>=3,"偏弱","低迷"))))) -> 偏强 | G13: 科技制造/订单库存周期 | H13: 基本面筛选与排序；非交易仓位指令 | I13: 一级行业 | J13: 订单、库存和利用率优先；不同子行业拆分后再汇总。
A14: 公用事业 | B14: =公用事业!$P$4 -> 9 | C14: =公用事业!$P$5 -> 7.1 | D14: =公用事业!$P$6 -> 8 | E14: =公用事业!$G$18 -> 7.9 | F14: =IF(E14>=8.5,"强/防过热",IF(E14>=7.5,"偏强",IF(E14>=6.5,"中性偏强",IF(E14>=5,"中性",IF(E14>=3,"偏弱","低迷"))))) -> 偏强 | G14: 防御/成熟 | H14: 基本面筛选与排序；非交易仓位指令 | I14: 一级行业 | J14: 同步经营和现金流优先；先行指标只作边际变化确认。
A15: 交通运输 | B15: =交通运输!$P$4 -> 8 | C15: =交通运输!$P$5 -> 8 | D15: =交通运输!$P$6 -> 8 | E15: =交通运输!$G$18 -> 8 | F15: =IF(E15>=8.5,"强/防过热",IF(E15>=7.5,"偏强",IF(E15>=6.5,"中性偏强",IF(E15>=5,"中性",IF(E15>=3,"偏弱","低迷"))))) -> 偏强 | G15: 消费/需求恢复 | H15: 基本面筛选与排序；非交易仓位指令 | I15: 一级行业 | J15: 高频需求、渠道库存和价格/利润交叉确认，使用季调数据。
A16: 房地产 | B16: =房地产!$P$4 -> 4.9 | C16: =房地产!$P$5 -> 4 | D16: =房地产!$P$6 -> 3.4 | E16: =房地产!$G$18 -> 4.3 | F16: =IF(E16>=8.5,"强/防过热",IF(E16>=7.5,"偏强",IF(E16>=6.5,"中性偏强",IF(E16>=5,"中性",IF(E16>=3,"偏弱","低迷"))))) -> 偏弱 | G16: 强周期/供给出清 | H16: 基本面筛选与排序；非交易仓位指令 | I16: 一级行业 | J16: 先用库存、供给、订单确认反转；价格本身不能直接等同高景气。
A17: 商贸零售 | B17: =商贸零售!$P$4 -> 5.5 | C17: =商贸零售!$P$5 -> 7.4 | D17: =商贸零售!$P$6 -> 6.6 | E17: =商贸零售!$G$18 -> 6.5 | F17: =IF(E17>=8.5,"强/防过热",IF(E17>=7.5,"偏强",IF(E17>=6.5,"中性偏强",IF(E17>=5,"中性",IF(E17>=3,"偏弱","低迷"))))) -> 中性偏强 | G17: 消费/需求恢复 | H17: 基本面筛选与排序；非交易仓位指令 | I17: 一级行业 | J17: 高频需求、渠道库存和价格/利润交叉确认，使用季调数据。
A18: 社会服务 | B18: =社会服务!$P$4 -> 7.2 | C18: =社会服务!$P$5 -> 7.6 | D18: =社会服务!$P$6 -> 5.4 | E18: =社会服务!$G$18 -> 7 | F18: =IF(E18>=8.5,"强/防过热",IF(E18>=7.5,"偏强",IF(E18>=6.5,"中性偏强",IF(E18>=5,"中性",IF(E18>=3,"偏弱","低迷"))))) -> 中性偏强 | G18: 消费/需求恢复 | H18: 基本面筛选与排序；非交易仓位指令 | I18: 一级行业 | J18: 高频需求、渠道库存和价格/利润交叉确认，使用季调数据。
A19: 综合 | B19: =综合!$P$4 -> 6.4 | C19: =综合!$P$5 -> 6.7 | D19: =综合!$P$6 -> 7.2 | E19: =综合!$G$15 -> 6.6 | F19: =IF(E19>=8.5,"强/防过热",IF(E19>=7.5,"偏强",IF(E19>=6.5,"中性偏强",IF(E19>=5,"中性",IF(E19>=3,"偏弱","低迷"))))) -> 中性偏强 | G19: 扩张/订单周期 | H19: 基本面筛选与排序；非交易仓位指令 | I19: 一级行业 | J19: 订单、需求和利润三段式确认，避免单一宏观指标主导。
A20: 建筑材料 | B20: =建筑材料!$P$4 -> 4.8 | C20: =建筑材料!$P$5 -> 4.9 | D20: =建筑材料!$P$6 -> 4 | E20: =建筑材料!$G$18 -> 4.7 | F20: =IF(E20>=8.5,"强/防过热",IF(E20>=7.5,"偏强",IF(E20>=6.5,"中性偏强",IF(E20>=5,"中性",IF(E20>=3,"偏弱","低迷"))))) -> 偏弱 | G20: 强周期/供给出清 | H20: 基本面筛选与排序；非交易仓位指令 | I20: 一级行业 | J20: 先用库存、供给、订单确认反转；价格本身不能直接等同高景气。
A21: 建筑装饰 | B21: =建筑装饰!$P$4 -> 7.1 | C21: =建筑装饰!$P$5 -> 5.3 | D21: =建筑装饰!$P$6 -> 6 | E21: =建筑装饰!$G$18 -> 6.3 | F21: =IF(E21>=8.5,"强/防过热",IF(E21>=7.5,"偏强",IF(E21>=6.5,"中性偏强",IF(E21>=5,"中性",IF(E21>=3,"偏弱","低迷"))))) -> 中性 | G21: 政策资本开支/交付 | H21: 基本面筛选与排序；非交易仓位指令 | I21: 一级行业 | J21: 政策与规划只作确认项，必须由招标、交付、回款和利润验证。
A22: 电力设备 | B22: =电力设备!$P$4 -> 8.8 | C22: =电力设备!$P$5 -> 6.4 | D22: =电力设备!$P$6 -> 5.9 | E22: =电力设备!$G$19 -> 7.4 | F22: =IF(E22>=8.5,"强/防过热",IF(E22>=7.5,"偏强",IF(E22>=6.5,"中性偏强",IF(E22>=5,"中性",IF(E22>=3,"偏弱","低迷"))))) -> 中性偏强 | G22: 政策资本开支/交付 | H22: 基本面筛选与排序；非交易仓位指令 | I22: 一级行业 | J22: 政策与规划只作确认项，必须由招标、交付、回款和利润验证。
A23: 国防军工 | B23: =国防军工!$P$4 -> 7.2 | C23: =国防军工!$P$5 -> 7.7 | D23: =国防军工!$P$6 -> 7.2 | E23: =国防军工!$G$18 -> 7.4 | F23: =IF(E23>=8.5,"强/防过热",IF(E23>=7.5,"偏强",IF(E23>=6.5,"中性偏强",IF(E23>=5,"中性",IF(E23>=3,"偏弱","低迷"))))) -> 中性偏强 | G23: 政策资本开支/交付 | H23: 基本面筛选与排序；非交易仓位指令 | I23: 一级行业 | J23: 政策与规划只作确认项，必须由招标、交付、回款和利润验证。
A24: 计算机 | B24: =计算机!$P$4 -> 8.5 | C24: =计算机!$P$5 -> 7.6 | D24: =计算机!$P$6 -> 6.6 | E24: =计算机!$G$18 -> 7.9 | F24: =IF(E24>=8.5,"强/防过热",IF(E24>=7.5,"偏强",IF(E24>=6.5,"中性偏强",IF(E24>=5,"中性",IF(E24>=3,"偏弱","低迷"))))) -> 偏强 | G24: 科技制造/订单库存周期 | H24: 基本面筛选与排序；非交易仓位指令 | I24: 一级行业 | J24: 订单、库存和利用率优先；不同子行业拆分后再汇总。
A25: 传媒 | B25: =传媒!$P$4 -> 7.2 | C25: =传媒!$P$5 -> 7 | D25: =传媒!$P$6 -> 6.6 | E25: =传媒!$G$18 -> 7 | F25: =IF(E25>=8.5,"强/防过热",IF(E25>=7.5,"偏强",IF(E25>=6.5,"中性偏强",IF(E25>=5,"中性",IF(E25>=3,"偏弱","低迷"))))) -> 中性偏强 | G25: 消费/需求恢复 | H25: 基本面筛选与排序；非交易仓位指令 | I25: 一级行业 | J25: 高频需求、渠道库存和价格/利润交叉确认，使用季调数据。
A26: 通信 | B26: =通信!$P$4 -> 9.5 | C26: =通信!$P$5 -> 8.5 | D26: =通信!$P$6 -> 8 | E26: =通信!$G$18 -> 8.9 | F26: =IF(E26>=8.5,"强/防过热",IF(E26>=7.5,"偏强",IF(E26>=6.5,"中性偏强",IF(E26>=5,"中性",IF(E26>=3,"偏弱","低迷"))))) -> 强/防过热 | G26: 科技制造/订单库存周期 | H26: 基本面筛选与排序；非交易仓位指令 | I26: 一级行业 | J26: 订单、库存和利用率优先；不同子行业拆分后再汇总。
A27: 银行 | B27: =银行!$P$4 -> 8 | C27: =银行!$P$5 -> 6.5 | D27: =银行!$P$6 -> 6.6 | E27: =银行!$G$18 -> 7 | F27: =IF(E27>=8.5,"强/防过热",IF(E27>=7.5,"偏强",IF(E27>=6.5,"中性偏强",IF(E27>=5,"中性",IF(E27>=3,"偏弱","低迷"))))) -> 中性偏强 | G27: 防御/成熟 | H27: 基本面筛选与排序；非交易仓位指令 | I27: 一级行业 | J27: 同步经营和现金流优先；先行指标只作边际变化确认。
A28: 非银金融 | B28: =非银金融!$P$4 -> 7.1 | C28: =非银金融!$P$5 -> 7.1 | D28: =非银金融!$P$6 -> 7.4 | E28: =非银金融!$G$18 -> 7.2 | F28: =IF(E28>=8.5,"强/防过热",IF(E28>=7.5,"偏强",IF(E28>=6.5,"中性偏强",IF(E28>=5,"中性",IF(E28>=3,"偏弱","低迷"))))) -> 中性偏强 | G28: 信用/风险偏好周期 | H28: 基本面筛选与排序；非交易仓位指令 | I28: 一级行业 | J28: 信用与资产质量优先；券商、保险、银行不宜混算。
A29: 汽车 | B29: =汽车!$P$4 -> 7.3 | C29: =汽车!$P$5 -> 8 | D29: =汽车!$P$6 -> 7.4 | E29: =汽车!$G$18 -> 7.6 | F29: =IF(E29>=8.5,"强/防过热",IF(E29>=7.5,"偏强",IF(E29>=6.5,"中性偏强",IF(E29>=5,"中性",IF(E29>=3,"偏弱","低迷"))))) -> 偏强 | G29: 消费/需求恢复 | H29: 基本面筛选与排序；非交易仓位指令 | I29: 一级行业 | J29: 高频需求、渠道库存和价格/利润交叉确认，使用季调数据。
A30: 机械设备 | B30: =机械设备!$P$4 -> 7.5 | C30: =机械设备!$P$5 -> 7.5 | D30: =机械设备!$P$6 -> 6 | E30: =机械设备!$G$18 -> 7.2 | F30: =IF(E30>=8.5,"强/防过热",IF(E30>=7.5,"偏强",IF(E30>=6.5,"中性偏强",IF(E30>=5,"中性",IF(E30>=3,"偏弱","低迷"))))) -> 中性偏强 | G30: 科技制造/订单库存周期 | H30: 基本面筛选与排序；非交易仓位指令 | I30: 一级行业 | J30: 订单、库存和利用率优先；不同子行业拆分后再汇总。
A31: 煤炭 | B31: =煤炭!$P$4 -> 7.6 | C31: =煤炭!$P$5 -> 7.6 | D31: =煤炭!$P$6 -> 6.6 | E31: =煤炭!$G$18 -> 7.5 | F31: =IF(E31>=8.5,"强/防过热",IF(E31>=7.5,"偏强",IF(E31>=6.5,"中性偏强",IF(E31>=5,"中性",IF(E31>=3,"偏弱","低迷"))))) -> 偏强 | G31: 强周期/供给出清 | H31: 基本面筛选与排序；非交易仓位指令 | I31: 一级行业 | J31: 先用库存、供给、订单确认反转；价格本身不能直接等同高景气。
A32: 石油石化 | B32: =石油石化!$P$4 -> 7.6 | C32: =石油石化!$P$5 -> 6 | D32: =石油石化!$P$6 -> 6.6 | E32: =石油石化!$G$18 -> 6.9 | F32: =IF(E32>=8.5,"强/防过热",IF(E32>=7.5,"偏强",IF(E32>=6.5,"中性偏强",IF(E32>=5,"中性",IF(E32>=3,"偏弱","低迷"))))) -> 中性偏强 | G32: 强周期/供给出清 | H32: 基本面筛选与排序；非交易仓位指令 | I32: 一级行业 | J32: 先用库存、供给、订单确认反转；价格本身不能直接等同高景气。
A33: 环保 | B33: =环保!$P$4 -> 8 | C33: =环保!$P$5 -> 6.5 | D33: =环保!$P$6 -> 6 | E33: =环保!$G$18 -> 7.1 | F33: =IF(E33>=8.5,"强/防过热",IF(E33>=7.5,"偏强",IF(E33>=6.5,"中性偏强",IF(E33>=5,"中性",IF(E33>=3,"偏弱","低迷"))))) -> 中性偏强 | G33: 政策资本开支/交付 | H33: 基本面筛选与排序；非交易仓位指令 | I33: 一级行业 | J33: 政策与规划只作确认项，必须由招标、交付、回款和利润验证。
A34: 美容护理 | B34: =美容护理!$P$4 -> 5.8 | C34: =美容护理!$P$5 -> 7.6 | D34: =美容护理!$P$6 -> 7.2 | E34: =美容护理!$G$18 -> 6.8 | F34: =IF(E34>=8.5,"强/防过热",IF(E34>=7.5,"偏强",IF(E34>=6.5,"中性偏强",IF(E34>=5,"中性",IF(E34>=3,"偏弱","低迷"))))) -> 中性偏强 | G34: 消费/需求恢复 | H34: 基本面筛选与排序；非交易仓位指令 | I34: 一级行业 | J34: 高频需求、渠道库存和价格/利润交叉确认，使用季调数据。
A35: 半导体 | B35: =半导体!$P$4 -> 8 | C35: =半导体!$P$5 -> 7.6 | D35: =半导体!$P$6 -> 8.6 | E35: =半导体!$G$22 -> 8 | F35: =IF(E35>=8.5,"强/防过热",IF(E35>=7.5,"偏强",IF(E35>=6.5,"中性偏强",IF(E35>=5,"中性",IF(E35>=3,"偏弱","低迷"))))) -> 偏强 | G35: 科技制造/订单库存周期 | H35: 基本面筛选与排序；非交易仓位指令 | I35: 重点细分行业 | J35: 订单、库存和利用率优先；不同子行业拆分后再汇总。
A36: 新能源 | B36: =新能源!$P$4 -> 8.6 | C36: =新能源!$P$5 -> 6.5 | D36: =新能源!$P$6 -> 5.4 | E36: =新能源!$G$22 -> 7.3 | F36: =IF(E36>=8.5,"强/防过热",IF(E36>=7.5,"偏强",IF(E36>=6.5,"中性偏强",IF(E36>=5,"中性",IF(E36>=3,"偏弱","低迷"))))) -> 中性偏强 | G36: 强周期/供给出清 | H36: 基本面筛选与排序；非交易仓位指令 | I36: 重点细分行业 | J36: 先用库存、供给、订单确认反转；价格本身不能直接等同高景气。
A37: 医药医疗 | B37: =医药医疗!$P$4 -> 8 | C37: =医药医疗!$P$5 -> 7.2 | D37: =医药医疗!$P$6 -> 8 | E37: =医药医疗!$G$22 -> 7.7 | F37: =IF(E37>=8.5,"强/防过热",IF(E37>=7.5,"偏强",IF(E37>=6.5,"中性偏强",IF(E37>=5,"中性",IF(E37>=3,"偏弱","低迷"))))) -> 偏强 | G37: 科技制造/订单库存周期 | H37: 基本面筛选与排序；非交易仓位指令 | I37: 重点细分行业 | J37: 订单、库存和利用率优先；不同子行业拆分后再汇总。
A38: 高端制造 | B38: =高端制造!$P$4 -> 7.6 | C38: =高端制造!$P$5 -> 7 | D38: =高端制造!$P$6 -> 6 | E38: =高端制造!$G$19 -> 7.2 | F38: =IF(E38>=8.5,"强/防过热",IF(E38>=7.5,"偏强",IF(E38>=6.5,"中性偏强",IF(E38>=5,"中性",IF(E38>=3,"偏弱","低迷"))))) -> 中性偏强 | G38: 科技制造/订单库存周期 | H38: 基本面筛选与排序；非交易仓位指令 | I38: 重点细分行业 | J38: 订单、库存和利用率优先；不同子行业拆分后再汇总。
A39: 人形机器人 | B39: =人形机器人!$P$4 -> 8.4 | C39: =人形机器人!$P$5 -> 7.6 | D39: =人形机器人!$P$6 -> 5.8 | E39: =人形机器人!$G$19 -> 7.8 | F39: =IF(E39>=8.5,"强/防过热",IF(E39>=7.5,"偏强",IF(E39>=6.5,"中性偏强",IF(E39>=5,"中性",IF(E39>=3,"偏弱","低迷"))))) -> 偏强 | G39: 早期产业化/兑现 | H39: 基本面筛选与排序；非交易仓位指令 | I39: 重点细分行业 | J39: 量产、订单、交付优先；热度与规划指标不得主导评分。
A40: AI算力 | B40: =AI算力!$P$4 -> 9.4 | C40: =AI算力!$P$5 -> 8.5 | D40: =AI算力!$P$6 -> 8 | E40: =AI算力!$G$19 -> 8.9 | F40: =IF(E40>=8.5,"强/防过热",IF(E40>=7.5,"偏强",IF(E40>=6.5,"中性偏强",IF(E40>=5,"中性",IF(E40>=3,"偏弱","低迷"))))) -> 强/防过热 | G40: 早期产业化/兑现 | H40: 基本面筛选与排序；非交易仓位指令 | I40: 重点细分行业 | J40: 量产、订单、交付优先；热度与规划指标不得主导评分。
...

Sheet 农林牧渔
A1: 行业景气度量化跟踪体系（参数优化版）— 农林牧渔
A2: 默认阶段框架：强周期/供给出清｜先行/同步/滞后=50%/35%/15%。先用库存、供给、订单确认反转；价格本身不能直接等同高景气。｜核心验证：供给周期与养殖价差；必选：母猪存栏/淘汰率、仔猪价、饲料成本
A3: 指标名称 | B3: 数据来源 | C3: 最新数值 | D3: 单位 | E3: 趋势 | F3: 权重 | G3: 评分 (1-10) | H3: 评分阈值说明 | I3: 历史分位 | J3: 对景气度影响 | K3: 跟踪频率 | L3: 原权重 | M3: 参数优化建议 | N3: 评分口径（更新时采用） | O3: 阶段分项 | P3: 公式分数
A4: 【第一部分：先行指标（Leading Indicators）——提前1-2个季度预示景气变化】 | O4: 先行 | P4: =ROUND(SUMPRODUCT(F5:F9,G5:G9)/SUM(F5:F9),1) -> 7.2
A5: 1-能繁母猪存栏量变化 | B5: 农业农村部 | C5: +1.2 | D5: %YoY | E5: 企稳 | F5: 0.125 | G5: 6 | H5: >5%=10分,2-5%=8分,0-2%=6分,-2-0%=4分,<-2%=2分 | I5: 45% | J5: 产能温和回升，供给端压力可控 | K5: 月度 | L5: 0.15 | M5: 目标组权重 50%；按同组相对重要性归一化。 | N5: 采用5年滚动分位+同比/环比双阈值；数据滞后超过一个频率周期时自动降权。 | O5: 同步 | P5: =ROUND(SUMPRODUCT(F11:F14,G11:G14)/SUM(F11:F14),1) -> 6.5
A6: 2-仔猪价格变化 | B6: 农业农村部/博亚和讯 | C6: +35 | D6: %YoY | E6: 大涨 | F6: 0.125 | G6: 9 | H6: >30%=10分,10-30%=8分,0-10%=6分,-10-0%=4分,<-10%=2分 | I6: 78% | J6: 补栏积极性高，预示6个月后出栏增加 | K6: 周度 | L6: 0.15 | M6: 目标组权重 50%；按同组相对重要性归一化。 | N6: 改为5年滚动分位(P20/P40/P60/P80)+3个月动量；须与库存、价差或利润交叉确认。 | O6: 滞后 | P6: =ROUND(SUMPRODUCT(F16:F18,G16:G18)/SUM(F16:F18),1) -> 6.6
A7: 3-饲料价格变化 | B7: 中国饲料工业协会 | C7: -3.5 | D7: %YoY | E7: 下行 | F7: 0.1 | G7: 8 | H7: <-10%=10分,-10-0%=8分,0-5%=6分,5-10%=4分,>10%=2分 | I7: 35% | J7: 成本端改善，养殖利润修复 | K7: 月度 | L7: 0.12 | M7: 目标组权重 50%；按同组相对重要性归一化。 | N7: 改为5年滚动分位(P20/P40/P60/P80)+3个月动量；须与库存、价差或利润交叉确认。
A8: 4-农产品进口量增速 | B8: 海关总署 | C8: +2.1 | D8: %YoY | E8: 上行 | F8: 0.0833 | G8: 6 | H8: <-5%=10分,-5-0%=8分,0-5%=6分,5-10%=4分,>10%=2分 | I8: 52% | J8: 进口平稳，国内供给基本自足 | K8: 月度 | L8: 0.1 | M8: 目标组权重 50%；按同组相对重要性归一化。 | N8: 采用5年滚动分位+同比/环比双阈值；数据滞后超过一个频率周期时自动降权。
A9: 5-种植面积变化 | B9: 国家统计局 | C9: +0.8 | D9: %YoY | E9: 企稳 | F9: 0.0667 | G9: 6 | H9: >2%=10分,0-2%=8分,-2-0%=6分,-5--2%=4分,<-5%=2分 | I9: 48% | J9: 种植面积稳定，产量预期平稳 | K9: 年度 | L9: 0.08 | M9: 目标组权重 50%；按同组相对重要性归一化。 | N9: 采用5年滚动分位+同比/环比双阈值；数据滞后超过一个频率周期时自动降权。
A10: 【第二部分：同步指标（Coincident Indicators）——与当前景气同步变动】
A11: 6-生猪出栏均价 | B11: 农业农村部 | C11: 15.8 | D11: 元/公斤 | E11: 上行 | F11: 0.1312 | G11: 6 | H11: >20=10分,16-20=8分,14-16=6分,12-14=4分,<12=2分 | I11: 55% | J11: 猪价温和回升，养殖盈利改善 | K11: 周度 | L11: 0.15 | M11: 目标组权重 35%；按同组相对重要性归一化。 | N11: 改为5年滚动分位(P20/P40/P60/P80)+3个月动量；须与库存、价差或利润交叉确认。
A12: 7-白羽肉鸡价格 | B12: 博亚和讯 | C12: 8.2 | D12: 元/公斤 | E12: 上行 | F12: 0.0875 | G12: 8 | H12: >10=10分,8-10=8分,7-8=6分,6-7=4分,<6=2分 | I12: 62% | J12: 禽价处于较好水平，养殖利润可观 | K12: 周度 | L12: 0.1 | M12: 目标组权重 35%；按同组相对重要性归一化。 | N12: 改为5年滚动分位(P20/P40/P60/P80)+3个月动量；须与库存、价差或利润交叉确认。
A13: 8-水产批发价格指数 | B13: 农业农村部 | C13: 112 | D13: 点 | E13: 上行 | F13: 0.07 | G13: 6 | H13: >120=10分,110-120=8分,100-110=6分,90-100=4分,<90=2分 | I13: 58% | J13: 水产价格温和上涨，消费旺季来临 | K13: 周度 | L13: 0.08 | M13: 目标组权重 35%；按同组相对重要性归一化。 | N13: 改为5年滚动分位(P20/P40/P60/P80)+3个月动量；须与库存、价差或利润交叉确认。
A14: 9-农产品批发价格200指数 | B14: 农业农村部 | C14: 118 | D14: 点 | E14: 上行 | F14: 0.0612 | G14: 6 | H14: >130=10分,120-130=8分,110-120=6分,100-110=4分,<100=2分 | I14: 54% | J14: 农产品价格整体平稳略升 | K14: 日度 | L14: 0.07 | M14: 目标组权重 35%；按同组相对重要性归一化。 | N14: 改为5年滚动分位(P20/P40/P60/P80)+3个月动量；须与库存、价差或利润交叉确认。
A15: 【第三部分：滞后指标（Lagging Indicators）——滞后1-2个季度反映景气变化】
A16: 10-养殖企业季度净利润率 | B16: 上市公司财报 | C16: 6.5 | D16: % | E16: 上行 | F16: 0.06 | G16: 6 | H16: >15%=10分,5-15%=8分,0-5%=6分,-5-0%=4分,<-5%=2分 | I16: 48% | J16: Q1养殖利润转正，景气度回升 | K16: 季度 | L16: 0.1 | M16: 目标组权重 15%；按同组相对重要性归一化。 | N16: 采用TTM/滚动4季同比+历史分位；剔除一次性损益，IRR按项目现金流复核。
A17: 11-农林牧渔固定资产投资增速 | B17: 国家统计局 | C17: +8.2 | D17: %YoY | E17: 上行 | F17: 0.048 | G17: 8 | H17: >15%=10分,5-15%=8分,0-5%=6分,-5-0%=4分,<-5%=2分 | I17: 60% | J17: 投资回暖，产能扩张意愿增强 | K17: 季度 | L17: 0.08 | M17: 目标组权重 15%；按同组相对重要性归一化。 | N17: 采用5年滚动分位+同比/环比双阈值；数据滞后超过一个频率周期时自动降权。
A18: 12-CPI食品项同比 | B18: 国家统计局 | C18: +1.2 | D18: % | E18: 上行 | F18: 0.042 | G18: 6 | H18: >5%=10分,2-5%=8分,0-2%=6分,-2-0%=4分,<-2%=2分 | I18: 42% | J18: 食品通胀温和，终端需求平稳 | K18: 月度 | L18: 0.07 | M18: 目标组权重 15%；按同组相对重要性归一化。 | N18: 采用5年滚动分位+同比/环比双阈值；数据滞后超过一个频率周期时自动降权。
A19: 行业综合景气度加权得分 | G19: =ROUND(SUMPRODUCT(F5:F18,G5:G18),1) -> 6.8 | H19: 综合分=Σ(建议权重×单项评分)，建议权重和=100%。

Sheet 基础化工
A1: 行业景气度量化跟踪体系（参数优化版）— 基础化工
A2: 默认阶段框架：强周期/供给出清｜先行/同步/滞后=50%/35%/15%。先用库存、供给、订单确认反转；价格本身不能直接等同高景气。｜核心验证：库存周期与价差修复；必选：下游订单、库存、计划新增产能
A3: 指标名称 | B3: 数据来源 | C3: 最新数值 | D3: 单位 | E3: 趋势 | F3: 权重 | G3: 评分 (1-10) | H3: 评分阈值说明 | I3: 历史分位 | J3: 对景气度影响 | K3: 跟踪频率 | L3: 原权重 | M3: 参数优化建议 | N3: 评分口径（更新时采用） | O3: 阶段分项 | P3: 公式分数
A4: 【第一部分：先行指标（Leading Indicators）——提前1-2个季度预示景气变化】 | O4: 先行 | P4: =ROUND(SUMPRODUCT(F5:F8,G5:G8)/SUM(F5:F8),1) -> 8
A5: 1-原油价格变化 | B5: WTI/布伦特 | C5: 72 | D5: 美元/桶 | E5: 下行 | F5: 0.15 | G5: 8 | H5: 60-80=10分,50-60或80-90=8分,40-50或90-100=6分,<40或>100=4分 | I5: 55% | J5: 油价中枢回落，成本压力缓解 | K5: 日度 | L5: 0.15 | M5: 目标组权重 50%；按同组相对重要性归一化。 | N5: 改为5年滚动分位(P20/P40/P60/P80)+3个月动量；须与库存、价差或利润交叉确认。 | O5: 同步 | P5: =ROUND(SUMPRODUCT(F10:F13,G10:G13)/SUM(F10:F13),1) -> 6.8
A6: 2-煤化工原料煤价格 | B6: 秦皇岛动力煤 | C6: 680 | D6: 元/吨 | E6: 下行 | F6: 0.12 | G6: 10 | H6: <700=10分,700-800=8分,800-900=6分,900-1000=4分,>1000=2分 | I6: 30% | J6: 煤价处于低位，煤化工成本优势明显 | K6: 周度 | L6: 0.12 | M6: 目标组权重 50%；按同组相对重要性归一化。 | N6: 改为5年滚动分位(P20/P40/P60/P80)+3个月动量；须与库存、价差或利润交叉确认。 | O6: 滞后 | P6: =ROUND(SUMPRODUCT(F15:F17,G15:G17)/SUM(F15:F17),1) -> 6.6
A7: 3-化工品产能利用率 | B7: 卓创资讯 | C7: 74 | D7: % | E7: 上行 | F7: 0.13 | G7: 6 | H7: >80%=10分,75-80%=8分,70-75%=6分,65-70%=4分,<65%=2分 | I7: 52% | J7: 产能利用率回升，供需格局改善 | K7: 月度 | L7: 0.13 | M7: 目标组权重 50%；按同组相对重要性归一化。 | N7: 采用TTM/滚动4季同比+历史分位；剔除一次性损益，IRR按项目现金流复核。
A8: 4-新增产能投放计划 | B8: 公司公告/行业协会 | C8: +3.5 | D8: % | E8: 放缓 | F8: 0.1 | G8: 8 | H8: <2%=10分,2-5%=8分,5-8%=6分,8-12%=4分,>12%=2分 | I8: 45% | J8: 产能投放放缓，供给压力减轻 | K8: 季度 | L8: 0.1 | M8: 目标组权重 50%；按同组相对重要性归一化。 | N8: 采用5年滚动分位+同比/环比双阈值；数据滞后超过一个频率周期时自动降权。
A9: 【第二部分：同步指标（Coincident Indicators）——与当前景气同步变动】
A10: 5-中国化工产品价格指数(CCPI) | B10: 卓创资讯 | C10: 4850 | D10: 点 | E10: 上行 | F10: 0.1167 | G10: 6 | H10: >5500=10分,5000-5500=8分,4500-5000=6分,4000-4500=4分,<4000=2分 | I10: 48% | J10: 化工品价格温和上涨，价差修复 | K10: 周度 | L10: 0.15 | M10: 目标组权重 35%；按同组相对重要性归一化。 | N10: 改为5年滚动分位(P20/P40/P60/P80)+3个月动量；须与库存、价差或利润交叉确认。
A11: 6-主要化工品价差 | B11: 百川盈孚 | C11: +5 | D11: %vs均值 | E11: 上行 | F11: 0.0933 | G11: 6 | H11: >历史均值20%=10分,0-20%=8分,-10-0%=6分,-20--10%=4分,<-20%=2分 | I11: 55% | J11: 价差改善，企业盈利空间扩大 | K11: 周度 | L11: 0.12 | M11: 目标组权重 35%；按同组相对重要性归一化。 | N11: 改为5年滚动分位(P20/P40/P60/P80)+3个月动量；须与库存、价差或利润交叉确认。
A12: 7-化工品库存天数 | B12: 卓创资讯 | C12: 18 | D12: 天 | E12: 下行 | F12: 0.0778 | G12: 8 | H12: <15天=10分,15-20天=8分,20-25天=6分,25-30天=4分,>30天=2分 | I12: 40% | J12: 库存健康，去库接近尾声 | K12: 月度 | L12: 0.1 | M12: 目标组权重 35%；按同组相对重要性归一化。 | N12: 采用同比、环比、历史分位三维评分；按去库/改善方向计分。
A13: 8-化工品出口增速 | B13: 海关总署 | C13: +12.5 | D13: %YoY | E13: 上行 | F13: 0.0622 | G13: 8 | H13: >15%=10分,5-15%=8分,0-5%=6分,-5-0%=4分,<-5%=2分 | I13: 65% | J13: 出口强劲，外需支撑景气度 | K13: 月度 | L13: 0.08 | M13: 目标组权重 35%；按同组相对重要性归一化。 | N13: 采用5年滚动分位+同比/环比双阈值；数据滞后超过一个频率周期时自动降权。
A14: 【第三部分：滞后指标（Lagging Indicators）——滞后1-2个季度反映景气变化】
A15: 9-化工企业季度ROE | B15: 上市公司财报 | C15: 7.5 | D15: % | E15: 上行 | F15: 0.06 | G15: 6 | H15: >12%=10分,8-12%=8分,4-8%=6分,0-4%=4分,<0%=2分 | I15: 50% | J15: Q1盈利修复，ROE回升 | K15: 季度 | L15: 0.1 | M15: 目标组权重 15%；按同组相对重要性归一化。 | N15: 采用TTM/滚动4季同比+历史分位；剔除一次性损益，IRR按项目现金流复核。
A16: 10-化工行业固定资产投资增速 | B16: 国家统计局 | C16: +8.5 | D16: %YoY | E16: 上行 | F16: 0.048 | G16: 8 | H16: >10%=10分,5-10%=8分,0-5%=6分,-5-0%=4分,<-5%=2分 | I16: 58% | J16: 投资回暖，扩产意愿增强 | K16: 季度 | L16: 0.08 | M16: 目标组权重 15%；按同组相对重要性归一化。 | N16: 采用5年滚动分位+同比/环比双阈值；数据滞后超过一个频率周期时自动降权。
A17: 11-PPI化工原料同比 | B17: 国家统计局 | C17: +2.5 | D17: % | E17: 上行 | F17: 0.042 | G17: 6 | H17: >5%=10分,0-5%=8分,-3-0%=6分,-6--3%=4分,<-6%=2分 | I17: 55% | J17: 价格同比转正，通缩压力缓解 | K17: 月度 | L17: 0.07 | M17: 目标组权重 15%；按同组相对重要性归一化。 | N17: 采用5年滚动分位+同比/环比双阈值；数据滞后超过一个频率周期时自动降权。
A18: 行业综合景气度加权得分 | G18: =ROUND(SUMPRODUCT(F5:F17,G5:G17),1) -> 7.4 | H18: 综合分=Σ(建议权重×单项评分)，建议权重和=100%。

Sheet 钢铁
A1: 行业景气度量化跟踪体系（参数优化版）— 钢铁
A2: 默认阶段框架：强周期/供给出清｜先行/同步/滞后=50%/35%/15%。先用库存、供给、订单确认反转；价格本身不能直接等同高景气。｜核心验证：需求/去库与利润修复；必选：地产施工、基建实物量、库存变化
A3: 指标名称 | B3: 数据来源 | C3: 最新数值 | D3: 单位 | E3: 趋势 | F3: 权重 | G3: 评分 (1-10) | H3: 评分阈值说明 | I3: 历史分位 | J3: 对景气度影响 | K3: 跟踪频率 | L3: 原权重 | M3: 参数优化建议 | N3: 评分口径（更新时采用） | O3: 阶段分项 | P3: 公式分数
A4: 【第一部分：先行指标（Leading Indicators）——提前1-2个季度预示景气变化】 | O4: 先行 | P4: =ROUND(SUMPRODUCT(F5:F8,G5:G8)/SUM(F5:F8),1) -> 8
A5: 1-铁矿石价格变化 | B5: 普氏62%指数 | C5: 105 | D5: 美元/吨 | E5: 下行 | F5: 0.15 | G5: 8 | H5: 80-100=10分,70-80或100-120=8分,60-70或120-140=6分,<60或>140=4分 | I5: 62% | J5: 矿价回落，成本压力减轻 | K5: 日度 | L5: 0.15 | M5: 目标组权重 50%；按同组相对重要性归一化。 | N5: 改为5年滚动分位(P20/P40/P60/P80)+3个月动量；须与库存、价差或利润交叉确认。 | O5: 同步 | P5: =ROUND(SUMPRODUCT(F10:F13,G10:G13)/SUM(F10:F13),1) -> 6
A6: 2-焦煤价格变化 | B6: CCI指数 | C6: 1650 | D6: 元/吨 | E6: 下行 | F6: 0.12 | G6: 8 | H6: <1500=10分,1500-1800=8分,1800-2200=6分,2200-2600=4分,>2600=2分 | I6: 45% | J6: 焦煤价格回落，焦炭成本下降 | K6: 周度 | L6: 0.12 | M6: 目标组权重 50%；按同组相对重要性归一化。 | N6: 改为5年滚动分位(P20/P40/P60/P80)+3个月动量；须与库存、价差或利润交叉确认。 | O6: 滞后 | P6: =ROUND(SUMPRODUCT(F15:F17,G15:G17)/SUM(F15:F17),1) -> 6
A7: 3-高炉开工率 | B7: Mysteel | C7: 82 | D7: % | E7: 上行 | F7: 0.13 | G7: 8 | H7: >85%=10分,80-85%=8分,75-80%=6分,70-75%=4分,<70%=2分 | I7: 58% | J7: 开工率回升，生产积极性改善 | K7: 周度 | L7: 0.13 | M7: 目标组权重 50%；按同组相对重要性归一化。 | N7: 采用5年滚动分位+同比/环比双阈值；数据滞后超过一个频率周期时自动降权。
A8: 4-钢材社会库存变化 | B8: Mysteel | C8: -4.2 | D8: %MoM | E8: 去库 | F8: 0.1 | G8: 8 | H8: <-5%=10分,-5-0%=8分,0-5%=6分,5-10%=4分,>10%=2分 | I8: 38% | J8: 库存去化顺利，供需格局改善 | K8: 周度 | L8: 0.1 | M8: 目标组权重 50%；按同组相对重要性归一化。 | N8: 采用同比、环比、历史分位三维评分；按去库/改善方向计分。
A9: 【第二部分：同步指标（Coincident Indicators）——与当前景气同步变动】
A10: 5-螺纹钢现货价格 | B10: 上海钢联 | C10: 3450 | D10: 元/吨 | E10: 上行 | F10: 0.1167 | G10: 6 | H10: >4000=10分,3500-4000=8分,3000-3500=6分,2500-3000=4分,<2500=2分 | I10: 48% | J10: 钢价温和回升，盈利边际改善 | K10: 日度 | L10: 0.15 | M10: 目标组权重 35%；按同组相对重要性归一化。 | N10: 改为5年滚动分位(P20/P40/P60/P80)+3个月动量；须与库存、价差或利润交叉确认。
A11: 6-热轧板卷价格 | B11: 上海钢联 | C11: 3650 | D11: 元/吨 | E11: 上行 | F11: 0.0778 | G11: 6 | H11: >4200=10分,3800-4200=8分,3400-3800=6分,3000-3400=4分,<3000=2分 | I11: 45% | J11: 板材价格回升，制造业需求支撑 | K11: 日度 | L11: 0.1 | M11: 目标组权重 35%；按同组相对重要性归一化。 | N11: 改为5年滚动分位(P20/P40/P60/P80)+3个月动量；须与库存、价差或利润交叉确认。
A12: 7-钢厂盈利面 | B12: Mysteel | C12: 55 | D12: % | E12: 上行 | F12: 0.0933 | G12: 6 | H12: >70%=10分,50-70%=8分,30-50%=6分,10-30%=4分,<10%=2分 | I12: 48% | J12: 盈利面扩大，过半钢厂实现盈利 | K12: 周度 | L12: 0.12 | M12: 目标组权重 35%；按同组相对重要性归一化。 | N12: 采用5年滚动分位+同比/环比双阈值；数据滞后超过一个频率周期时自动降权。
A13: 8-钢材表观消费量 | B13: 国家统计局 | C13: 1.05 | D13: 亿吨/年化 | E13: 上行 | F13: 0.0622 | G13: 6 | H13: >1.1亿年化=10分,1.0-1.1亿=8分,0.9-1.0亿=6分,0.8-0.9亿=4分,<0.8亿=2分 | I13: 52% | J13: 表观消费回升，需求端改善 | K13: 月度 | L13: 0.08 | M13: 目标组权重 35%；按同组相对重要性归一化。 | N13: 采用季调同比+3个月环比；单月值用3个月移动均值过滤。
A14: 【第三部分：滞后指标（Lagging Indicators）——滞后1-2个季度反映景气变化】
A15: 9-钢铁企业季度净利润 | B15: 上市公司财报 | C15: 35 | D15: 亿元 | E15: 上行 | F15: 0.06 | G15: 6 | H15: >50亿=10分,20-50亿=8分,0-20亿=6分,-20-0亿=4分,<-20亿=2分 | I15: 45% | J15: Q1扭亏为盈，利润端改善 | K15: 季度 | L15: 0.1 | M15: 目标组权重 15%；按同组相对重要性归一化。 | N15: 采用TTM/滚动4季同比+历史分位；剔除一次性损益，IRR按项目现金流复核。
A16: 10-钢铁行业产能利用率 | B16: 国家统计局 | C16: 77 | D16: % | E16: 上行 | F16: 0.048 | G16: 6 | H16: >80%=10分,75-80%=8分,70-75%=6分,65-70%=4分,<65%=2分 | I16: 52% | J16: 产能利用率回升，供需趋于平衡 | K16: 季度 | L16: 0.08 | M16: 目标组权重 15%；按同组相对重要性归一化。 | N16: 采用TTM/滚动4季同比+历史分位；剔除一次性损益，IRR按项目现金流复核。
A17: 11-PPI黑色金属冶炼同比 | B17: 国家统计局 | C17: +1.8 | D17: % | E17: 上行 | F17: 0.042 | G17: 6 | H17: >5%=10分,0-5%=8分,-5-0%=6分,-10--5%=4分,<-10%=2分 | I17: 48% | J17: 价格同比转正，通缩压力缓解 | K17: 月度 | L17: 0.07 | M17: 目标组权重 15%；按同组相对重要性归一化。 | N17: 采用5年滚动分位+同比/环比双阈值；数据滞后超过一个频率周期时自动降权。
A18: 行业综合景气度加权得分 | G18: =ROUND(SUMPRODUCT(F5:F17,G5:G17),1) -> 7 | H18: 综合分=Σ(建议权重×单项评分)，建议权重和=100%。

Sheet 有色金属
A1: 行业景气度量化跟踪体系（参数优化版）— 有色金属
A2: 默认阶段框架：资源品/宏观供需｜先行/同步/滞后=45%/40%/15%。库存、加工费、美元和价格共同确认。｜核心验证：库存、供给约束与需求弹性；必选：库存、TC/RC、美元、矿端扰动
A3: 指标名称 | B3: 数据来源 | C3: 最新数值 | D3: 单位 | E3: 趋势 | F3: 权重 | G3: 评分 (1-10) | H3: 评分阈值说明 | I3: 历史分位 | J3: 对景气度影响 | K3: 跟踪频率 | L3: 原权重 | M3: 参数优化建议 | N3: 评分口径（更新时采用） | O3: 阶段分项 | P3: 公式分数
A4: 【第一部分：先行指标（Leading Indicators）——提前1-2个季度预示景气变化】 | O4: 先行 | P4: =ROUND(SUMPRODUCT(F5:F8,G5:G8)/SUM(F5:F8),1) -> 6.9
A5: 1-LME铜库存变化 | B5: LME | C5: -12 | D5: %YoY | E5: 去库 | F5: 0.15 | G5: 8 | H5: <-10%=10分,-10-0%=8分,0-10%=6分,10-20%=4分,>20%=2分 | I5: 35% | J5: 全球库存去化，供给偏紧 | K5: 周度 | L5: 0.15 | M5: 目标组权重 45%；按同组相对重要性归一化。 | N5: 采用同比、环比、历史分位三维评分；按去库/改善方向计分。 | O5: 同步 | P5: =ROUND(SUMPRODUCT(F10:F13,G10:G13)/SUM(F10:F13),1) -> 8.7
A6: 2-铜精矿TC/RC | B6: SMM | C6: 25 | D6: 美元/吨 | E6: 下行 | F6: 0.12 | G6: 4 | H6: >80=10分,60-80=8分,40-60=6分,20-40=4分,<20=2分 | I6: 15% | J6: 加工费极低，铜矿供给紧张 | K6: 月度 | L6: 0.12 | M6: 目标组权重 45%；按同组相对重要性归一化。 | N6: 改为5年滚动分位(P20/P40/P60/P80)+3个月动量；须与库存、价差或利润交叉确认。 | O6: 滞后 | P6: =ROUND(SUMPRODUCT(F15:F17,G15:G17)/SUM(F15:F17),1) -> 8.6
A7: 3-美元指数 | B7: 美联储 | C7: 99.5 | D7: 点 | E7: 下行 | F7: 0.1 | G7: 8 | H7: <100=10分,100-103=8分,103-106=6分,106-110=4分,>110=2分 | I7: 35% | J7: 美元走弱，利好大宗商品定价 | K7: 日度 | L7: 0.1 | M7: 目标组权重 45%；按同组相对重要性归一化。 | N7: 采用5年滚动分位+同比/环比双阈值；数据滞后超过一个频率周期时自动降权。
A8: 4-全球矿山资本开支增速 | B8: Wood Mackenzie | C8: +18 | D8: %YoY | E8: 上行 | F8: 0.08 | G8: 8 | H8: >15%=10分,5-15%=8分,0-5%=6分,-5-0%=4分,<-5%=2分 | I8: 65% | J8: 资本开支增加，远期供给有望改善 | K8: 年度 | L8: 0.08 | M8: 目标组权重 45%；按同组相对重要性归一化。 | N8: 采用5年滚动分位+同比/环比双阈值；数据滞后超过一个频率周期时自动降权。
A9: 【第二部分：同步指标（Coincident Indicators）——与当前景气同步变动】
A10: 5-LME铜现货价格 | B10: LME | C10: 9800 | D10: 美元/吨 | E10: 上行 | F10: 0.1395 | G10: 10 | H10: >9500=10分,8500-9500=8分,7500-8500=6分,6500-7500=4分,<6500=2分 | I10: 85% | J10: 铜价处于历史高位，新能源+AI需求强劲 | K10: 日度 | L10: 0.15 | M10: 目标组权重 40%；按同组相对重要性归一化。 | N10: 改为5年滚动分位(P20/P40/P60/P80)+3个月动量；须与库存、价差或利润交叉确认。
A11: 6-铝现货价格 | B11: SMM | C11: 20500 | D11: 元/吨 | E11: 上行 | F11: 0.093 | G11: 10 | H11: >20000=10分,18000-20000=8分,16000-18000=6分,14000-16000=4分,<14000=2分 | I11: 78% | J11: 铝价高位运行，氧化铝成本支撑 | K11: 日度 | L11: 0.1 | M11: 目标组权重 40%；按同组相对重要性归一化。 | N11: 改为5年滚动分位(P20/P40/P60/P80)+3个月动量；须与库存、价差或利润交叉确认。
A12: 7-有色金属冶炼加工费 | B12: SMM | C12: +8 | D12: %vs均值 | E12: 上行 | F12: 0.093 | G12: 6 | H12: >均值20%=10分,0-20%=8分,-10-0%=6分,-20--10%=4分,<-20%=2分 | I12: 55% | J12: 加工费改善，冶炼端利润修复 | K12: 月度 | L12: 0.1 | M12: 目标组权重 40%；按同组相对重要性归一化。 | N12: 采用5年滚动分位+同比/环比双阈值；数据滞后超过一个频率周期时自动降权。
A13: 8-中国有色金属消费量 | B13: 中国有色金属工业协会 | C13: +7.5 | D13: %YoY | E13: 上行 | F13: 0.0744 | G13: 8 | H13: >8%=10分,5-8%=8分,2-5%=6分,0-2%=4分,<0%=2分 | I13: 62% | J13: 消费量稳健增长，新能源需求拉动 | K13: 月度 | L13: 0.08 | M13: 目标组权重 40%；按同组相对重要性归一化。 | N13: 采用季调同比+3个月环比；单月值用3个月移动均值过滤。
A14: 【第三部分：滞后指标（Lagging Indicators）——滞后1-2个季度反映景气变化】
A15: 9-有色企业季度净利润 | B15: 上市公司财报 | C15: 180 | D15: 亿元 | E15: 上行 | F15: 0.06 | G15: 8 | H15: >100亿=10分,50-100亿=8分,10-50亿=6分,0-10亿=4分,<0亿=2分 | I15: 72% | J15: Q1业绩爆发，小金属板块净利增93% | K15: 季度 | L15: 0.1 | M15: 目标组权重 15%；按同组相对重要性归一化。 | N15: 采用TTM/滚动4季同比+历史分位；剔除一次性损益，IRR按项目现金流复核。
A16: 10-有色金属库存周转天数 | B16: 上市公司财报 | C16: 38 | D16: 天 | E16: 下行 | F16: 0.048 | G16: 8 | H16: <30天=10分,30-45天=8分,45-60天=6分,60-75天=4分,>75天=2分 | I16: 42% | J16: 库存周转加快，运营效率提升 | K16: 季度 | L16: 0.08 | M16: 目标组权重 15%；按同组相对重要性归一化。 | N16: 采用同比、环比、历史分位三维评分；按去库/改善方向计分。
A17: 11-PPI有色金属冶炼同比 | B17: 国家统计局 | C17: +12.5 | D17: % | E17: 上行 | F17: 0.042 | G17: 10 | H17: >10%=10分,5-10%=8分,0-5%=6分,-5-0%=4分,<-5%=2分 | I17: 75% | J17: 价格同比大涨，行业景气度高企 | K17: 月度 | L17: 0.07 | M17: 目标组权重 15%；按同组相对重要性归一化。 | N17: 采用5年滚动分位+同比/环比双阈值；数据滞后超过一个频率周期时自动降权。
A18: 行业综合景气度加权得分 | G18: =ROUND(SUMPRODUCT(F5:F17,G5:G17),1) -> 7.9 | H18: 综合分=Σ(建议权重×单项评分)，建议权重和=100%。

Sheet 电子
A1: 行业景气度量化跟踪体系（参数优化版）— 电子
A2: 默认阶段框架：科技制造/订单库存周期｜先行/同步/滞后=50%/35%/15%。订单、库存和利用率优先；不同子行业拆分后再汇总。｜核心验证：库存去化与需求/产能利用率；必选：订单、库存周转、存储价格、终端出货
A3: 指标名称 | B3: 数据来源 | C3: 最新数值 | D3: 单位 | E3: 趋势 | F3: 权重 | G3: 评分 (1-10) | H3: 评分阈值说明 | I3: 历史分位 | J3: 对景气度影响 | K3: 跟踪频率 | L3: 原权重 | M3: 参数优化建议 | N3: 评分口径（更新时采用） | O3: 阶段分项 | P3: 公式分数
A4: 【第一部分：先行指标（Leading Indicators）——提前1-2个季度预示景气变化】 | O4: 先行 | P4: =ROUND(SUMPRODUCT(F5:F9,G5:G9)/SUM(F5:F9),1) -> 8.2
A5: 1-全球半导体销售额增速 | B5: SIA/WSTS | C5: +18.5 | D5: %YoY | E5: 上行 | F5: 0.1364 | G5: 8 | H5: >20%=10分,10-20%=8分,5-10%=6分,0-5%=4分,<0%=2分 | I5: 75% | J5: 半导体周期强劲复苏，AI需求驱动 | K5: 月度 | L5: 0.15 | M5: 目标组权重 50%；按同组相对重要性归一化。 | N5: 采用5年滚动分位+同比/环比双阈值；数据滞后超过一个频率周期时自动降权。 | O5: 同步 | P5: =ROUND(SUMPRODUCT(F11:F14,G11:G14)/SUM(F11:F14),1) -> 7.2
A6: 2-存储芯片价格变化 | B6: DRAMeXchange | C6: +22 | D6: %MoM | E6: 大涨 | F6: 0.1091 | G6: 9 | H6: 涨价>10%=10分,涨价5-10%=8分,持平=5分,跌价5-10%=3分,跌价>10%=1分 | I6: 82% | J6: 存储超级周期，HBM需求爆发 | K6: 周度 | L6: 0.12 | M6: 目标组权重 50%；按同组相对重要性归一化。 | N6: 改为5年滚动分位(P20/P40/P60/P80)+3个月动量；须与库存、价差或利润交叉确认。 | O6: 滞后 | P6: =ROUND(SUMPRODUCT(F16:F18,G16:G18)/SUM(F16:F18),1) -> 8
A7: 3-硅片出货量增速 | B7: SEMI | C7: +15.2 | D7: %YoY | E7: 上行 | F7: 0.0909 | G7: 7 | H7: >30%=10分,20-30%=8分,10-20%=6分,0-10%=4分,<0%=2分 | I7: 68% | J7: 硅片需求回暖，晶圆厂扩产 | K7: 季度 | L7: 0.1 | M7: 目标组权重 50%；按同组相对重要性归一化。 | N7: 采用季调同比+3个月环比；单月值用3个月移动均值过滤。
A8: 4-设备商订单增速 | B8: 应用材料/ASML财报 | C8: +28 | D8: %YoY | E8: 上行 | F8: 0.0909 | G8: 8 | H8: >40%=10分,20-40%=8分,10-20%=6分,0-10%=4分,<0%=2分 | I8: 72% | J8: 设备订单高增，扩产周期确认 | K8: 季度 | L8: 0.1 | M8: 目标组权重 50%；按同组相对重要性归一化。 | N8: 滚动3M/4Q同比；以交付、收入或现金流确认，政策/规划单项权重≤8%。
A9: 5-下游客户库存周转天数 | B9: 下游公司财报 | C9: 58 | D9: 天 | E9: 去库完成 | F9: 0.0727 | G9: 9 | H9: 去库完成<60天=10分,去库中60-80天=7分,高位80-100天=4分,补库初期100-120天=6分,补库后期>120天=3分 | I9: 35% | J9: 库存去化完成，补库周期即将启动 | K9: 季度 | L9: 0.08 | M9: 目标组权重 50%；按同组相对重要性归一化。 | N9: 采用同比、环比、历史分位三维评分；按去库/改善方向计分。
A10: 【第二部分：同步指标（Coincident Indicators）——与当前景气同步变动】
A11: 6-晶圆厂产能利用率 | B11: 台积电/中芯国际 | C11: 88 | D11: % | E11: 上行 | F11: 0.1105 | G11: 8 | H11: >90%=10分,80-90%=8分,70-80%=6分,60-70%=4分,<60%=2分 | I11: 72% | J11: 产能利用率高位，供需偏紧 | K11: 月度 | L11: 0.12 | M11: 目标组权重 35%；按同组相对重要性归一化。 | N11: 采用TTM/滚动4季同比+历史分位；剔除一次性损益，IRR按项目现金流复核。
A12: 7-智能手机出货量增速 | B12: IDC/Counterpoint | C12: +8.5 | D12: %YoY | E12: 上行 | F12: 0.0921 | G12: 8 | H12: >10%=10分,5-10%=8分,0-5%=6分,-5-0%=4分,<-5%=2分 | I12: 60% | J12: 手机出货回暖，AI手机换机潮 | K12: 季度 | L12: 0.1 | M12: 目标组权重 35%；按同组相对重要性归一化。 | N12: 采用季调同比+3个月环比；单月值用3个月移动均值过滤。
A13: 8-PC出货量增速 | B13: IDC/Gartner | C13: +3.2 | D13: %YoY | E13: 上行 | F13: 0.0737 | G13: 6 | H13: >5%=10分,0-5%=8分,-5-0%=6分,-10--5%=4分,<-10%=2分 | I13: 55% | J13: PC出货温和复苏，AI PC渗透 | K13: 季度 | L13: 0.08 | M13: 目标组权重 35%；按同组相对重要性归一化。 | N13: 采用季调同比+3个月环比；单月值用3个月移动均值过滤。
A14: 9-MLCC出货量 | B14: 村田/TDK | C14: 480 | D14: 亿颗/月 | E14: 上行 | F14: 0.0737 | G14: 6 | H14: >500=10分,450-500=8分,400-450=6分,350-400=4分,<350=2分 | I14: 58% | J14: 被动元件出货回升，消费电子复苏 | K14: 月度 | L14: 0.08 | M14: 目标组权重 35%；按同组相对重要性归一化。 | N14: 采用季调同比+3个月环比；单月值用3个月移动均值过滤。
A15: 【第三部分：滞后指标（Lagging Indicators）——滞后1-2个季度反映景气变化】
A16: 10-电子企业季度毛利率 | B16: 上市公司财报 | C16: 28 | D16: % | E16: 上行 | F16: 0.0625 | G16: 8 | H16: >30%=10分,25-30%=8分,20-25%=6分,15-20%=4分,<15%=2分 | I16: 62% | J16: Q1毛利率改善，产品结构优化 | K16: 季度 | L16: 0.1 | M16: 目标组权重 15%；按同组相对重要性归一化。 | N16: 改为5年滚动分位(P20/P40/P60/P80)+3个月动量；须与库存、价差或利润交叉确认。
A17: 11-电子行业固定资产投资增速 | B17: 国家统计局 | C17: +12 | D17: %YoY | E17: 上行 | F17: 0.0437 | G17: 8 | H17: >15%=10分,5-15%=8分,0-5%=6分,-5-0%=4分,<-5%=2分 | I17: 65% | J17: 投资高增，产能扩张积极 | K17: 季度 | L17: 0.07 | M17: 目标组权重 15%；按同组相对重要性归一化。 | N17: 采用5年滚动分位+同比/环比双阈值；数据滞后超过一个频率周期时自动降权。
A18: 12-电子元器件进口金额增速 | B18: 海关总署 | C18: +15 | D18: %YoY | E18: 上行 | F18: 0.0437 | G18: 8 | H18: >10%=10分,5-10%=8分,0-5%=6分,-5-0%=4分,<-5%=2分 | I18: 68% | J18: 进口高增，国内需求旺盛 | K18: 月度 | L18: 0.07 | M18: 目标组权重 15%；按同组相对重要性归一化。 | N18: 采用5年滚动分位+同比/环比双阈值；数据滞后超过一个频率周期时自动降权。
A19: 行业综合景气度加权得分 | G19: =ROUND(SUMPRODUCT(F5:F18,G5:G18),1) -> 7.8 | H19: 综合分=Σ(建议权重×单项评分)，建议权重和=100%。

Sheet 家用电器
A1: 行业景气度量化跟踪体系（参数优化版）— 家用电器
A2: 默认阶段框架：消费/需求恢复｜先行/同步/滞后=40%/40%/20%。高频需求、渠道库存和价格/利润交叉确认，使用季调数据。｜核心验证：更新需求、出口和产品结构；必选：地产竣工、海外订单、排产
A3: 指标名称 | B3: 数据来源 | C3: 最新数值 | D3: 单位 | E3: 趋势 | F3: 权重 | G3: 评分 (1-10) | H3: 评分阈值说明 | I3: 历史分位 | J3: 对景气度影响 | K3: 跟踪频率 | L3: 原权重 | M3: 参数优化建议 | N3: 评分口径（更新时采用） | O3: 阶段分项 | P3: 公式分数
A4: 【第一部分：先行指标（Leading Indicators）——提前1-2个季度预示景气变化】 | O4: 先行 | P4: =ROUND(SUMPRODUCT(F5:F8,G5:G8)/SUM(F5:F8),1) -> 5.3
A5: 1-房地产竣工面积增速 | B5: 国家统计局 | C5: -8.5 | D5: %YoY | E5: 下行 | F5: 0.1277 | G5: 4 | H5: >10%=10分,5-10%=8分,0-5%=6分,-5-0%=4分,<-5%=2分 | I5: 25% | J5: 竣工下滑，后周期需求承压 | K5: 月度 | L5: 0.15 | M5: 目标组权重 40%；按同组相对重要性归一化。 | N5: 采用5年滚动分位+同比/环比双阈值；数据滞后超过一个频率周期时自动降权。 | O5: 同步 | P5: =ROUND(SUMPRODUCT(F10:F13,G10:G13)/SUM(F10:F13),1) -> 7.2
A6: 2-商品房销售面积增速 | B6: 国家统计局 | C6: -5.2 | D6: %YoY | E6: 下行 | F6: 0.1021 | G6: 4 | H6: >5%=10分,0-5%=8分,-5-0%=6分,-10--5%=4分,<-10%=2分 | I6: 30% | J6: 销售低迷，新增需求不足 | K6: 月度 | L6: 0.12 | M6: 目标组权重 40%；按同组相对重要性归一化。 | N6: 采用5年滚动分位+同比/环比双阈值；数据滞后超过一个频率周期时自动降权。 | O6: 滞后 | P6: =ROUND(SUMPRODUCT(F15:F17,G15:G17)/SUM(F15:F17),1) -> 7.4
A7: 3-铜/钢等原材料价格 | B7: LME/上海期货 | C7: -2.5 | D7: %YoY | E7: 下行 | F7: 0.0851 | G7: 8 | H7: <-5%=10分,-5-0%=8分,0-5%=6分,5-10%=4分,>10%=2分 | I7: 45% | J7: 原材料成本下降，利润端改善 | K7: 日度 | L7: 0.1 | M7: 目标组权重 40%；按同组相对重要性归一化。 | N7: 改为5年滚动分位(P20/P40/P60/P80)+3个月动量；须与库存、价差或利润交叉确认。
A8: 4-家电企业排产计划 | B8: 产业在线 | C8: +8 | D8: %YoY | E8: 上行 | F8: 0.0851 | G8: 6 | H8: >15%=10分,5-15%=8分,0-5%=6分,-5-0%=4分,<-5%=2分 | I8: 55% | J8: 排产温和增长，出口订单支撑 | K8: 月度 | L8: 0.1 | M8: 目标组权重 40%；按同组相对重要性归一化。 | N8: 采用5年滚动分位+同比/环比双阈值；数据滞后超过一个频率周期时自动降权。
A9: 【第二部分：同步指标（Coincident Indicators）——与当前景气同步变动】
A10: 5-空调销量增速 | B10: 产业在线 | C10: +12 | D10: %YoY | E10: 上行 | F10: 0.1395 | G10: 8 | H10: >15%=10分,5-15%=8分,0-5%=6分,-5-0%=4分,<-5%=2分 | I10: 62% | J10: 空调销售旺季，出口强劲 | K10: 月度 | L10: 0.15 | M10: 目标组权重 40%；按同组相对重要性归一化。 | N10: 采用季调同比+3个月环比；单月值用3个月移动均值过滤。
A11: 6-冰箱销量增速 | B11: 产业在线 | C11: +6.5 | D11: %YoY | E11: 上行 | F11: 0.093 | G11: 6 | H11: >10%=10分,5-10%=8分,0-5%=6分,-5-0%=4分,<-5%=2分 | I11: 55% | J11: 冰箱销售平稳，更新需求为主 | K11: 月度 | L11: 0.1 | M11: 目标组权重 40%；按同组相对重要性归一化。 | N11: 采用季调同比+3个月环比；单月值用3个月移动均值过滤。
A12: 7-洗衣机销量增速 | B12: 产业在线 | C12: +4.2 | D12: %YoY | E12: 上行 | F12: 0.0744 | G12: 6 | H12: >10%=10分,5-10%=8分,0-5%=6分,-5-0%=4分,<-5%=2分 | I12: 52% | J12: 洗衣机销售温和增长 | K12: 月度 | L12: 0.08 | M12: 目标组权重 40%；按同组相对重要性归一化。 | N12: 采用季调同比+3个月环比；单月值用3个月移动均值过滤。
A13: 8-家电出口金额增速 | B13: 海关总署 | C13: +18.5 | D13: %YoY | E13: 上行 | F13: 0.093 | G13: 8 | H13: >15%=10分,5-15%=8分,0-5%=6分,-5-0%=4分,<-5%=2分 | I13: 70% | J13: 出口高增，海外需求旺盛 | K13: 月度 | L13: 0.1 | M13: 目标组权重 40%；按同组相对重要性归一化。 | N13: 采用5年滚动分位+同比/环比双阈值；数据滞后超过一个频率周期时自动降权。
A14: 【第三部分：滞后指标（Lagging Indicators）——滞后1-2个季度反映景气变化】
A15: 9-家电企业季度净利润率 | B15: 上市公司财报 | C15: 8.5 | D15: % | E15: 上行 | F15: 0.08 | G15: 8 | H15: >10%=10分,7-10%=8分,4-7%=6分,1-4%=4分,<1%=2分 | I15: 60% | J15: Q1净利率改善，成本红利释放 | K15: 季度 | L15: 0.1 | M15: 目标组权重 20%；按同组相对重要性归一化。 | N15: 采用TTM/滚动4季同比+历史分位；剔除一次性损益，IRR按项目现金流复核。
A16: 10-家电行业库存周转天数 | B16: 上市公司财报 | C16: 42 | D16: 天 | E16: 下行 | F16: 0.064 | G16: 8 | H16: <40天=10分,40-50天=8分,50-60天=6分,60-70天=4分,>70天=2分 | I16: 45% | J16: 库存周转加快，运营效率提升 | K16: 季度 | L16: 0.08 | M16: 目标组权重 20%；按同组相对重要性归一化。 | N16: 采用同比、环比、历史分位三维评分；按去库/改善方向计分。
A17: 11-家电零售均价变化 | B17: 奥维云网 | C17: +2.5 | D17: %YoY | E17: 上行 | F17: 0.056 | G17: 6 | H17: >5%=10分,0-5%=8分,-3-0%=6分,-6--3%=4分,<-6%=2分 | I17: 55% | J17: 均价温和上涨，产品结构升级 | K17: 月度 | L17: 0.07 | M17: 目标组权重 20%；按同组相对重要性归一化。 | N17: 改为5年滚动分位(P20/P40/P60/P80)+3个月动量；须与库存、价差或利润交叉确认。
A18: 行业综合景气度加权得分 | G18: =ROUND(SUMPRODUCT(F5:F17,G5:G17),1) -> 6.5 | H18: 综合分=Σ(建议权重×单项评分)，建议权重和=100%。

Sheet 食品饮料
A1: 行业景气度量化跟踪体系（参数优化版）— 食品饮料
A2: 默认阶段框架：防御/成熟｜先行/同步/滞后=30%/45%/25%。同步经营和现金流优先；先行指标只作边际变化确认。｜核心验证：动销、渠道与价格带；必选：经销商库存、终端动销、批价
A3: 指标名称 | B3: 数据来源 | C3: 最新数值 | D3: 单位 | E3: 趋势 | F3: 权重 | G3: 评分 (1-10) | H3: 评分阈值说明 | I3: 历史分位 | J3: 对景气度影响 | K3: 跟踪频率 | L3: 原权重 | M3: 参数优化建议 | N3: 评分口径（更新时采用） | O3: 阶段分项 | P3: 公式分数
A4: 【第一部分：先行指标（Leading Indicators）——提前1-2个季度预示景气变化】 | O4: 先行 | P4: =ROUND(SUMPRODUCT(F5:F8,G5:G8)/SUM(F5:F8),1) -> 5.9
A5: 1-粮食价格变化 | B5: 农业农村部 | C5: +2.8 | D5: %YoY | E5: 上行 | F5: 0.08 | G5: 6 | H5: <3%=10分,3-5%=8分,5-8%=6分,8-10%=4分,>10%=2分 | I5: 55% | J5: 粮价温和上涨，成本端可控 | K5: 月度 | L5: 0.12 | M5: 目标组权重 30%；按同组相对重要性归一化。 | N5: 改为5年滚动分位(P20/P40/P60/P80)+3个月动量；须与库存、价差或利润交叉确认。 | O5: 同步 | P5: =ROUND(SUMPRODUCT(F10:F13,G10:G13)/SUM(F10:F13),1) -> 6.8
A6: 2-包材价格变化 | B6: 生意社 | C6: -4.5 | D6: %YoY | E6: 下行 | F6: 0.0667 | G6: 8 | H6: <-5%=10分,-5-0%=8分,0-5%=6分,5-10%=4分,>10%=2分 | I6: 38% | J6: 包材成本下降，利润端改善 | K6: 月度 | L6: 0.1 | M6: 目标组权重 30%；按同组相对重要性归一化。 | N6: 改为5年滚动分位(P20/P40/P60/P80)+3个月动量；须与库存、价差或利润交叉确认。 | O6: 滞后 | P6: =ROUND(SUMPRODUCT(F15:F17,G15:G17)/SUM(F15:F17),1) -> 7.4
A7: 3-消费者信心指数 | B7: 国家统计局 | C7: 88 | D7: 点 | E7: 下行 | F7: 0.0867 | G7: 4 | H7: >120=10分,110-120=8分,100-110=6分,90-100=4分,<90=2分 | I7: 25% | J7: 信心指数低迷，消费意愿偏弱 | K7: 月度 | L7: 0.13 | M7: 目标组权重 30%；按同组相对重要性归一化。 | N7: 采用5年滚动分位+同比/环比双阈值；数据滞后超过一个频率周期时自动降权。
A8: 4-社会消费品零售总额增速 | B8: 国家统计局 | C8: +5.2 | D8: %YoY | E8: 上行 | F8: 0.0667 | G8: 6 | H8: >8%=10分,5-8%=8分,3-5%=6分,0-3%=4分,<0%=2分 | I8: 48% | J8: 社零温和增长，消费复苏缓慢 | K8: 月度 | L8: 0.1 | M8: 目标组权重 30%；按同组相对重要性归一化。 | N8: 采用季调同比+3个月环比；单月值用3个月移动均值过滤。
A9: 【第二部分：同步指标（Coincident Indicators）——与当前景气同步变动】
A10: 5-白酒批价 | B10: 今日酒价 | C10: 2650 | D10: 元/瓶 | E10: 下行 | F10: 0.1776 | G10: 8 | H10: >2800=10分,2500-2800=8分,2200-2500=6分,2000-2200=4分,<2000=2分 | I10: 65% | J10: 茅台批价坚挺，高端酒需求稳定 | K10: 周度 | L10: 0.15 | M10: 目标组权重 45%；按同组相对重要性归一化。 | N10: 改为5年滚动分位(P20/P40/P60/P80)+3个月动量；须与库存、价差或利润交叉确认。
A11: 6-乳制品产量增速 | B11: 国家统计局 | C11: +3.5 | D11: %YoY | E11: 上行 | F11: 0.0947 | G11: 6 | H11: >5%=10分,2-5%=8分,0-2%=6分,-3-0%=4分,<-3%=2分 | I11: 52% | J11: 乳制品产量温和增长 | K11: 月度 | L11: 0.08 | M11: 目标组权重 45%；按同组相对重要性归一化。 | N11: 采用季调同比+3个月环比；单月值用3个月移动均值过滤。
A12: 7-啤酒产量增速 | B12: 国家统计局 | C12: +1.8 | D12: %YoY | E12: 上行 | F12: 0.0947 | G12: 6 | H12: >5%=10分,2-5%=8分,0-2%=6分,-3-0%=4分,<-3%=2分 | I12: 48% | J12: 啤酒产量平稳，旺季来临 | K12: 月度 | L12: 0.08 | M12: 目标组权重 45%；按同组相对重要性归一化。 | N12: 采用季调同比+3个月环比；单月值用3个月移动均值过滤。
A13: 8-调味品产量增速 | B13: 中国调味品协会 | C13: +2.5 | D13: %YoY | E13: 上行 | F13: 0.0829 | G13: 6 | H13: >5%=10分,2-5%=8分,0-2%=6分,-3-0%=4分,<-3%=2分 | I13: 50% | J13: 调味品产量温和增长 | K13: 月度 | L13: 0.07 | M13: 目标组权重 45%；按同组相对重要性归一化。 | N13: 采用季调同比+3个月环比；单月值用3个月移动均值过滤。
A14: 【第三部分：滞后指标（Lagging Indicators）——滞后1-2个季度反映景气变化】
A15: 9-食品饮料企业季度ROE | B15: 上市公司财报 | C15: 16 | D15: % | E15: 上行 | F15: 0.1 | G15: 8 | H15: >20%=10分,15-20%=8分,10-15%=6分,5-10%=4分,<5%=2分 | I15: 65% | J15: Q1 ROE稳健，盈利能力维持高位 | K15: 季度 | L15: 0.1 | M15: 目标组权重 25%；按同组相对重要性归一化。 | N15: 采用TTM/滚动4季同比+历史分位；剔除一次性损益，IRR按项目现金流复核。
A16: 10-食品饮料行业毛利率 | B16: 上市公司财报 | C16: 48 | D16: % | E16: 上行 | F16: 0.08 | G16: 8 | H16: >50%=10分,40-50%=8分,30-40%=6分,20-30%=4分,<20%=2分 | I16: 62% | J16: 毛利率改善，成本红利释放 | K16: 季度 | L16: 0.08 | M16: 目标组权重 25%；按同组相对重要性归一化。 | N16: 改为5年滚动分位(P20/P40/P60/P80)+3个月动量；须与库存、价差或利润交叉确认。
A17: 11-CPI非食品项同比 | B17: 国家统计局 | C17: +0.8 | D17: % | E17: 上行 | F17: 0.07 | G17: 6 | H17: >2%=10分,1-2%=8分,0-1%=6分,-1-0%=4分,<-1%=2分 | I17: 42% | J17: 非食品通胀温和，终端价格稳定 | K17: 月度 | L17: 0.07 | M17: 目标组权重 25%；按同组相对重要性归一化。 | N17: 采用5年滚动分位+同比/环比双阈值；数据滞后超过一个频率周期时自动降权。
A18: 行业综合景气度加权得分 | G18: =ROUND(SUMPRODUCT(F5:F17,G5:G17),1) -> 6.7 | H18: 综合分=Σ(建议权重×单项评分)，建议权重和=100%。

Sheet 纺织服饰
A1: 行业景气度量化跟踪体系（参数优化版）— 纺织服饰
A2: 默认阶段框架：消费/需求恢复｜先行/同步/滞后=40%/40%/20%。高频需求、渠道库存和价格/利润交叉确认，使用季调数据。｜核心验证：海外库存、订单与汇率；必选：海外零售库存、订单、汇率
A3: 指标名称 | B3: 数据来源 | C3: 最新数值 | D3: 单位 | E3: 趋势 | F3: 权重 | G3: 评分 (1-10) | H3: 评分阈值说明 | I3: 历史分位 | J3: 对景气度影响 | K3: 跟踪频率 | L3: 原权重 | M3: 参数优化建议 | N3: 评分口径（更新时采用） | O3: 阶段分项 | P3: 公式分数
A4: 【第一部分：先行指标（Leading Indicators）——提前1-2个季度预示景气变化】 | O4: 先行 | P4: =ROUND(SUMPRODUCT(F5:F8,G5:G8)/SUM(F5:F8),1) -> 7.6
A5: 1-棉花价格变化 | B5: 郑商所/ICE | C5: -5.2 | D5: %YoY | E5: 下行 | F5: 0.1333 | G5: 8 | H5: <-10%=10分,-10-0%=8分,0-5%=6分,5-10%=4分,>10%=2分 | I5: 42% | J5: 棉价回落，纺企成本压力缓解 | K5: 日度 | L5: 0.15 | M5: 目标组权重 40%；按同组相对重要性归一化。 | N5: 改为5年滚动分位(P20/P40/P60/P80)+3个月动量；须与库存、价差或利润交叉确认。 | O5: 同步 | P5: =ROUND(SUMPRODUCT(F10:F13,G10:G13)/SUM(F10:F13),1) -> 6.7
A6: 2-化纤价格变化 | B6: CCFEI | C6: -3.8 | D6: %YoY | E6: 下行 | F6: 0.1067 | G6: 8 | H6: <-5%=10分,-5-0%=8分,0-5%=6分,5-10%=4分,>10%=2分 | I6: 45% | J6: 化纤价格下行，成本端改善 | K6: 周度 | L6: 0.12 | M6: 目标组权重 40%；按同组相对重要性归一化。 | N6: 改为5年滚动分位(P20/P40/P60/P80)+3个月动量；须与库存、价差或利润交叉确认。 | O6: 滞后 | P6: =ROUND(SUMPRODUCT(F15:F17,G15:G17)/SUM(F15:F17),1) -> 6
A7: 3-美国服装零售库存 | B7: 美国商务部 | C7: -3.5 | D7: %YoY | E7: 去库 | F7: 0.0889 | G7: 8 | H7: <-5%=10分,-5-0%=8分,0-5%=6分,5-10%=4分,>10%=2分 | I7: 38% | J7: 海外去库顺利，订单有望回流 | K7: 月度 | L7: 0.1 | M7: 目标组权重 40%；按同组相对重要性归一化。 | N7: 采用同比、环比、历史分位三维评分；按去库/改善方向计分。
A8: 4-人民币汇率 | B8: 中国外汇交易中心 | C8: 7.18 | E8: 贬值 | F8: 0.0711 | G8: 6 | H8: 升值>3%=10分,升值0-3%=8分,持平=6分,贬值0-3%=4分,贬值>3%=2分 | I8: 55% | J8: 汇率小幅贬值，利好出口竞争力 | K8: 日度 | L8: 0.08 | M8: 目标组权重 40%；按同组相对重要性归一化。 | N8: 采用5年滚动分位+同比/环比双阈值；数据滞后超过一个频率周期时自动降权。
A9: 【第二部分：同步指标（Coincident Indicators）——与当前景气同步变动】
A10: 5-纺织品出口金额增速 | B10: 海关总署 | C10: +8.5 | D10: %YoY | E10: 上行 | F10: 0.1333 | G10: 8 | H10: >10%=10分,5-10%=8分,0-5%=6分,-5-0%=4分,<-5%=2分 | I10: 58% | J10: 纺织品出口回暖，外需改善 | K10: 月度 | L10: 0.15 | M10: 目标组权重 40%；按同组相对重要性归一化。 | N10: 采用5年滚动分位+同比/环比双阈值；数据滞后超过一个频率周期时自动降权。
A11: 6-服装出口金额增速 | B11: 海关总署 | C11: +6.2 | D11: %YoY | E11: 上行 | F11: 0.1067 | G11: 6 | H11: >10%=10分,5-10%=8分,0-5%=6分,-5-0%=4分,<-5%=2分 | I11: 55% | J11: 服装出口温和增长 | K11: 月度 | L11: 0.12 | M11: 目标组权重 40%；按同组相对重要性归一化。 | N11: 采用5年滚动分位+同比/环比双阈值；数据滞后超过一个频率周期时自动降权。
A12: 7-柯桥纺织价格指数 | B12: 柯桥指数 | C12: 104 | D12: 点 | E12: 上行 | F12: 0.0889 | G12: 6 | H12: >105=10分,102-105=8分,100-102=6分,98-100=4分,<98=2分 | I12: 58% | J12: 价格指数温和回升 | K12: 周度 | L12: 0.1 | M12: 目标组权重 40%；按同组相对重要性归一化。 | N12: 改为5年滚动分位(P20/P40/P60/P80)+3个月动量；须与库存、价差或利润交叉确认。
A13: 8-纺服企业开工率 | B13: 中国纺织工业联合会 | C13: 78 | D13: % | E13: 上行 | F13: 0.0711 | G13: 6 | H13: >85%=10分,80-85%=8分,75-80%=6分,70-75%=4分,<70%=2分 | I13: 52% | J13: 开工率回升，订单边际改善 | K13: 月度 | L13: 0.08 | M13: 目标组权重 40%；按同组相对重要性归一化。 | N13: 采用5年滚动分位+同比/环比双阈值；数据滞后超过一个频率周期时自动降权。
A14: 【第三部分：滞后指标（Lagging Indicators）——滞后1-2个季度反映景气变化】
A15: 9-纺服企业季度净利润率 | B15: 上市公司财报 | C15: 5.5 | D15: % | E15: 上行 | F15: 0.08 | G15: 6 | H15: >8%=10分,5-8%=8分,3-5%=6分,0-3%=4分,<0%=2分 | I15: 50% | J15: Q1利润率改善，成本红利释放 | K15: 季度 | L15: 0.1 | M15: 目标组权重 20%；按同组相对重要性归一化。 | N15: 采用TTM/滚动4季同比+历史分位；剔除一次性损益，IRR按项目现金流复核。
A16: 10-纺服行业库存周转天数 | B16: 上市公司财报 | C16: 68 | D16: 天 | E16: 下行 | F16: 0.064 | G16: 6 | H16: <60天=10分,60-75天=8分,75-90天=6分,90-105天=4分,>105天=2分 | I16: 48% | J16: 库存周转加快，运营效率提升 | K16: 季度 | L16: 0.08 | M16: 目标组权重 20%；按同组相对重要性归一化。 | N16: 采用同比、环比、历史分位三维评分；按去库/改善方向计分。
A17: 11-社会消费品零售-服装类 | B17: 国家统计局 | C17: +3.8 | D17: %YoY | E17: 上行 | F17: 0.056 | G17: 6 | H17: >10%=10分,5-10%=8分,0-5%=6分,-5-0%=4分,<-5%=2分 | I17: 48% | J17: 服装零售温和增长 | K17: 月度 | L17: 0.07 | M17: 目标组权重 20%；按同组相对重要性归一化。 | N17: 采用季调同比+3个月环比；单月值用3个月移动均值过滤。
A18: 行业综合景气度加权得分 | G18: =ROUND(SUMPRODUCT(F5:F17,G5:G17),1) -> 6.9 | H18: 综合分=Σ(建议权重×单项评分)，建议权重和=100%。

Sheet 轻工制造
A1: 行业景气度量化跟踪体系（参数优化版）— 轻工制造
A2: 默认阶段框架：消费/需求恢复｜先行/同步/滞后=40%/40%/20%。高频需求、渠道库存和价格/利润交叉确认，使用季调数据。｜核心验证：地产后周期/出口与价差；必选：竣工、海外地产、原料与产品价差
A3: 指标名称 | B3: 数据来源 | C3: 最新数值 | D3: 单位 | E3: 趋势 | F3: 权重 | G3: 评分 (1-10) | H3: 评分阈值说明 | I3: 历史分位 | J3: 对景气度影响 | K3: 跟踪频率 | L3: 原权重 | M3: 参数优化建议 | N3: 评分口径（更新时采用） | O3: 阶段分项 | P3: 公式分数
A4: 【第一部分：先行指标（Leading Indicators）——提前1-2个季度预示景气变化】 | O4: 先行 | P4: =ROUND(SUMPRODUCT(F5:F8,G5:G8)/SUM(F5:F8),1) -> 6.6
A5: 1-纸浆价格变化 | B5: 针叶浆/阔叶浆 | C5: -8.5 | D5: %YoY | E5: 下行 | F5: 0.1333 | G5: 8 | H5: <-10%=10分,-10-0%=8分,0-5%=6分,5-10%=4分,>10%=2分 | I5: 35% | J5: 纸浆价格回落，造纸成本改善 | K5: 周度 | L5: 0.15 | M5: 目标组权重 40%；按同组相对重要性归一化。 | N5: 改为5年滚动分位(P20/P40/P60/P80)+3个月动量；须与库存、价差或利润交叉确认。 | O5: 同步 | P5: =ROUND(SUMPRODUCT(F10:F13,G10:G13)/SUM(F10:F13),1) -> 5
A6: 2-木材价格变化 | B6: 木材指数 | C6: -2.5 | D6: %YoY | E6: 下行 | F6: 0.0889 | G6: 8 | H6: <-5%=10分,-5-0%=8分,0-5%=6分,5-10%=4分,>10%=2分 | I6: 42% | J6: 木材价格下行，家具成本下降 | K6: 月度 | L6: 0.1 | M6: 目标组权重 40%；按同组相对重要性归一化。 | N6: 改为5年滚动分位(P20/P40/P60/P80)+3个月动量；须与库存、价差或利润交叉确认。 | O6: 滞后 | P6: =ROUND(SUMPRODUCT(F15:F17,G15:G17)/SUM(F15:F17),1) -> 6
A7: 3-房地产竣工面积增速 | B7: 国家统计局 | C7: -8.5 | D7: %YoY | E7: 下行 | F7: 0.1067 | G7: 4 | H7: >10%=10分,5-10%=8分,0-5%=6分,-5-0%=4分,<-5%=2分 | I7: 25% | J7: 竣工下滑，后周期需求承压 | K7: 月度 | L7: 0.12 | M7: 目标组权重 40%；按同组相对重要性归一化。 | N7: 采用5年滚动分位+同比/环比双阈值；数据滞后超过一个频率周期时自动降权。
A8: 4-美国新房销售 | B8: 美国商务部 | C8: +2.5 | D8: %YoY | E8: 上行 | F8: 0.0711 | G8: 6 | H8: >5%=10分,0-5%=8分,-5-0%=6分,-10--5%=4分,<-10%=2分 | I8: 52% | J8: 美国房市回暖，出口订单有望改善 | K8: 月度 | L8: 0.08 | M8: 目标组权重 40%；按同组相对重要性归一化。 | N8: 采用5年滚动分位+同比/环比双阈值；数据滞后超过一个频率周期时自动降权。
A9: 【第二部分：同步指标（Coincident Indicators）——与当前景气同步变动】
A10: 5-瓦楞纸价格 | B10: 卓创资讯 | C10: 2800 | D10: 元/吨 | E10: 下行 | F10: 0.1143 | G10: 4 | H10: >3500=10分,3200-3500=8分,2900-3200=6分,2600-2900=4分,<2600=2分 | I10: 32% | J10: 瓦楞纸价格低迷，包装需求偏弱 | K10: 周度 | L10: 0.12 | M10: 目标组权重 40%；按同组相对重要性归一化。 | N10: 改为5年滚动分位(P20/P40/P60/P80)+3个月动量；须与库存、价差或利润交叉确认。
A11: 6-双胶纸价格 | B11: 卓创资讯 | C11: 5200 | D11: 元/吨 | E11: 下行 | F11: 0.0952 | G11: 4 | H11: >6000=10分,5500-6000=8分,5000-5500=6分,4500-5000=4分,<4500=2分 | I11: 38% | J11: 文化纸价格承压，出版需求平淡 | K11: 周度 | L11: 0.1 | M11: 目标组权重 40%；按同组相对重要性归一化。 | N11: 改为5年滚动分位(P20/P40/P60/P80)+3个月动量；须与库存、价差或利润交叉确认。
A12: 7-家具零售额增速 | B12: 国家统计局 | C12: +1.5 | D12: %YoY | E12: 上行 | F12: 0.1143 | G12: 6 | H12: >10%=10分,5-10%=8分,0-5%=6分,-5-0%=4分,<-5%=2分 | I12: 45% | J12: 家具零售温和增长，更新需求为主 | K12: 月度 | L12: 0.12 | M12: 目标组权重 40%；按同组相对重要性归一化。 | N12: 采用季调同比+3个月环比；单月值用3个月移动均值过滤。
A13: 8-造纸企业开工率 | B13: 卓创资讯 | C13: 72 | D13: % | E13: 上行 | F13: 0.0762 | G13: 6 | H13: >80%=10分,75-80%=8分,70-75%=6分,65-70%=4分,<65%=2分 | I13: 48% | J13: 开工率回升，供需边际改善 | K13: 月度 | L13: 0.08 | M13: 目标组权重 40%；按同组相对重要性归一化。 | N13: 采用5年滚动分位+同比/环比双阈值；数据滞后超过一个频率周期时自动降权。
A14: 【第三部分：滞后指标（Lagging Indicators）——滞后1-2个季度反映景气变化】
A15: 9-轻工企业季度ROE | B15: 上市公司财报 | C15: 7.5 | D15: % | E15: 上行 | F15: 0.08 | G15: 6 | H15: >12%=10分,8-12%=8分,4-8%=6分,0-4%=4分,<0%=2分 | I15: 48% | J15: Q1 ROE改善，盈利能力修复 | K15: 季度 | L15: 0.1 | M15: 目标组权重 20%；按同组相对重要性归一化。 | N15: 采用TTM/滚动4季同比+历史分位；剔除一次性损益，IRR按项目现金流复核。
A16: 10-轻工行业库存周转天数 | B16: 上市公司财报 | C16: 58 | D16: 天 | E16: 下行 | F16: 0.064 | G16: 6 | H16: <50天=10分,50-65天=8分,65-80天=6分,80-95天=4分,>95天=2分 | I16: 45% | J16: 库存周转加快，运营效率提升 | K16: 季度 | L16: 0.08 | M16: 目标组权重 20%；按同组相对重要性归一化。 | N16: 采用同比、环比、历史分位三维评分；按去库/改善方向计分。
A17: 11-轻工行业固定资产投资 | B17: 国家统计局 | C17: +6.5 | D17: %YoY | E17: 上行 | F17: 0.056 | G17: 6 | H17: >10%=10分,5-10%=8分,0-5%=6分,-5-0%=4分,<-5%=2分 | I17: 52% | J17: 投资温和增长，产能扩张谨慎 | K17: 季度 | L17: 0.07 | M17: 目标组权重 20%；按同组相对重要性归一化。 | N17: 采用5年滚动分位+同比/环比双阈值；数据滞后超过一个频率周期时自动降权。
A18: 行业综合景气度加权得分 | G18: =ROUND(SUMPRODUCT(F5:F17,G5:G17),1) -> 5.8 | H18: 综合分=Σ(建议权重×单项评分)，建议权重和=100%。

Sheet 医药生物
A1: 行业景气度量化跟踪体系（参数优化版）— 医药生物
A2: 默认阶段框架：科技制造/订单库存周期｜先行/同步/滞后=50%/35%/15%。订单、库存和利用率优先；不同子行业拆分后再汇总。｜核心验证：创新、诊疗与政策支付；必选：IND/注册、医保政策、研发融资
A3: 指标名称 | B3: 数据来源 | C3: 最新数值 | D3: 单位 | E3: 趋势 | F3: 权重 | G3: 评分 (1-10) | H3: 评分阈值说明 | I3: 历史分位 | J3: 对景气度影响 | K3: 跟踪频率 | L3: 原权重 | M3: 参数优化建议 | N3: 评分口径（更新时采用） | O3: 阶段分项 | P3: 公式分数
A4: 【第一部分：先行指标（Leading Indicators）——提前1-2个季度预示景气变化】 | O4: 先行 | P4: =ROUND(SUMPRODUCT(F5:F8,G5:G8)/SUM(F5:F8),1) -> 8
A5: 1-创新药IND数量 | B5: CDE | C5: 185 | D5: 个/月 | E5: 上行 | F5: 0.1667 | G5: 8 | H5: >200=10分,150-200=8分,100-150=6分,50-100=4分,<50=2分 | I5: 72% | J5: 创新药申报活跃，研发管线丰富 | K5: 月度 | L5: 0.15 | M5: 目标组权重 50%；按同组相对重要性归一化。 | N5: 采用5年滚动分位+同比/环比双阈值；数据滞后超过一个频率周期时自动降权。 | O5: 同步 | P5: =ROUND(SUMPRODUCT(F10:F13,G10:G13)/SUM(F10:F13),1) -> 7.2
A6: 2-医保谈判降价幅度 | B6: 国家医保局 | C6: 45 | D6: % | E6: 温和 | F6: 0.1111 | G6: 8 | H6: <40%=10分,40-50%=8分,50-60%=6分,60-70%=4分,>70%=2分 | I6: 55% | J6: 降价幅度可控，创新药定价环境改善 | K6: 年度 | L6: 0.1 | M6: 目标组权重 50%；按同组相对重要性归一化。 | N6: 采用5年滚动分位+同比/环比双阈值；数据滞后超过一个频率周期时自动降权。 | O6: 滞后 | P6: =ROUND(SUMPRODUCT(F15:F17,G15:G17)/SUM(F15:F17),1) -> 8
A7: 3-原料药价格变化 | B7: 健康网 | C7: -2.5 | D7: %YoY | E7: 下行 | F7: 0.1111 | G7: 8 | H7: <-5%=10分,-5-0%=8分,0-5%=6分,5-10%=4分,>10%=2分 | I7: 42% | J7: 原料药价格回落，制剂成本改善 | K7: 月度 | L7: 0.1 | M7: 目标组权重 50%；按同组相对重要性归一化。 | N7: 改为5年滚动分位(P20/P40/P60/P80)+3个月动量；须与库存、价差或利润交叉确认。
A8: 4-全球生物医药融资额 | B8: PitchBook | C8: +15 | D8: %YoY | E8: 上行 | F8: 0.1111 | G8: 8 | H8: >20%=10分,10-20%=8分,0-10%=6分,-10-0%=4分,<-10%=2分 | I8: 60% | J8: 融资回暖，创新药估值修复 | K8: 季度 | L8: 0.1 | M8: 目标组权重 50%；按同组相对重要性归一化。 | N8: 滚动3M/4Q同比；以交付、收入或现金流确认，政策/规划单项权重≤8%。
A9: 【第二部分：同步指标（Coincident Indicators）——与当前景气同步变动】
A10: 5-医药制造业收入增速 | B10: 国家统计局 | C10: +8.5 | D10: %YoY | E10: 上行 | F10: 0.1105 | G10: 8 | H10: >10%=10分,5-10%=8分,0-5%=6分,-5-0%=4分,<-5%=2分 | I10: 62% | J10: 制造业收入稳健增长 | K10: 月度 | L10: 0.12 | M10: 目标组权重 35%；按同组相对重要性归一化。 | N10: 采用季调同比+3个月环比；单月值用3个月移动均值过滤。
A11: 6-化学药品原药产量 | B11: 国家统计局 | C11: +4.2 | D11: %YoY | E11: 上行 | F11: 0.0737 | G11: 6 | H11: >5%=10分,2-5%=8分,0-2%=6分,-3-0%=4分,<-3%=2分 | I11: 55% | J11: 原料药产量温和增长 | K11: 月度 | L11: 0.08 | M11: 目标组权重 35%；按同组相对重要性归一化。 | N11: 采用季调同比+3个月环比；单月值用3个月移动均值过滤。
A12: 7-医疗器械出口增速 | B12: 海关总署 | C12: +18.5 | D12: %YoY | E12: 上行 | F12: 0.0921 | G12: 8 | H12: >15%=10分,5-15%=8分,0-5%=6分,-5-0%=4分,<-5%=2分 | I12: 70% | J12: 器械出口强劲，海外需求旺盛 | K12: 月度 | L12: 0.1 | M12: 目标组权重 35%；按同组相对重要性归一化。 | N12: 采用5年滚动分位+同比/环比双阈值；数据滞后超过一个频率周期时自动降权。
A13: 8-医院诊疗人次增速 | B13: 国家卫健委 | C13: +6.5 | D13: %YoY | E13: 上行 | F13: 0.0737 | G13: 6 | H13: >10%=10分,5-10%=8分,0-5%=6分,-5-0%=4分,<-5%=2分 | I13: 58% | J13: 诊疗人次恢复，院内需求回暖 | K13: 月度 | L13: 0.08 | M13: 目标组权重 35%；按同组相对重要性归一化。 | N13: 采用5年滚动分位+同比/环比双阈值；数据滞后超过一个频率周期时自动降权。
A14: 【第三部分：滞后指标（Lagging Indicators）——滞后1-2个季度反映景气变化】
A15: 9-医药企业季度毛利率 | B15: 上市公司财报 | C15: 55 | D15: % | E15: 上行 | F15: 0.06 | G15: 8 | H15: >60%=10分,50-60%=8分,40-50%=6分,30-40%=4分,<30%=2分 | I15: 65% | J15: Q1毛利率稳健，产品结构优化 | K15: 季度 | L15: 0.1 | M15: 目标组权重 15%；按同组相对重要性归一化。 | N15: 改为5年滚动分位(P20/P40/P60/P80)+3个月动量；须与库存、价差或利润交叉确认。
A16: 10-医药企业研发费用率 | B16: 上市公司财报 | C16: 12 | D16: % | E16: 上行 | F16: 0.048 | G16: 8 | H16: >15%=10分,10-15%=8分,5-10%=6分,2-5%=4分,<2%=2分 | I16: 60% | J16: 研发投入维持高位，创新转型加速 | K16: 季度 | L16: 0.08 | M16: 目标组权重 15%；按同组相对重要性归一化。 | N16: 采用5年滚动分位+同比/环比双阈值；数据滞后超过一个频率周期时自动降权。
A17: 11-医药制造业利润增速 | B17: 国家统计局 | C17: +12 | D17: %YoY | E17: 上行 | F17: 0.042 | G17: 8 | H17: >15%=10分,5-15%=8分,0-5%=6分,-5-0%=4分,<-5%=2分 | I17: 65% | J17: 利润增速回升，盈利能力改善 | K17: 月度 | L17: 0.07 | M17: 目标组权重 15%；按同组相对重要性归一化。 | N17: 采用TTM/滚动4季同比+历史分位；剔除一次性损益，IRR按项目现金流复核。
A18: 行业综合景气度加权得分 | G18: =ROUND(SUMPRODUCT(F5:F17,G5:G17),1) -> 7.7 | H18: 综合分=Σ(建议权重×单项评分)，建议权重和=100%。

Sheet 公用事业
A1: 行业景气度量化跟踪体系（参数优化版）— 公用事业
A2: 默认阶段框架：防御/成熟｜先行/同步/滞后=30%/45%/25%。同步经营和现金流优先；先行指标只作边际变化确认。｜核心验证：利用小时、燃料传导与资本回报；必选：来水、燃料、电价机制、装机进度
A3: 指标名称 | B3: 数据来源 | C3: 最新数值 | D3: 单位 | E3: 趋势 | F3: 权重 | G3: 评分 (1-10) | H3: 评分阈值说明 | I3: 历史分位 | J3: 对景气度影响 | K3: 跟踪频率 | L3: 原权重 | M3: 参数优化建议 | N3: 评分口径（更新时采用） | O3: 阶段分项 | P3: 公式分数
A4: 【第一部分：先行指标（Leading Indicators）——提前1-2个季度预示景气变化】 | O4: 先行 | P4: =ROUND(SUMPRODUCT(F5:F8,G5:G8)/SUM(F5:F8),1) -> 9
A5: 1-动力煤价格变化 | B5: 秦皇岛动力煤 | C5: -12 | D5: %YoY | E5: 下行 | F5: 0.1 | G5: 10 | H5: <-10%=10分,-10-0%=8分,0-5%=6分,5-10%=4分,>10%=2分 | I5: 28% | J5: 煤价大幅回落，火电成本显著改善 | K5: 周度 | L5: 0.15 | M5: 目标组权重 30%；按同组相对重要性归一化。 | N5: 改为5年滚动分位(P20/P40/P60/P80)+3个月动量；须与库存、价差或利润交叉确认。 | O5: 同步 | P5: =ROUND(SUMPRODUCT(F10:F13,G10:G13)/SUM(F10:F13),1) -> 7.1
A6: 2-天然气进口价格 | B6: 海关总署 | C6: -5.5 | D6: %YoY | E6: 下行 | F6: 0.08 | G6: 8 | H6: <-5%=10分,-5-0%=8分,0-5%=6分,5-10%=4分,>10%=2分 | I6: 38% | J6: 气价回落，燃气发电成本下降 | K6: 月度 | L6: 0.12 | M6: 目标组权重 30%；按同组相对重要性归一化。 | N6: 改为5年滚动分位(P20/P40/P60/P80)+3个月动量；须与库存、价差或利润交叉确认。 | O6: 滞后 | P6: =ROUND(SUMPRODUCT(F15:F17,G15:G17)/SUM(F15:F17),1) -> 8
A7: 3-来水情况(三峡出库流量) | B7: 长江水利委员会 | C7: 18500 | D7: m³/s | E7: 充沛 | F7: 0.0667 | G7: 8 | H7: >20000=10分,15000-20000=8分,10000-15000=6分,5000-10000=4分,<5000=2分 | I7: 72% | J7: 来水充沛，水电出力提升 | K7: 日度 | L7: 0.1 | M7: 目标组权重 30%；按同组相对重要性归一化。 | N7: 采用5年滚动分位+同比/环比双阈值；数据滞后超过一个频率周期时自动降权。
A8: 4-新能源装机规划 | B8: 国家能源局 | C8: 120 | D8: GW | E8: 高增 | F8: 0.0533 | G8: 10 | H8: >100=10分,70-100=8分,50-70=6分,30-50%=4分,<30=2分 | I8: 85% | J8: 新能源装机规划创新高，绿电转型加速 | K8: 年度 | L8: 0.08 | M8: 目标组权重 30%；按同组相对重要性归一化。 | N8: 滚动3M/4Q同比；以交付、收入或现金流确认，政策/规划单项权重≤8%。
A9: 【第二部分：同步指标（Coincident Indicators）——与当前景气同步变动】
A10: 5-全社会用电量增速 | B10: 国家能源局 | C10: +7.5 | D10: %YoY | E10: 上行 | F10: 0.1646 | G10: 8 | H10: >8%=10分,5-8%=8分,3-5%=6分,0-3%=4分,<0%=2分 | I10: 62% | J10: 用电量稳健增长，经济活力回升 | K10: 月度 | L10: 0.15 | M10: 目标组权重 45%；按同组相对重要性归一化。 | N10: 采用5年滚动分位+同比/环比双阈值；数据滞后超过一个频率周期时自动降权。
A11: 6-火电利用小时数 | B11: 国家能源局 | C11: 1180 | D11: 小时(累计) | E11: 上行 | F11: 0.1098 | G11: 6 | H11: >4200年化=10分,4000-4200=8分,3800-4000=6分,3600-3800=4分,<3600=2分 | I11: 55% | J11: 火电利用小时回升，煤电需求改善 | K11: 月度 | L11: 0.1 | M11: 目标组权重 45%；按同组相对重要性归一化。 | N11: 采用5年滚动分位+同比/环比双阈值；数据滞后超过一个频率周期时自动降权。
A12: 7-水电利用小时数 | B12: 国家能源局 | C12: 980 | D12: 小时(累计) | E12: 上行 | F12: 0.0878 | G12: 8 | H12: >3800年化=10分,3500-3800=8分,3200-3500=6分,2900-3200=4分,<2900=2分 | I12: 70% | J12: 水电利用小时高增，来水偏丰 | K12: 月度 | L12: 0.08 | M12: 目标组权重 45%；按同组相对重要性归一化。 | N12: 采用5年滚动分位+同比/环比双阈值；数据滞后超过一个频率周期时自动降权。
A13: 8-风电/光伏利用小时数 | B13: 国家能源局 | C13: +5 | D13: %vs均值 | E13: 上行 | F13: 0.0878 | G13: 6 | H13: >均值10%=10分,0-10%=8分,-10-0%=6分,-20--10%=4分,<-20%=2分 | I13: 58% | J13: 新能源利用小时改善，消纳好转 | K13: 月度 | L13: 0.08 | M13: 目标组权重 45%；按同组相对重要性归一化。 | N13: 采用5年滚动分位+同比/环比双阈值；数据滞后超过一个频率周期时自动降权。
A14: 【第三部分：滞后指标（Lagging Indicators）——滞后1-2个季度反映景气变化】
A15: 9-电力企业季度ROE | B15: 上市公司财报 | C15: 8.5 | D15: % | E15: 上行 | F15: 0.1 | G15: 8 | H15: >10%=10分,7-10%=8分,4-7%=6分,1-4%=4分,<1%=2分 | I15: 60% | J15: Q1 ROE改善，煤价红利释放 | K15: 季度 | L15: 0.1 | M15: 目标组权重 25%；按同组相对重要性归一化。 | N15: 采用TTM/滚动4季同比+历史分位；剔除一次性损益，IRR按项目现金流复核。
A16: 10-电力行业资产负债率 | B16: 上市公司财报 | C16: 62 | D16: % | E16: 下行 | F16: 0.08 | G16: 8 | H16: <60%=10分,60-65%=8分,65-70%=6分,70-75%=4分,>75%=2分 | I16: 45% | J16: 负债率下降，财务结构优化 | K16: 季度 | L16: 0.08 | M16: 目标组权重 25%；按同组相对重要性归一化。 | N16: 采用同比、环比、历史分位三维评分；按去库/改善方向计分。
A17: 11-电力行业固定资产投资 | B17: 国家统计局 | C17: +18 | D17: %YoY | E17: 上行 | F17: 0.07 | G17: 8 | H17: >15%=10分,5-15%=8分,0-5%=6分,-5-0%=4分,<-5%=2分 | I17: 72% | J17: 投资高增，电网/新能源建设加速 | K17: 季度 | L17: 0.07 | M17: 目标组权重 25%；按同组相对重要性归一化。 | N17: 采用5年滚动分位+同比/环比双阈值；数据滞后超过一个频率周期时自动降权。
A18: 行业综合景气度加权得分 | G18: =ROUND(SUMPRODUCT(F5:F17,G5:G17),1) -> 7.9 | H18: 综合分=Σ(建议权重×单项评分)，建议权重和=100%。

Sheet 交通运输
A1: 行业景气度量化跟踪体系（参数优化版）— 交通运输
A2: 默认阶段框架：消费/需求恢复｜先行/同步/滞后=40%/40%/20%。高频需求、渠道库存和价格/利润交叉确认，使用季调数据。｜核心验证：运价、运量与供给；必选：运力投放、运价、油价
A3: 指标名称 | B3: 数据来源 | C3: 最新数值 | D3: 单位 | E3: 趋势 | F3: 权重 | G3: 评分 (1-10) | H3: 评分阈值说明 | I3: 历史分位 | J3: 对景气度影响 | K3: 跟踪频率 | L3: 原权重 | M3: 参数优化建议 | N3: 评分口径（更新时采用） | O3: 阶段分项 | P3: 公式分数
A4: 【第一部分：先行指标（Leading Indicators）——提前1-2个季度预示景气变化】 | O4: 先行 | P4: =ROUND(SUMPRODUCT(F5:F8,G5:G8)/SUM(F5:F8),1) -> 8
A5: 1-BDI指数 | B5: 波罗的海交易所 | C5: 1850 | D5: 点 | E5: 上行 | F5: 0.1333 | G5: 8 | H5: >2000=10分,1500-2000=8分,1000-1500=6分,500-1000=4分,<500=2分 | I5: 68% | J5: 干散货运价回升，大宗商品贸易活跃 | K5: 日度 | L5: 0.15 | M5: 目标组权重 40%；按同组相对重要性归一化。 | N5: 采用5年滚动分位+同比/环比双阈值；数据滞后超过一个频率周期时自动降权。 | O5: 同步 | P5: =ROUND(SUMPRODUCT(F10:F13,G10:G13)/SUM(F10:F13),1) -> 8
A6: 2-原油运输指数(BDTI) | B6: 波罗的海交易所 | C6: 1150 | D6: 点 | E6: 上行 | F6: 0.0889 | G6: 8 | H6: >1200=10分,900-1200=8分,600-900=6分,400-600=4分,<400=2分 | I6: 65% | J6: 油运运价高位，红海绕行支撑 | K6: 日度 | L6: 0.1 | M6: 目标组权重 40%；按同组相对重要性归一化。 | N6: 采用5年滚动分位+同比/环比双阈值；数据滞后超过一个频率周期时自动降权。 | O6: 滞后 | P6: =ROUND(SUMPRODUCT(F15:F17,G15:G17)/SUM(F15:F17),1) -> 8
A7: 3-集装箱运价指数(CCFI) | B7: 上海航运交易所 | C7: 1250 | D7: 点 | E7: 上行 | F7: 0.1067 | G7: 8 | H7: >1200=10分,1000-1200=8分,800-1000=6分,600-800=4分,<600=2分 | I7: 62% | J7: 集运运价回升，出口需求强劲 | K7: 周度 | L7: 0.12 | M7: 目标组权重 40%；按同组相对重要性归一化。 | N7: 采用5年滚动分位+同比/环比双阈值；数据滞后超过一个频率周期时自动降权。
A8: 4-航空煤油价格 | B8: IATA | C8: -8.5 | D8: %YoY | E8: 下行 | F8: 0.0711 | G8: 8 | H8: <-10%=10分,-10-0%=8分,0-5%=6分,5-10%=4分,>10%=2分 | I8: 35% | J8: 航油价格回落，航空成本改善 | K8: 月度 | L8: 0.08 | M8: 目标组权重 40%；按同组相对重要性归一化。 | N8: 改为5年滚动分位(P20/P40/P60/P80)+3个月动量；须与库存、价差或利润交叉确认。
A9: 【第二部分：同步指标（Coincident Indicators）——与当前景气同步变动】
A10: 5-港口货物吞吐量增速 | B10: 交通运输部 | C10: +5.5 | D10: %YoY | E10: 上行 | F10: 0.12 | G10: 8 | H10: >5%=10分,3-5%=8分,0-3%=6分,-3-0%=4分,<-3%=2分 | I10: 58% | J10: 港口吞吐量增长，贸易活动活跃 | K10: 月度 | L10: 0.12 | M10: 目标组权重 40%；按同组相对重要性归一化。 | N10: 采用季调同比+3个月环比；单月值用3个月移动均值过滤。
A11: 6-民航客运量增速 | B11: 民航局 | C11: +16.5 | D11: %YoY | E11: 上行 | F11: 0.12 | G11: 8 | H11: >15%=10分,10-15%=8分,5-10%=6分,0-5%=4分,<0%=2分 | I11: 70% | J11: 民航客运强劲恢复，出行需求旺盛 | K11: 月度 | L11: 0.12 | M11: 目标组权重 40%；按同组相对重要性归一化。 | N11: 采用季调同比+3个月环比；单月值用3个月移动均值过滤。
A12: 7-铁路货运量增速 | B12: 国铁集团 | C12: +4.5 | D12: %YoY | E12: 上行 | F12: 0.08 | G12: 6 | H12: >5%=10分,3-5%=8分,0-3%=6分,-3-0%=4分,<-3%=2分 | I12: 55% | J12: 铁路货运平稳增长 | K12: 月度 | L12: 0.08 | M12: 目标组权重 40%；按同组相对重要性归一化。 | N12: 采用季调同比+3个月环比；单月值用3个月移动均值过滤。
A13: 8-快递业务量增速 | B13: 国家邮政局 | C13: +22 | D13: %YoY | E13: 上行 | F13: 0.08 | G13: 10 | H13: >20%=10分,15-20%=8分,10-15%=6分,5-10%=4分,<5%=2分 | I13: 75% | J13: 快递业务量高增，电商消费活跃 | K13: 月度 | L13: 0.08 | M13: 目标组权重 40%；按同组相对重要性归一化。 | N13: 采用季调同比+3个月环比；单月值用3个月移动均值过滤。
A14: 【第三部分：滞后指标（Lagging Indicators）——滞后1-2个季度反映景气变化】
A15: 9-交运企业季度净利润 | B15: 上市公司财报 | C15: 85 | D15: 亿元 | E15: 上行 | F15: 0.08 | G15: 8 | H15: >50亿=10分,20-50亿=8分,0-20亿=6分,-20-0亿=4分,<-20亿=2分 | I15: 68% | J15: Q1净利润改善，油运/航空贡献 | K15: 季度 | L15: 0.1 | M15: 目标组权重 20%；按同组相对重要性归一化。 | N15: 采用TTM/滚动4季同比+历史分位；剔除一次性损益，IRR按项目现金流复核。
A16: 10-交运行业资产负债率 | B16: 上市公司财报 | C16: 58 | D16: % | E16: 下行 | F16: 0.064 | G16: 8 | H16: <55%=10分,55-60%=8分,60-65%=6分,65-70%=4分,>70%=2分 | I16: 48% | J16: 负债率下降，财务结构优化 | K16: 季度 | L16: 0.08 | M16: 目标组权重 20%；按同组相对重要性归一化。 | N16: 采用同比、环比、历史分位三维评分；按去库/改善方向计分。
A17: 11-交运行业固定资产投资 | B17: 国家统计局 | C17: +8.5 | D17: %YoY | E17: 上行 | F17: 0.056 | G17: 8 | H17: >10%=10分,5-10%=8分,0-5%=6分,-5-0%=4分,<-5%=2分 | I17: 58% | J17: 投资温和增长，基础设施完善 | K17: 季度 | L17: 0.07 | M17: 目标组权重 20%；按同组相对重要性归一化。 | N17: 采用5年滚动分位+同比/环比双阈值；数据滞后超过一个频率周期时自动降权。
A18: 行业综合景气度加权得分 | G18: =ROUND(SUMPRODUCT(F5:F17,G5:G17),1) -> 8 | H18: 综合分=Σ(建议权重×单项评分)，建议权重和=100%。

Sheet 房地产
A1: 行业景气度量化跟踪体系（参数优化版）— 房地产
A2: 默认阶段框架：强周期/供给出清｜先行/同步/滞后=50%/35%/15%。先用库存、供给、订单确认反转；价格本身不能直接等同高景气。｜核心验证：融资、销售与库存去化；必选：按揭利率、融资、限购/供给、城市库存
A3: 指标名称 | B3: 数据来源 | C3: 最新数值 | D3: 单位 | E3: 趋势 | F3: 权重 | G3: 评分 (1-10) | H3: 评分阈值说明 | I3: 历史分位 | J3: 对景气度影响 | K3: 跟踪频率 | L3: 原权重 | M3: 参数优化建议 | N3: 评分口径（更新时采用） | O3: 阶段分项 | P3: 公式分数
A4: 【第一部分：先行指标（Leading Indicators）——提前1-2个季度预示景气变化】 | O4: 先行 | P4: =ROUND(SUMPRODUCT(F5:F8,G5:G8)/SUM(F5:F8),1) -> 4.9
A5: 1-百城土地成交面积增速 | B5: 中指院 | C5: -15 | D5: %YoY | E5: 下行 | F5: 0.1667 | G5: 4 | H5: >10%=10分,0-10%=8分,-10-0%=6分,-20--10%=4分,<-20%=2分 | I5: 22% | J5: 土地成交低迷，房企拿地谨慎 | K5: 月度 | L5: 0.15 | M5: 目标组权重 50%；按同组相对重要性归一化。 | N5: 采用5年滚动分位+同比/环比双阈值；数据滞后超过一个频率周期时自动降权。 | O5: 同步 | P5: =ROUND(SUMPRODUCT(F10:F13,G10:G13)/SUM(F10:F13),1) -> 4
